Workbook
Name ___lst1: [1]Ref!$A$1:$A$4
Name ___lst2: [1]Ref!$B$1:$B$4
Name ___lst3: [1]Ref!$C$1:$C$4
Name __a1: '[2]CP đàotạo'!__a1
Name __a2: {"'Sheet1'!$L$16"}
Name __a3: {"'Sheet1'!$L$16"}
Name __bia5: '[2]CP đàotạo'!__bia5
Name __bia6: '[2]CP đàotạo'!__bia6
Name __BOT10: "Botón de opción 10"
Name __BOT9: "Botón de opción 9"
Name __cap1: '[2]CP đàotạo'!__cap1
Name __Cap2: '[2]CP đàotạo'!__Cap2
Name __D11: '[2]CP đàotạo'!__D11
Name __d1500: {"'Sheet1'!$L$16"}
Name __Goi8: {"'Sheet1'!$L$16"}
Name __h1: {"'Sheet1'!$L$16"}
Name __hsm2: 1.1289
Name __IntlFixup: TRUE
Name __Lan1: {"'Sheet1'!$L$16"}
Name __LAN3: {"'Sheet1'!$L$16"}
Name __ne2: {"ÿÿÿÿÿ","DT cau tam Ha trinh 7.xls","DT cau tam Ha trinh 3.xls"}
Name __PA3: {"'Sheet1'!$L$16"}
Name __pd10: {"'Summary'!$A$1:$J$46"}
Name __PD11: {"'Summary'!$A$1:$J$46"}
Name __SD30: {"'Summary'!$A$1:$J$46"}
Name __t22: '[2]CP đàotạo'!__t22
Name __T7: {"Thuxm2.xls","Sheet1"}
Name __td1: {"'Sheet1'!$L$16"}
Name __TH1: '[2]CP đàotạo'!__TH1
Name __thu2: {"Thuxm2.xls","Sheet1"}
Name __tt3: {"'Sheet1'!$L$16"}
Name __xlcn.WorksheetConnection_App_totalC3J41: #REF!
Name _40x4: 5100
Name _A4: {"'Sheet1'!$L$16"}
Name _Bia22: '[2]CP đàotạo'!_Bia22
Name _Bia3: '[2]CP đàotạo'!_Bia3
Name _bia5: '[2]CP đàotạo'!_bia5
Name _bia6: '[2]CP đàotạo'!_bia6
Name _BOT10: "Botón de opción 10"
Name _BOT9: "Botón de opción 9"
Name _cap1: '[2]CP đàotạo'!_cap1
Name _Cap2: '[2]CP đàotạo'!_Cap2
Name _D11: '[2]CP đàotạo'!_D11
Name _F1: {"'Sheet1'!$L$16"}
Name _Fill: #REF!
Name _GID1: '[3]LKVL-CK-HT-GD1'!$A$4
Name _Goi8: {"'Sheet1'!$L$16"}
Name _hsm2: 1.1289
Name _huy1: {"'Sheet1'!$L$16"}
Name _Key1: #REF!
Name _Key2: #REF!
Name _Lan1: {"Thuxm2.xls","Sheet1"}
Name _ncb1: '[2]CP đàotạo'!_ncb1
Name _ne2: {"ÿÿÿÿÿ","DT cau tam Ha trinh 7.xls","DT cau tam Ha trinh 3.xls"}
Name _NSO2: {"'Sheet1'!$L$16"}
Name _NSO3: {"'Sheet1'!$L$16"}
Name _Order1: 255
Name _Order2: 255
Name _PA3: {"'Sheet1'!$L$16"}
Name _pd10: {"'Summary'!$A$1:$J$46"}

Sheet 1. GTPM
A1: Bảng tính toán giá trị phần mềm
A3: STT | B3: Hạng mục | C3: Diễn giải | D3: Giá trị | E3: Ghi chú
A4: I | B4: Tính điểm trường hợp sử dụng Use case
A5: 1 | B5: Điểm Actor (TAW) | C5: TAW | D5: ='1.2.TAW'!F8 -> 17 | E5: TAW
A6: 2 | B6: Điểm Use-case (TBF) | C6: TBF | D6: ='1.3. TBF'!F17 -> 1720 | E6: TBF
A7: 3 | B7: Tính điểm UUCP | C7: UUCP = TAW +TBF | D7: =D5+D6 -> 1737 | E7: UUCP
A8: 4 | B8: Hệ số phức tạp về KT-CN (TCF) | C8: TCF = 0,6 + (0,01 x TFW) | D8: ='1.4.TCF moi'!E19 -> 0.98 | E8: TCF
A9: 5 | B9: Hệ số phức tạp về môi trường (EF) | C9: EF = 1,4 + (-0,03 x EFW) | D9: ='1.5. EF moi'!E13 -> 0.935 | E9: EF
A10: 6 | B10: Tính điểm AUCP | C10: AUCP = UUCP x TCF x EF | D10: =D7*D8*D9 -> 1591.6131 | E10: AUCP
A11: II | B11: Nội suy thời gian lao động (P) | C11: P | D11: ='1.5. EF moi'!F15 -> 26.7 | E11: P
A12: III | B12: Giá trị nỗ lực thực tế (E) | C12: E = 10/6 x AUCP | D12: =10/6*D10 -> 2652.6885 | E12: E
A13: IV | B13: Mức lương lao động bình quân (H) | C13: H | D13: ='Bang luong'!D19 -> 72594 | E13: Kỹ sư bậc 2
A14: V | B14: Giá trị phần mềm nội bộ (G) | C14: G = 1,4 x E x P x H | D14: =1.4*D12*D11*D13 -> 7.1982393e+09 | E14: G
A15: Bảng tổng hợp chi phí phần mềm
A17: STT | B17: Khoản mục chi phí | C17: Cách tính | D17: Giá trị | E17: Ký hiệu
A18: 1 | B18: Chi phí trực tiếp xây dựng, phát triển, nâng cấp, mở rộng phần mềm nội bộ | C18: 1,4 x E x P x H | D18: =D14 -> 7.1982393e+09 | E18: G
A19: 2 | B19: Chi phí chung | C19: G x 65% | D19: =D18*0.65 -> 4.6788555e+09 | E19: C
A20: 3 | B20: Thu nhập chịu thuế tính trước | C20: (G+C) x 6% | D20: =(D18+D19)*6% -> 7.1262569e+08 | E20: TL
A21: 4 | B21: Chi phí xây dựng, phát triển, nâng cấp, mở rông phần mềm nội bộ | C21: G + C + TL | D21: =SUM(D18:D20) -> 1.258972e+10 | E21: Gpm
B22: TỔNG CỘNG | C22: Gpm | D22: =D21 -> 1.258972e+10

Sheet 1.2.TAW
A2: PHỤ LỤC III: BẢNG TÍNH TOÁN ĐIỂM CÁC TÁC NHÂN (ACTORS) TƯƠNG TÁC, TRAO ĐỔI THÔNG TIN VỚI PHẦN MỀM
A4: STT | B4: Loại Actor | C4: Mô tả | D4: Số tác nhân | E4: Trọng số | F4: Điểm từng loại tác nhân | G4: Ghi chú
A5: 1 | B5: Đơn giản | C5: Thuộc loại giao diện của chương trình | D5: =COUNTIF(C15:C23,B5) -> 2 | E5: 1 | F5: =E5*D5 -> 2
A6: 2 | B6: Trung bình | C6: Giao diện tương tác hoặc phục vụ một giao thức hoạt động | D6: =COUNTIF(C16:C24,B6) -> 0 | E6: 2 | F6: =E6*D6 -> 0
A7: 3 | B7: Phức tạp | C7: Giao diện đồ họa | D7: =COUNTIF(C15:C25,B7) -> 5 | E7: 3 | F7: =E7*D7 -> 15
A8: 4 | B8: Cộng (1+2+3) | C8: TAW | F8: =SUM(F5:F7) -> 17
A9: Actor – Tác nhân: là người hay hệ thống bên ngoài tương tác, trao đổi thông tin với hệ thống
A12: BẢNG TÁC NHÂN THAM GIA HỆ THỐNG
A14: STT | B14: Tên Actor | C14: Phân loại tác nhân | D14: Mô tả
A15: 1 | B15: QTHT | C15: Phức tạp | D15: Quản trị hệ thống thực hiện tích hợp đồng bộ, quản lý, cập nhật danh mục dùng chung
A16: 2 | B16: QTĐV | C16: Phức tạp | D16: Quản trị đơn vị là cán bộ đóng vai trò quản trị của từng đơn vị trực thuộc Bộ, thiết lập cấu hình nhận thông tin, cảnh báo
A17: 3 | B17: LGSP | C17: Đơn giản | D17: Nền tảng tích hợp, chia sẻ dữ liệu cấp của Bộ chứa các dịch vụ dùng chung để chia sẻ dữ liệu giữa các hệ thống thông tin của các cơ quan, đơn vị
A18: 4 | B18: HTK | C18: Đơn giản | D18: Các hệ thống khác của Bộ đang sử dụng (Phần mềm quản lý văn bản và điều hành, Phần mềm quản lý nhiệm vụ lãnh đạo bộ giao…)
A19: 5 | B19: Lãnh đạo bộ | C19: Phức tạp | D19: Lãnh đạo bộ bao gồm bộ trưởng, thứ trưởng
A20: 6 | B20: Lãnh đạo cục/vụ | C20: Phức tạp | D20: Lãnh đạo cục/vụ bao gồm vụ trưởng, phó vụ trưởng, cục trưởng, phó cục trưởng các cục/vụ.
A21: 7 | B21: Chuyên viên nhập liệu | C21: Phức tạp | D21: Cán bộ chuyên trách là cán bộ đóng vai trò tham gia hệ thống của từng đơn vị trực thuộc
B24: Ghi chú
B25: - Loại đơn giản: Một máy tính với giao diện lập trình ứng dụng API
B26: - Loại trung bình: Hoặc là giao diện người - máy qua “command line” hoặc thông qua một giao thức nào đó nhưng không có lập trình qua API
B27: - Loại phức tạp: giao diện người - máy qua GUI (giao diện đồ hoạ)

Sheet 1.3. TBF
A2: PHỤ LỤC IV: BẢNG TÍNH TOÁN ĐIỂM CÁC TRƯỜNG HỢP SỬ DỤNG (USE CASE)
A3: I
A4: STT | B4: Loại Use Case | C4: Trọng số UCP chuẩn | D4: Hệ số BMT | E4: Số trường hợp sử dụng | F4: Điểm của từng trường hợp | G4: Mô tả
A5: 1 | B5: B | G5: Các yêu cầu phải thỏa mãn thì phần mềm mới được chấp nhận
B6: Use case đơn giản | C6: =VLOOKUP(B6,$E$22:$F$24,2,0) -> 5 | D6: 1 | E6: =UseCase!L1 -> 163 | F6: =E6*5*1 -> 815 | G6: Có số lượng giao dịch <4
B7: Use case trung bình | C7: =VLOOKUP(B7,$E$22:$F$24,2,0) -> 10 | D7: 1 | E7: =UseCase!L2 -> 53 | F7: =E7*10*1 -> 530 | G7: 4<=Có số lượng giao dịch < =7
B8: Use case phức tạp | C8: =VLOOKUP(B8,$E$22:$F$24,2,0) -> 15 | D8: 1 | E8: =UseCase!L3 -> 25 | F8: =E8*15*1 -> 375 | G8: 7<Có số lượng giao dịch
A9: 2 | B9: M | F9: =SUM(F10:F12) -> 0 | G9: Các chức năng không phải cốt lõi hoặc các chức năng phụ trợ theo yêu cầu của bên đặt hàng
B10: Use case đơn giản | C10: =VLOOKUP(B10,$E$22:$F$24,2,0) -> 5 | D10: 1.2 | F10: =E10*5*1.2 -> 0 | G10: Có số lượng giao dịch <4
B11: Use case trung bình | C11: =VLOOKUP(B11,$E$22:$F$24,2,0) -> 10 | D11: 1.2 | F11: =E11*10*1.2 -> 0 | G11: 4<=Có số lượng giao dịch < =7
B12: Use case phức tạp | C12: =VLOOKUP(B12,$E$22:$F$24,2,0) -> 15 | D12: 1.2 | F12: =E12*15*1.2 -> 0 | G12: 7<Có số lượng giao dịch
A13: 3 | B13: T | F13: =SUM(F14:F16) -> 0 | G13: Các yêu cầu được bên PT PM tư vấn hoặc đưa ra thêm để bên đặt hàng lựa chọn thêm nếu muốn
B14: Use case đơn giản | C14: =VLOOKUP(B14,$E$22:$F$24,2,0) -> 5 | D14: 1.5 | F14: =E14*5*1.5 -> 0 | G14: Có số lượng giao dịch <4
B15: Use case trung bình | C15: =VLOOKUP(B15,$E$22:$F$24,2,0) -> 10 | D15: 1.5 | F15: =E15*10*1.5 -> 0 | G15: 4<=Có số lượng giao dịch < =7
B16: Use case phức tạp | C16: =VLOOKUP(B16,$E$22:$F$24,2,0) -> 15 | D16: 1.5 | F16: =E16*15*1.5 -> 0 | G16: 7<Có số lượng giao dịch
B17: TBF = Cộng (1+2+3) | E17: =SUM(E6:E16) -> 241 | F17: =SUM(F6:F16) -> 1720
B20: Ghi chú:
B21: BMT | E21: Trọng số:
B22: B: Có hệ số bằng 1 | E22: Use case đơn giản | F22: 5
B23: M: Có hệ số bằng 1.2 | E23: Use case trung bình | F23: 10
B24: T: Có hệ số bằng 1.5 | E24: Use case phức tạp | F24: 15
B25: Điểm của từng loại trường hợp sử dụng = Số trường hợp sử dụng x Trọng số x Hệ số BMT

Sheet UseCase
H1: SUM = | I1: =SUM(L1:L3) -> 241 | J1: B | K1: Đơn giản | L1: =COUNTIF(G:G,K1) -> 163
J2: M | K2: Trung bình | L2: =COUNTIF(G:G,K2) -> 53
B3: TT | C3: Tên Use Case | D3: Tên tác nhân chính | E3: Mô tả trường hợp sử dụng | F3: Mức độ cần thiết | G3: Phân loại Use Case | H3: SL | J3: T | K3: Phức tạp | L3: =COUNTIF(G:G,K3) -> 25
B4: A | C4: Giao diện Web
B5: I | C5: Thông tin chung: Thông tin đơn vị, Thông tin lưu trữ, License | F5: =IF(D5="","","B") | G5: =IF(AND(B5<>"",C5<>"",D5<>""),IF(H5<4,$K$1,IF(H5<8,$K$2,$K$3)),"") | H5: =IF(AND(B5<>"",C5<>"",D5<>""),COUNTIF(I5:I512,B5),"") | I5: =IF(OR(E5="",B5<>""),"",IF(#REF!<>"",#REF!,#REF!))
B6: =IF(C6="","",IF(F6="B",COUNTIF($F$5:F7,"B"),"")) -> 1 | C6: Thiết lập hệ thống | D6: Quản trị hệ thống | F6: =IF(D6="","","B") -> B | G6: =IF(AND(B6<>"",C6<>"",D6<>""),IF(H6<4,$K$1,IF(H6<8,$K$2,$K$3)),"") -> Trung bình | H6: =IF(AND(B6<>"",C6<>"",D6<>""),COUNTIF(I6:I513,B6),"") -> 4 | I6: =IF(OR(E6="",B6<>""),"",IF(I5<>"",I5,B5))
B7: =IF(C7="","",IF(F7="B",COUNTIF($F$5:F7,"B"),"")) | E7: Quản trị hệ thống Thiết lập thông tin tổ chức. Hệ thống cập nhật thông tin tổ chức và thông báo kết quả xử lý cho Quản trị hệ thống | F7: =IF(D7="","","B") | G7: =IF(AND(B7<>"",C7<>"",D7<>""),IF(H7<4,$K$1,IF(H7<8,$K$2,$K$3)),"") | H7: =IF(AND(B7<>"",C7<>"",D7<>""),COUNTIF(I7:I514,B7),"") | I7: =IF(OR(E7="",B7<>""),"",IF(I6<>"",I6,B6)) -> 1
B8: =IF(C8="","",IF(F8="B",COUNTIF($F$5:F9,"B"),"")) | E8: Quản trị hệ thống có thể cấu hình, chỉnh sửa giao diện sử dụng và ghi lại. Hệ thống xử lý theo yêu cầu và thông báo kết quả xử lý cho Quản trị hệ thống | F8: =IF(D8="","","B") | G8: =IF(AND(B8<>"",C8<>"",D8<>""),IF(H8<4,$K$1,IF(H8<8,$K$2,$K$3)),"") | H8: =IF(AND(B8<>"",C8<>"",D8<>""),COUNTIF(I8:I516,B8),"") | I8: =IF(OR(E8="",B8<>""),"",IF(I7<>"",I7,B7)) -> 1
B9: =IF(C9="","",IF(F9="B",COUNTIF($F$5:F10,"B"),"")) | E9: Quản trị hệ thống có cấu hình banner cho hệ thống theo khoảng thời gian áp dụng. Hệ thống xử lý theo yêu cầu và thông báo kết quả xử lý cho Quản trị hệ thống | F9: =IF(D9="","","B") | G9: =IF(AND(B9<>"",C9<>"",D9<>""),IF(H9<4,$K$1,IF(H9<8,$K$2,$K$3)),"") | H9: =IF(AND(B9<>"",C9<>"",D9<>""),COUNTIF(I9:I518,B9),"") | I9: =IF(OR(E9="",B9<>""),"",IF(I8<>"",I8,B8)) -> 1
B10: =IF(C10="","",IF(F10="B",COUNTIF($F$5:F10,"B"),"")) | E10: Quản trị hệ thống có thể cấu hình ngày lễ cho hệ thống. Hệ thống xử lý theo yêu cầu và thông báo kết quả xử lý cho Quản trị hệ thống | F10: =IF(D10="","","B") | G10: =IF(AND(B10<>"",C10<>"",D10<>""),IF(H10<4,$K$1,IF(H10<8,$K$2,$K$3)),"") | H10: =IF(AND(B10<>"",C10<>"",D10<>""),COUNTIF(I10:I519,B10),"") | I10: =IF(OR(E10="",B10<>""),"",IF(I9<>"",I9,B9)) -> 1
B11: =IF(C11="","",IF(F11="B",COUNTIF($F$5:F12,"B"),"")) -> 2 | C11: Cơ cấu tổ chức | D11: Quản trị hệ thống | F11: =IF(D11="","","B") -> B | G11: =IF(AND(B11<>"",C11<>"",D11<>""),IF(H11<4,$K$1,IF(H11<8,$K$2,$K$3)),"") -> Trung bình | H11: =IF(AND(B11<>"",C11<>"",D11<>""),COUNTIF(I11:I522,B11),"") -> 5 | I11: =IF(OR(E11="",B11<>""),"",IF(#REF!<>"",#REF!,#REF!))
B12: =IF(C12="","",IF(F12="B",COUNTIF($F$5:F13,"B"),"")) | E12: Quản trị hệ thống có thể xem danh sách phòng ban. Hệ thống xử lý theo yêu cầu và hiển thị phòng ban cho Quản trị hệ thống | F12: =IF(D12="","","B") | G12: =IF(AND(B12<>"",C12<>"",D12<>""),IF(H12<4,$K$1,IF(H12<8,$K$2,$K$3)),"") | H12: =IF(AND(B12<>"",C12<>"",D12<>""),COUNTIF(I12:I523,B12),"") | I12: =IF(OR(E12="",B12<>""),"",IF(I11<>"",I11,B11)) -> 2
B13: =IF(C13="","",IF(F13="B",COUNTIF($F$5:F14,"B"),"")) | E13: Quản trị hệ thống có thể xem danh sách chức vụ. Hệ thống xử lý theo yêu cầu và hiển thị danh sách chức vụ cho Quản trị hệ thống | F13: =IF(D13="","","B") | G13: =IF(AND(B13<>"",C13<>"",D13<>""),IF(H13<4,$K$1,IF(H13<8,$K$2,$K$3)),"") | H13: =IF(AND(B13<>"",C13<>"",D13<>""),COUNTIF(I13:I524,B13),"") | I13: =IF(OR(E13="",B13<>""),"",IF(I12<>"",I12,B12)) -> 2
B14: =IF(C14="","",IF(F14="B",COUNTIF($F$5:F15,"B"),"")) | E14: Quản trị hệ thống có thể xem danh sách chức danh. Hệ thống xử lý theo yêu cầu và hiển thị danh sách chức danh cho Quản trị hệ thống | F14: =IF(D14="","","B") | G14: =IF(AND(B14<>"",C14<>"",D14<>""),IF(H14<4,$K$1,IF(H14<8,$K$2,$K$3)),"") | H14: =IF(AND(B14<>"",C14<>"",D14<>""),COUNTIF(I14:I525,B14),"") | I14: =IF(OR(E14="",B14<>""),"",IF(I13<>"",I13,B13)) -> 2
B15: =IF(C15="","",IF(F15="B",COUNTIF($F$5:F16,"B"),"")) | E15: Quản trị hệ thống xem danh sách người dùng. Hệ thống xử lý theo yêu cầu và hiển thị danh sách người dùngcho Quản trị hệ thống | F15: =IF(D15="","","B") | G15: =IF(AND(B15<>"",C15<>"",D15<>""),IF(H15<4,$K$1,IF(H15<8,$K$2,$K$3)),"") | H15: =IF(AND(B15<>"",C15<>"",D15<>""),COUNTIF(I15:I525,B15),"") | I15: =IF(OR(E15="",B15<>""),"",IF(I14<>"",I14,B14)) -> 2
B16: =IF(C16="","",IF(F16="B",COUNTIF($F$5:F16,"B"),"")) | E16: Quản trị hệ thống xem danh sách người dùng theo từng nhóm. Hệ thống xử lý theo yêu cầu và hiển thị nhóm người dùng cho Quản trị hệ thống | F16: =IF(D16="","","B") | G16: =IF(AND(B16<>"",C16<>"",D16<>""),IF(H16<4,$K$1,IF(H16<8,$K$2,$K$3)),"") | H16: =IF(AND(B16<>"",C16<>"",D16<>""),COUNTIF(I16:I525,B16),"") | I16: =IF(OR(E16="",B16<>""),"",IF(I15<>"",I15,B15)) -> 2
B17: I.1 | C17: Quản lý Vai trò, quyền hạn, nhóm quyền | F17: =IF(D17="","","B") | G17: =IF(AND(B17<>"",C17<>"",D17<>""),IF(H17<4,$K$1,IF(H17<8,$K$2,$K$3)),"") | H17: =IF(AND(B17<>"",C17<>"",D17<>""),COUNTIF(I17:I525,B17),"") | I17: =IF(OR(E17="",B17<>""),"",IF(#REF!<>"",#REF!,#REF!))
B18: =IF(C18="","",IF(F18="B",COUNTIF($F$5:F19,"B"),"")) -> 3 | C18: Quản lý quyền | D18: Quản trị hệ thống | F18: =IF(D18="","","B") -> B | G18: =IF(AND(B18<>"",C18<>"",D18<>""),IF(H18<4,$K$1,IF(H18<8,$K$2,$K$3)),"") -> Trung bình | H18: =IF(AND(B18<>"",C18<>"",D18<>""),COUNTIF(I18:I511,B18),"") -> 4 | I18: =IF(OR(E18="",B18<>""),"",IF(#REF!<>"",#REF!,#REF!))
B19: =IF(C19="","",IF(F19="B",COUNTIF($F$5:F20,"B"),"")) | E19: Quản trị hệ thống thêm quyền. Hệ thống xử lý theo yêu cầu và thông báo kết quả xử lý cho Quản trị hệ thống | F19: =IF(D19="","","B") | G19: =IF(AND(B19<>"",C19<>"",D19<>""),IF(H19<4,$K$1,IF(H19<8,$K$2,$K$3)),"") | H19: =IF(AND(B19<>"",C19<>"",D19<>""),COUNTIF(I19:I512,B19),"") | I19: =IF(OR(E19="",B19<>""),"",IF(I18<>"",I18,B18)) -> 3
B20: =IF(C20="","",IF(F20="B",COUNTIF($F$5:F21,"B"),"")) | E20: Quản trị hệ thống sửa quyền. Hệ thống xử lý theo yêu cầu và thông báo kết quả xử lý cho Quản trị hệ thống | F20: =IF(D20="","","B") | G20: =IF(AND(B20<>"",C20<>"",D20<>""),IF(H20<4,$K$1,IF(H20<8,$K$2,$K$3)),"") | H20: =IF(AND(B20<>"",C20<>"",D20<>""),COUNTIF(I20:I513,B20),"") | I20: =IF(OR(E20="",B20<>""),"",IF(I19<>"",I19,B19)) -> 3
B21: =IF(C21="","",IF(F21="B",COUNTIF($F$5:F22,"B"),"")) | E21: Quản trị hệ thống xóa quyền. Hệ thống xử lý theo yêu cầu và thông báo kết quả xử lý cho Quản trị hệ thống | F21: =IF(D21="","","B") | G21: =IF(AND(B21<>"",C21<>"",D21<>""),IF(H21<4,$K$1,IF(H21<8,$K$2,$K$3)),"") | H21: =IF(AND(B21<>"",C21<>"",D21<>""),COUNTIF(I21:I514,B21),"") | I21: =IF(OR(E21="",B21<>""),"",IF(I20<>"",I20,B20)) -> 3
B22: =IF(C22="","",IF(F22="B",COUNTIF($F$5:F23,"B"),"")) | E22: Quản trị hệ thống tìm kiếm quyền. Hệ thống xử lý theo yêu cầu và thông báo kết quả xử lý cho Quản trị hệ thống | F22: =IF(D22="","","B") | G22: =IF(AND(B22<>"",C22<>"",D22<>""),IF(H22<4,$K$1,IF(H22<8,$K$2,$K$3)),"") | H22: =IF(AND(B22<>"",C22<>"",D22<>""),COUNTIF(I22:I515,B22),"") | I22: =IF(OR(E22="",B22<>""),"",IF(I21<>"",I21,B21)) -> 3
B23: =IF(C23="","",IF(F23="B",COUNTIF($F$5:F24,"B"),"")) -> 4 | C23: Quản lý vai trò | D23: Quản trị hệ thống | F23: =IF(D23="","","B") -> B | G23: =IF(AND(B23<>"",C23<>"",D23<>""),IF(H23<4,$K$1,IF(H23<8,$K$2,$K$3)),"") -> Trung bình | H23: =IF(AND(B23<>"",C23<>"",D23<>""),COUNTIF(I23:I516,B23),"") -> 4 | I23: =IF(OR(E23="",B23<>""),"",IF(I22<>"",I22,B22))
B24: =IF(C24="","",IF(F24="B",COUNTIF($F$6:F24,"B"),"")) | E24: Quản trị hệ thống thêm vai trò. Hệ thống xử lý theo yêu cầu và thông báo kết quả xử lý cho Quản trị hệ thống | F24: =IF(D24="","","B") | G24: =IF(AND(B24<>"",C24<>"",D24<>""),IF(H24<4,$K$1,IF(H24<8,$K$2,$K$3)),"") | H24: =IF(AND(B24<>"",C24<>"",D24<>""),COUNTIF(I24:I517,B24),"") | I24: =IF(OR(E24="",B24<>""),"",IF(I23<>"",I23,B23)) -> 4
B25: =IF(C25="","",IF(F25="B",COUNTIF($F$6:F25,"B"),"")) | E25: Quản trị hệ thống sửa vai trò. Hệ thống xử lý theo yêu cầu và thông báo kết quả xử lý cho Quản trị hệ thống | F25: =IF(D25="","","B") | G25: =IF(AND(B25<>"",C25<>"",D25<>""),IF(H25<4,$K$1,IF(H25<8,$K$2,$K$3)),"") | H25: =IF(AND(B25<>"",C25<>"",D25<>""),COUNTIF(I25:I518,B25),"") | I25: =IF(OR(E25="",B25<>""),"",IF(I24<>"",I24,B24)) -> 4
B26: =IF(C26="","",IF(F26="B",COUNTIF($F$6:F26,"B"),"")) | E26: Quản trị hệ thống xóa vai trò. Hệ thống xử lý theo yêu cầu và thông báo kết quả xử lý cho Quản trị hệ thống | F26: =IF(D26="","","B") | G26: =IF(AND(B26<>"",C26<>"",D26<>""),IF(H26<4,$K$1,IF(H26<8,$K$2,$K$3)),"") | H26: =IF(AND(B26<>"",C26<>"",D26<>""),COUNTIF(I26:I519,B26),"") | I26: =IF(OR(E26="",B26<>""),"",IF(I25<>"",I25,B25)) -> 4
B27: =IF(C27="","",IF(F27="B",COUNTIF($F$6:F27,"B"),"")) | E27: Quản trị hệ thống tìm kiếm vai trò. Hệ thống xử lý theo yêu cầu và thông báo kết quả xử lý cho Quản trị hệ thống | F27: =IF(D27="","","B") | G27: =IF(AND(B27<>"",C27<>"",D27<>""),IF(H27<4,$K$1,IF(H27<8,$K$2,$K$3)),"") | H27: =IF(AND(B27<>"",C27<>"",D27<>""),COUNTIF(I27:I520,B27),"") | I27: =IF(OR(E27="",B27<>""),"",IF(I26<>"",I26,B26)) -> 4
B28: =IF(C28="","",IF(F28="B",COUNTIF($F$6:F28,"B"),"")) -> 5 | C28: Quản lý nhóm quyền | D28: Quản trị hệ thống | F28: =IF(D28="","","B") -> B | G28: =IF(AND(B28<>"",C28<>"",D28<>""),IF(H28<4,$K$1,IF(H28<8,$K$2,$K$3)),"") -> Trung bình | H28: =IF(AND(B28<>"",C28<>"",D28<>""),COUNTIF(I28:I521,B28),"") -> 5 | I28: =IF(OR(E28="",B28<>""),"",IF(I27<>"",I27,B27))
B29: =IF(C29="","",IF(F29="B",COUNTIF($F$6:F29,"B"),"")) | E29: Quản trị hệ thống Thêm quyền vào nhóm quyền. Hệ thống xử lý theo yêu cầu và thông báo kết quả xử lý cho Quản trị hệ thống | F29: =IF(D29="","","B") | G29: =IF(AND(B29<>"",C29<>"",D29<>""),IF(H29<4,$K$1,IF(H29<8,$K$2,$K$3)),"") | H29: =IF(AND(B29<>"",C29<>"",D29<>""),COUNTIF(I29:I522,B29),"") | I29: =IF(OR(E29="",B29<>""),"",IF(I28<>"",I28,B28)) -> 5
B30: =IF(C30="","",IF(F30="B",COUNTIF($F$6:F30,"B"),"")) | E30: Quản trị hệ thống Xóa quyền khỏi nhóm quyền. Hệ thống xử lý theo yêu cầu và thông báo kết quả xử lý cho Quản trị hệ thống | F30: =IF(D30="","","B") | G30: =IF(AND(B30<>"",C30<>"",D30<>""),IF(H30<4,$K$1,IF(H30<8,$K$2,$K$3)),"") | H30: =IF(AND(B30<>"",C30<>"",D30<>""),COUNTIF(I30:I523,B30),"") | I30: =IF(OR(E30="",B30<>""),"",IF(I29<>"",I29,B29)) -> 5
B31: =IF(C31="","",IF(F31="B",COUNTIF($F$6:F31,"B"),"")) | E31: Quản trị hệ thống thêm nhóm quyền. Hệ thống xử lý theo yêu cầu và thông báo kết quả xử lý cho Quản trị hệ thống | F31: =IF(D31="","","B") | G31: =IF(AND(B31<>"",C31<>"",D31<>""),IF(H31<4,$K$1,IF(H31<8,$K$2,$K$3)),"") | H31: =IF(AND(B31<>"",C31<>"",D31<>""),COUNTIF(I31:I524,B31),"") | I31: =IF(OR(E31="",B31<>""),"",IF(I30<>"",I30,B30)) -> 5
B32: =IF(C32="","",IF(F32="B",COUNTIF($F$6:F32,"B"),"")) | E32: Quản trị hệ thống xóa nhóm quyền. Hệ thống xử lý theo yêu cầu và thông báo kết quả xử lý cho Quản trị hệ thống | F32: =IF(D32="","","B") | G32: =IF(AND(B32<>"",C32<>"",D32<>""),IF(H32<4,$K$1,IF(H32<8,$K$2,$K$3)),"") | H32: =IF(AND(B32<>"",C32<>"",D32<>""),COUNTIF(I32:I525,B32),"") | I32: =IF(OR(E32="",B32<>""),"",IF(I31<>"",I31,B31)) -> 5
B33: =IF(C33="","",IF(F33="B",COUNTIF($F$6:F33,"B"),"")) | E33: Quản trị hệ thống sửa nhóm quyền. Hệ thống xử lý theo yêu cầu và thông báo kết quả xử lý cho Quản trị hệ thống | F33: =IF(D33="","","B") | G33: =IF(AND(B33<>"",C33<>"",D33<>""),IF(H33<4,$K$1,IF(H33<8,$K$2,$K$3)),"") | H33: =IF(AND(B33<>"",C33<>"",D33<>""),COUNTIF(I33:I525,B33),"") | I33: =IF(OR(E33="",B33<>""),"",IF(I32<>"",I32,B32)) -> 5
B34: =IF(C34="","",IF(F34="B",COUNTIF($F$6:F34,"B"),"")) -> 6 | C34: Phân quyền cho vai trò | D34: Quản trị hệ thống | F34: =IF(D34="","","B") -> B | G34: =IF(AND(B34<>"",C34<>"",D34<>""),IF(H34<4,$K$1,IF(H34<8,$K$2,$K$3)),"") -> Trung bình | H34: =IF(AND(B34<>"",C34<>"",D34<>""),COUNTIF(I34:I525,B34),"") -> 4 | I34: =IF(OR(E34="",B34<>""),"",IF(I33<>"",I33,B33))
B35: =IF(C35="","",IF(F35="B",COUNTIF($F$6:F35,"B"),"")) | E35: Quản trị hệ thống Thêm quyền vào vai trò. Hệ thống xử lý theo yêu cầu và thông báo kết quả xử lý cho Quản trị hệ thống | F35: =IF(D35="","","B") | G35: =IF(AND(B35<>"",C35<>"",D35<>""),IF(H35<4,$K$1,IF(H35<8,$K$2,$K$3)),"") | H35: =IF(AND(B35<>"",C35<>"",D35<>""),COUNTIF(I35:I525,B35),"") | I35: =IF(OR(E35="",B35<>""),"",IF(I34<>"",I34,B34)) -> 6
B36: =IF(C36="","",IF(F36="B",COUNTIF($F$6:F36,"B"),"")) | E36: Quản trị hệ thống Xóa quyền khỏi vai trò. Hệ thống xử lý theo yêu cầu và thông báo kết quả xử lý cho Quản trị hệ thống | F36: =IF(D36="","","B") | G36: =IF(AND(B36<>"",C36<>"",D36<>""),IF(H36<4,$K$1,IF(H36<8,$K$2,$K$3)),"") | H36: =IF(AND(B36<>"",C36<>"",D36<>""),COUNTIF(I36:I525,B36),"") | I36: =IF(OR(E36="",B36<>""),"",IF(I35<>"",I35,B35)) -> 6
B37: =IF(C37="","",IF(F37="B",COUNTIF($F$6:F37,"B"),"")) | E37: Quản trị hệ thống Thêm nhóm quyền vào vai trò. Hệ thống xử lý theo yêu cầu và thông báo kết quả xử lý cho Quản trị hệ thống | F37: =IF(D37="","","B") | G37: =IF(AND(B37<>"",C37<>"",D37<>""),IF(H37<4,$K$1,IF(H37<8,$K$2,$K$3)),"") | H37: =IF(AND(B37<>"",C37<>"",D37<>""),COUNTIF(I37:I525,B37),"") | I37: =IF(OR(E37="",B37<>""),"",IF(I36<>"",I36,B36)) -> 6
B38: =IF(C38="","",IF(F38="B",COUNTIF($F$6:F38,"B"),"")) | E38: Quản trị hệ thống Xóa nhóm quyền vào vai trò. Hệ thống xử lý theo yêu cầu và thông báo kết quả xử lý cho Quản trị hệ thống | F38: =IF(D38="","","B") | G38: =IF(AND(B38<>"",C38<>"",D38<>""),IF(H38<4,$K$1,IF(H38<8,$K$2,$K$3)),"") | H38: =IF(AND(B38<>"",C38<>"",D38<>""),COUNTIF(I38:I525,B38),"") | I38: =IF(OR(E38="",B38<>""),"",IF(I37<>"",I37,B37)) -> 6
B39: =IF(C39="","",IF(F39="B",COUNTIF($F$6:F39,"B"),"")) -> 7 | C39: Quản lý cơ quan | D39: Quản trị hệ thống | F39: =IF(D39="","","B") -> B | G39: =IF(AND(B39<>"",C39<>"",D39<>""),IF(H39<4,$K$1,IF(H39<8,$K$2,$K$3)),"") -> Trung bình | H39: =IF(AND(B39<>"",C39<>"",D39<>""),COUNTIF(I39:I525,B39),"") -> 4 | I39: =IF(OR(E39="",B39<>""),"",IF(I38<>"",I38,B38))
B40: =IF(C40="","",IF(F40="B",COUNTIF($F$6:F40,"B"),"")) | E40: Quản trị hệ thống tạo mới cơ quan / phòng ban. Hệ thống xử lý theo yêu cầu và thông báo kết quả xử lý cho Quản trị hệ thống | F40: =IF(D40="","","B") | G40: =IF(AND(B40<>"",C40<>"",D40<>""),IF(H40<4,$K$1,IF(H40<8,$K$2,$K$3)),"") | H40: =IF(AND(B40<>"",C40<>"",D40<>""),COUNTIF(I40:I525,B40),"") | I40: =IF(OR(E40="",B40<>""),"",IF(I39<>"",I39,B39)) -> 7
...

Sheet 1.5. HSTDMT (EF)
A1: BẢNG TÍNH TOÁN HỆ SỐ TÁC ĐỘNG MÔI TRƯỜNG
A3: STT | B3: Các hệ số tác động môi trường | C3: Mức xếp hạng (Từ 0 đến 5) | D3: Trọng số chuẩn | E3: TB cộng giá trị xếp hạng | F3: Kết quả (KQ) | G3: Đánh giá độ ổn định KN | H3: Diễn giải lý do
A4: I | B4: Hệ số tác động môi trường và nhóm dự án (EFW)
B5: Đánh giá cho từng thành viên | L5: Giá trị
A6: F1 | B6: Có áp dụng qui trình phát triển PM theo mẫu RUP và có hiểu biết về RUP | C6: 0 = Không có kinh nghiệm | D6: 1.5 | E6: 2 | F6: =D6*E6 -> 3 | G6: =IF(F6>3,1,IF(F6>2,0.6,IF(F6>1,0.1,IF(F6>0,0.05,0)))) -> 0.6 | L6: ='1. GTPM'!D22 -> 1.258972e+10 | S6: 3.6347296e+09
C7: 3 = Trung bình
C8: 5 = Trình độ chuyên gia
A9: F2 | B9: Có kinh nghiệm về ứng dụng tương tự (application experiences) | C9: 0 = Không có kinh nghiệm | D9: 0.5 | E9: 3 | F9: =D9*E9 -> 1.5 | G9: =IF(F9>3,1,IF(F9>2,0.6,IF(F9>1,0.1,IF(F9>0,0.05,0)))) -> 0.1 | S9: Bổ sung thêm 1 uc đơn giản, 1 UC phức tạp, 1 UC trung bình
C10: 3 = Trung bình
C11: 5 = Trình độ chuyên gia
A12: F3 | B12: Có kinh nghiệm về hướng đối tượng (Object Oriented) | C12: 0 = Không có kinh nghiệm | D12: 1 | E12: 3 | F12: =D12*E12 -> 3 | G12: =IF(F12>3,1,IF(F12>2,0.6,IF(F12>1,0.1,IF(F12>0,0.05,0)))) -> 0.6
C13: 3 = Trung bình
C14: 5 = Trình độ chuyên gia
A15: F4 | B15: Có khả năng lãnh đạo Nhóm | C15: 0 = Không có kinh nghiệm | D15: 0.5 | E15: 3 | F15: =D15*E15 -> 1.5 | G15: =IF(F15>3,1,IF(F15>2,0.6,IF(F15>1,0.1,IF(F15>0,0.05,0)))) -> 0.1
C16: 3 = Trung bình
C17: 5 = Trình độ chuyên gia
A18: F5 | B18: Tính chất năng động | C18: 0 = Không năng động | D18: 1 | E18: 2 | F18: =D18*E18 -> 2 | G18: =IF(F18>3,1,IF(F18>2,0.6,IF(F18>1,0.1,IF(F18>0,0.05,0)))) -> 0.1
C19: 3 = Trung bình
C20: 5 = Cao
B21: Đánh giá chung cho Dự án
A22: F6 | B22: Độ ổn định của các yêu cầu | C22: 0 = Rất bất định | D22: 2 | E22: 4 | F22: =D22*E22 -> 8 | G22: =IF(F22>3,1,IF(F22>2,0.6,IF(F22>1,0.1,IF(F22>0,0.05,0)))) -> 1
C23: 5 = Không hay thay đổi
A24: F7 | B24: Có sử dụng các nhân viên làm Part-time | C24: 0 = Không có NV Part-time | D24: -1 | E24: 0 | F24: =D24*E24 -> 0 | G24: =IF(F24>3,1,IF(F24>2,0.6,IF(F24>1,0.1,IF(F24>0,0.05,0)))) -> 0
B25: (TB là 3) | C25: 3 = Có nhân viên làm Part-time
C26: 5 = Tất cả đều làm Part-time
A27: F8 | B27: Dùng ngôn ngữ lập trình loại khó | C27: 0 = Ngôn ngữ lập trình dễ | D27: -1 | E27: 0 | F27: =D27*E27 -> 0 | G27: =IF(F27>3,1,IF(F27>2,0.6,IF(F27>1,0.1,IF(F27>0,0.05,0)))) -> 0
C28: 3 = Trung bình
C29: 5 = Khó
B30: Cộng I | C30: EFW | F30: =SUM(F6:F29) -> 19
A31: II | B31: Hệ số độ phức tạp về môi trường (Environmental Factor) | C31: EF = 1.4 + (-0.03 x EFW) | F31: =1.4+(-0.03*F30) -> 0.83
A32: III | B32: Độ ổn định kinh nghiệm (Experience Stable) | C32: ES | G32: =SUM(G6:G29) -> 2.5
A33: IV | B33: Nội suy năng suất P | C33: P= người/giờ/usecase | G33: =IF(G32>=3,20,IF(G32>=1,32,48)) -> 32
A39: Trong đó, đánh giá cho từng thành viên tham gia dự án như sau:
A41: Hệ số tác động môi trường và nhóm làm việc (EFW) | C41: Trung bình | D41: Nhân viên tham gia | J41: ES | K41: Giá trị nội suy (P)
A42: Đánh giá cho từng thành viên | D42: Nhóm KS bậc 1 | E42: Nhóm KS Bậc 2 | F42: Nhóm kỹ sư bậc 3 | J42: < 1 | K42: 48
A43: 1 | B43: Có áp dụng qui trình phát triển phần mềm theo mẫu RUP và có hiểu biết về RUP hoặc quy trình phát triển phần mềm tương đương | C43: =AVERAGE(D43:F43) -> 2 | D43: 1 | E43: 2 | F43: 3 | J43: ≥ 1 | K43: 32
A44: 2 | B44: Có kinh nghiệm về ứng dụng tương tự | C44: =AVERAGE(D44:F44) -> 2 | D44: 1 | E44: 2 | F44: 3 | J44: ≥ 3 | K44: 20
A45: 3 | B45: Có kinh nghiệm về hướng đối tượng | C45: =AVERAGE(D45:F45) -> 3 | D45: 2 | E45: 3 | F45: 4
A46: 4 | B46: Có khả năng lãnh đạo Nhóm | C46: =AVERAGE(D46:F46) -> 3 | D46: 2 | E46: 3 | F46: 4
A47: 5 | B47: Tính chất năng động | C47: =AVERAGE(D47:F47) -> 2 | D47: 1 | E47: 2 | F47: 3

Sheet 1.4.TCF moi
B2: PHỤ LỤC V: BẢNG TÍNH TOÁN HỆ SỐ PHỨC TẠP KỸ THUẬT - CÔNG NGHỆ
A3: STT | B3: Các hệ số | C3: Trọng số | D3: Giá trị xếp hạng | E3: Kết quả | F3: Ghi chú
A4: I | B4: Hệ số kỹ thuật - công nghệ | F4: Cần check với thiết kế và xác định pm có những yêu cầu nào | H4: ='1. GTPM'!D22 -> 1.258972e+10
A5: 1 | B5: Xử lý phân tán | C5: 1 | D5: 4 | E5: =$C$5*D5 -> 4 | F5: Yêu cầu xử lý phân tán, dữ liệu được truyền theo hai chiều (dữ liệu được xử lý tại một lớp/thành phần của hệ thống và được truyền qua lớp/thành phần khác của hệ thống xử lý tiếp, sau khi xử lý xong, dữ liệu được truyền ngược lại cho lớp/thành phần ban đầu của hệ thống)
A6: =A5+1 -> 2 | B6: Mức độ quan trọng của hiệu năng | C6: 1 | D6: 3 | E6: =$C$6*D6 -> 3 | F6: Yêu cầu cụ thể hiệu năng trong toàn bộ thời gian tác nghiệp. Các mốc thời gian tác nghiệp và yêu cầu cụ thể của hiệu năng: - Thời gian phản hồi: dưới 10s - Thông lượng: Số lượng người truy cập đồng thời 300 Không có yêu cầu thiết kế riêng biệt về sử dụng tài nguyên hệ thống để đáp ứng yêu cầu hiệu năng, yêu cầu cụ thể về thời gian phản hồi đối với các giao dịch được xử lý với các hệ thống (tích hợp) khác.
A7: =A6+1 -> 3 | B7: Hiệu quả sử dụng cho người dùng | C7: 1 | D7: 3 | E7: =$C$7*D7 -> 3 | F7: Yêu cầu đáp ứng từ 6 tiêu chí nêu trên trở lên, bao gồm: - Di chuyển con trỏ tự động - Các phím chức năng được cài đặt sẵn - Các ràng buộc đơn giản - Sử dụng nhiều màu sắc và hình ảnh nổi bật trong màn hình - Tối thiểu hóa số lượng giao diện để đạt được các mục tiêu nghiệp vụ - Hỗ trợ và tài liệu trực tuyến
A8: =A7+1 -> 4 | B8: Độ phức tạp của xử lý bên trong | C8: 2 | D8: 3 | E8: =$C$8*D8 -> 6 | F8: “Độ phức tạp của xử lý bên trong” được thể hiện thông qua việc hệ thống sử dụng/không sử dụng đến các thuật toán phức tạp. Yêu cầu đáp ứng 3 tiêu chí sau: - Yêu cầu xử lý lô-gic mở rộng - Yêu cầu có sử dụng công thức toán học - Yêu cầu xử lý nhiều loại thông tin đầu vào hoặc thông tin đầu ra
A9: =A8+1 -> 5 | B9: Khả năng tái sử dụng mã nguồn | C9: 1 | D9: 3 | E9: =$C$9*D9 -> 3 | F9: Yêu cầu ứng dụng phải được đóng gói riêng và tài liệu hóa nhằm tạo điều kiện cho việc tái sử dụng lại. Có thể tùy chỉnh ứng dụng để tái sử dụng bằng cách điều chỉnh mã nguồn.
A10: =A9+1 -> 6 | B10: Dễ cài đặt | C10: 0.5 | D10: 3 | E10: =$C$10*D10 -> 1.5 | F10: Yêu cầu cung cấp công cụ hỗ trợ cài đặt tự động trên một môi trường vận hành phần mềm (hệ điều hành máy chủ, máy tính, thiết bị di động,…), có yêu cầu thiết lập thông số khi cài đặt và có yêu cầu phải xây dựng tài liệu hướng dẫn cài đặt.
A11: =A10+1 -> 7 | B11: Dễ vận hành | C11: 0.5 | D11: 3 | E11: =$C$11*D11 -> 1.5 | F11: Việc vận hành hệ thống thực hiện theo quy trình, có yêu cầu phải lập quy trình vận hành hệ thống.
A12: =A11+1 -> 8 | B12: Khả năng chuyển đổi | C12: 1 | D12: 3 | E12: =$C$12*D12 -> 3 | F12: Có yêu cầu hệ thống vận hành được trên môi trường phần mềm hoặc phần cứng tương tự nhau
A13: =A12+1 -> 9 | B13: Dễ dàng bảo trì | C13: 1 | D13: 3 | E13: =$C$13*D13 -> 3 | F13: Có yêu cầu về việc chỉnh sửa hệ thống trong tương lai mà không cần lập trình lại từ đầu.
A14: =A13+1 -> 10 | B14: Xử lý đồng thời | C14: 1 | D14: 3 | E14: =$C$14*D14 -> 3 | F14: Yêu cầu truy cập dữ liệu đồng thời tại mọi thời điểm.
A15: =A14+1 -> 11 | B15: Mức độ hỗ trợ bảo mật | C15: 2 | D15: 2 | E15: =$C$15*D15 -> 4 | F15: Yêu cầu bảo mật mức 2
A16: =A15+1 -> 12 | B16: Sự phụ thuộc vào mã lệnh của bên thứ ba | C16: 1 | D16: 2 | E16: =$C$16*D16 -> 2 | F16: Hiệu chỉnh mã lệnh sẵn có để phát triển toàn bộ ứng dụng
A17: =A16+1 -> 13 | B17: Mức độ hỗ trợ đào tạo người sử dụng | C17: 1 | D17: 1 | E17: =$C17*D17 -> 1 | F17: Có yêu cầu hỗ trợ của hệ thống về đào tạo người sử dụng
A18: II | B18: Tổng hệ số kỹ thuật - công nghệ (TFW) | E18: =SUM(E5:E17) -> 38
B19: Hệ số phức tạp về kỹ thuật - công nghệ (TCF) = 0,6 + (0,01 x TFW) | E19: =0.6+(0.01*E18) -> 0.98

Sheet 1.5. EF moi
B1: BẢNG TÍNH TOÁN HỆ SỐ TÁC ĐỘNG MÔI TRƯỜNG VÀ NHÓM LÀM VIỆC, HỆ SỐ PHỨC TẠP VỀ MÔI TRƯỜNG, XÁC ĐỊNH ĐỘ ỔN ĐỊNH KINH NGHIỆM VÀ NỘI SUY THỜI GIAN LAO ĐỘNG
A3: TT | B3: Các hệ số tác động môi trường | C3: Trọng số | D3: Giá trị xếp hạng | E3: Kết quả | F3: Độ ổn định kinh nghiệm | G3: Ghi chú
A4: I | B4: Hệ số tác động môi trường và nhóm làm việc (EFW) | E4: =SUM(E5:E12) -> 15.5
A5: 1 | B5: Có áp dụng quy trình phát triển phần mềm | C5: 1.5 | D5: 3 | E5: =C5*D5 -> 4.5 | F5: =IF(E5<=0,0,IF(E5<=1,0.05,IF(E5<=2,0.1,IF(E5<=3,0.6,1)))) -> 1 | G5: Yêu cầu ít nhất 30% thành viên nhóm phát triển có kinh nghiệm tham gia dự án có áp dụng quy trình phát triển phần mềm.
A6: 2 | B6: Kinh nghiệm phát triển ứng dụng tương tự | C6: 0.5 | D6: 3 | E6: =C6*D6 -> 1.5 | F6: =IF(E6<=0,0,IF(E6<=1,0.05,IF(E6<=2,0.1,IF(E6<=3,0.6,1)))) -> 0.1 | G6: Yêu cầu ít nhất 30% thành viên nhóm phát triển có kinh nghiệm phát triển ứng dụng tương tự
A7: 3 | B7: Kinh nghiệm về hướng đối tượng | C7: 1 | D7: 3 | E7: =C7*D7 -> 3 | F7: =IF(E7<=0,0,IF(E7<=1,0.05,IF(E7<=2,0.1,IF(E7<=3,0.6,1)))) -> 0.6 | G7: Yêu cầu ít nhất 30% thành viên nhóm phát triển có kinh nghiệm về hướng đối tượng
A8: 4 | B8: Kinh nghiệm của trưởng nhóm lập trình | C8: 0.5 | D8: 3 | E8: =C8*D8 -> 1.5 | F8: =IF(E8<=0,0,IF(E8<=1,0.05,IF(E8<=2,0.1,IF(E8<=3,0.6,1)))) -> 0.1 | G8: Yêu cầu trưởng nhóm lập trình đã có kinh nghiệm làm trưởng nhóm lập trình 3 dự án/nhiệm vụ
A9: 5 | B9: Tính chủ động | C9: 1 | D9: 2 | E9: =C9*D9 -> 2 | F9: =IF(E9<=0,0,IF(E9<=1,0.05,IF(E9<=2,0.1,IF(E9<=3,0.6,1)))) -> 0.1 | G9: Yêu cầu nhóm phát triển thực hiện báo cáo công việc theo tháng
A10: 6 | B10: Độ ổn định của các yêu cầu | C10: 2 | D10: 3 | E10: =C10*D10 -> 6 | F10: =IF(E10<=0,0,IF(E10<=1,0.05,IF(E10<=2,0.1,IF(E10<=3,0.6,1)))) -> 1 | G10: Độ ổn định yêu cầu mức 3: Các yêu cầu hệ thống tương đối ổn định, có thể có dưới 10% số lượng Use case liên quan đến những yêu cầu nghiệp vụ cần phân tích, đặc tả cụ thể, chi tiết hơn
A11: 7 | B11: Sử dụng các nhân viên làm bán thời gian | C11: -1 | D11: 0 | E11: =C11*D11 -> 0 | F11: =IF(E11<=0,0,IF(E11<=1,0.05,IF(E11<=2,0.1,IF(E11<=3,0.6,1)))) -> 0 | G11: Không sử dụng nhân viên làm bán thời gian
A12: 8 | B12: Kinh nghiệm sử dụng ngôn ngữ lập trình | C12: -1 | D12: 3 | E12: =C12*D12 -> -3 | F12: =IF(E12<=0,0,IF(E12<=1,0.05,IF(E12<=2,0.1,IF(E12<=3,0.6,1)))) -> 0 | G12: Yêu cầu ít nhất 60% thành viên nhóm lập trình có kinh nghiệm lập trình
A13: II | B13: Hệ số phức tạp về môi trường (EF) | E13: =1.4+(-0.03*E4) -> 0.935
A14: III | B14: Độ ổn định kinh nghiệm (ES) | F14: =SUM(F5:F13) -> 2.9
A15: IV | B15: Nội suy thời gian lao động (P) | F15: =IF(F14<1,48-F14*8,IF(F14<3,40-(F14-1)*7,26-(F14-3)*6/2.2)) -> 26.7
G17: ='1. GTPM'!D22 -> 1.258972e+10
A18: Giá trị nội suy tương ứng của 8 hệ số thành phần: | D18: Kết quả | E18: Giá trị nội suy
D19: <=0 | E19: 0
D20: >0 | E20: 0.05
D21: >1 | E21: 0.1
D22: >2 | E22: 0.6
D23: >3 | E23: 1
A25: Độ ổn định kinh nghiệm | D25: ES | E25: Giá trị nội suy (P)
D26: <1 | E26: 48 – ES x 8
D27: >=1 | E27: 40 – (ES – 1) x 7
D28: >=3 | E28: 26 – (ES – 3) x 6/2,2

Sheet 2.Chi phí KT
A1: CHI PHÍ KIỂM THỬ
A3: TT | B3: Khoản mục chi phí | C3: Cách tính | D3: Giá trị | E3: Ký hiệu
A4: 1 | B4: Giá trị kiểm thử | D4: ='2.1.Giá trị KT'!D14 -> #REF! | E4: G
A5: 2 | B5: Chi phí chung | C5: G x 65% | D5: =D4*65% -> #REF! | E5: C
A6: 3 | B6: Thu nhập chịu thuế tính trước | C6: (G +C) x 6 % | D6: =(D4+D5)*6% -> #REF! | E6: TL
A7: 4 | B7: Chi phí kiểm thử | C7: G + C + TL | D7: =SUM(D4:D6) -> #REF! | E7: Gkt
B8: TỔNG CỘNG | C8: Gkt | D8: =ROUNDDOWN(D7,-5) -> #REF!

Sheet 2.1.Giá trị KT
B1: GIÁ TRỊ KIỂM THỬ
A3: TT | B3: Hạng mục | C3: Diễn giải | D3: Giá trị | E3: Ghi chú
A4: I | B4: Tính điểm trường hợp sử dụng (Use-case)
A5: 1 | B5: Điểm Actor (UAW) | D5: ='2.3.AW'!F6 -> 17
A6: 2 | B6: Điểm Use case (UUCW) | D6: ='2.2.UCW'!E6 -> 1720
A7: 3 | B7: Tính điểm UUCP | C7: UUCP = AW +UCW | D7: =D5+D6 -> 1737
A8: 4 | B8: Hệ số phức tạp về KT-CN (TCF) | C8: TCF= 0,6+0,014*TTF | D8: ='2.4.Hệ số phức tạp về KT- TCF'!E12 -> #REF!
A9: 5 | B9: Hệ số phức tạp về môi trường (ECF) | C9: ECF= 1,14+(-0,0362)*TEF | D9: ='2.5.Hệ số phức tạp về MT - ECF'!O13 -> 0.6941
A10: 6 | B10: Tính điểm AUCP | C10: AUCP =UUCP *TCF*ECF | D10: =D7*D8*D9 -> #REF!
A11: II | B11: Nội suy thời gian lao động (P) | C11: P (người/giờ/AUCP) | D11: 8
A12: III | B12: Giá trị nỗ lực thực tế (E) | C12: E = AUCP x P | D12: =D10*D11 -> #REF!
A13: IV | B13: Mức lương lao động bình quân (H) | C13: H = người/giờ | D13: ='Bang luong'!C19 -> 64101 | E13: KS1
A14: V | B14: Giá trị kiểm thử phần mềm (G) | C14: G = E*H | D14: =D12*D13 -> #REF! | E14: đồng

Sheet 2.2.UCW
A1: Giá trị điểm các trường hợp sử dụng (UCW)
A2: TT | B2: Loại | C2: Trọng số | D2: Số use case | E2: Kết quả | F2: Ghi chú
A3: 1 | B3: Đơn giản | C3: 5 | D3: ='1.3. TBF'!E6 -> 163 | E3: =C3*D3 -> 815
A4: 2 | B4: Trung bình | C4: 10 | D4: ='1.3. TBF'!E7 -> 53 | E4: =C4*D4 -> 530
A5: 3 | B5: Phức tạp | C5: 15 | D5: ='1.3. TBF'!E8 -> 25 | E5: =C5*D5 -> 375
B6: Cộng | E6: =SUM(E3:E5) -> 1720

Sheet 2.3.AW
A1: Giá trị điểm các tác nhân (AW)
A2: TT | B2: Loại Actor | C2: Mô tả | D2: Trọng số | E2: Số Actor | F2: Kết quả | G2: Ghi chú
A3: 1 | B3: Đơn giản (simple actor) | C3: Thuộc loại giao diện của chương trình | D3: 1 | E3: ='1.2.TAW'!D5 -> 2 | F3: =E3*D3 -> 2
A4: 2 | B4: Trung bình (average actor) | C4: Giao diện tương tác hoặc phục vụ một giao thức hoạt động | D4: 2 | E4: ='1.2.TAW'!D6 -> 0 | F4: =E4*D4 -> 0
A5: 3 | B5: Phức tạp (complex actor) | C5: Giao diện đồ họa: | D5: 3 | E5: ='1.2.TAW'!D7 -> 5 | F5: =E5*D5 -> 15
B6: Cộng | F6: =SUM(F3:F5) -> 17

Sheet 2.4.Hệ số phức tạp về KT- TCF
A1: BẢNG TÍNH TOÁN HỆ SỐ PHỨC TẠP KỸ THUẬT | G1: ='2.Chi phí KT'!D8 -> #REF!
A2: TT | B2: Các hệ số KT | C2: Trọng số chuẩn | D2: Giá trị xếp hạng | E2: Kết quả | F2: Diễn giải lý do
A3: I | B3: Hệ số KT-CN (TTF)
A4: T1 | B4: Các công cụ kiểm thử | C4: 2 | D4: 2 | E4: =D4*C4 -> 4 | F4: Có sử dụng công cụ kiểm thử mất phí không? Có sử dụng công cụ kiểm thử trực tiếp không? Có cần công cụ hỗ trợ trong quá trình kiểm thử không? Có đòi hỏi các công cụ quản lý quy trình kiểm thử không?
A5: T2 | B5: Tài liệu đầu vào | C5: 2 | D5: 2 | E5: =D5*C5 -> 4 | F5: Tài liệu yêu cầu người dùng có đủ theo yêu cầu hay không? Tài liệu mô tả kiến trúc hệ thống có đủ theo yêu cầu hay không? Tài liệu xác định yêu cầu kiểm thử có đúng theo yêu cầu hay không?
A6: T3 | B6: Tái sử dụng kho dữ liệu kiểm thử | C6: 1 | D6: 2 | E6: =D6*C6 -> 2 | F6: Dự án có sử dụng lại kho dữ liệu hay không?
A7: T4 | B7: Hệ thống phân tán | C7: 2 | D7: ='[59]1.4'!D5 -> #REF! | E7: =D7*C7 -> #REF! | F7: Kiến trúc của hệ thống là tập trung hay phân tán? Hệ thống được thiết kế theo mô hình nhiều lớp hay không? Trọng số càng cao tương ứng với hệ thống càng phức tạp.
A8: T5 | B8: Các mục tiêu hiệu suất | C8: 1 | D8: 2 | E8: =D8*C8 -> 2 | F8: Hệ thống đáp ứng được bao nhiêu người sử dụng đồng thời? Số giao dịch hay số yêu cầu tối đa mà hệ thống có thể phục vụ ? Tài nguyên hệ thống, tài nguyên mạng hệ thống đòi hỏi để đáp ứng các tham số trên? Thời gian tối thiểu để hoàn thành một giao dịch?
A9: T6 | B9: Các tính năng bảo mật | C9: 1 | D9: 2 | E9: =D9*C9 -> 2 | F9: Hệ thống có đảm bảo an toàn thông tin, hạn chế và khắc phục các lỗ hổng bảo mật? Khả năng nâng cao các chức năng an toàn bảo mật cho hệ thống và cập nhật nhanh chóng các bản vá lỗi ngay khi lỗi được phát hiện.
A10: T7 | B10: Giao diện phức tạp | C10: 1 | D10: 2 | E10: =D10*C10 -> 2 | F10: Giao diện sử dụng phương pháp thiết kế và bố cục đòi hỏi kỹ năng thiết kế ở mức cao, khả năng sáng tạo, tính logic trong thiết kế và tính thuận tiện, đơn giản với người sử dụng.
B11: Cộng I (TTF) | C11: Total TF | E11: =SUM(E3:E10) -> #REF!
B12: TCF | C12: TCF=0,6+(0,014)*TTF | E12: =0.6+0.014*E11 -> #REF!

Sheet 2.5.Hệ số phức tạp về MT - ECF
A1: BẢNG 6.6. TÍNH HỆ SỐ PHỨC TẠP MÔI TRƯỜNG | Q1: ='2.Chi phí KT'!D8 -> #REF!
A2: Các hệ số tác động môi trường | B2: Mức xếp hạng (Từ 0 đến 5) | C2: Trọng số chuẩn | D2: NV 1 | E2: NV 2 | F2: NV 3 | G2: NV 4 | H2: NV 5 | I2: NV 6 | J2: NV 7 | K2: NV 8 | L2: NV 9 | M2: NV 10 | N2: TB cộng giá trị xếp hạng | O2: Kết quả (KQ) | P2: Đánh giá độ ổn định KN (ESNV)
A3: Hệ số tác động môi trường (TEF)
A5: Có hiểu biết về ứng dụng | B5: 0 = Không có hiểu biết 3 = Trung bình 5 = Trình độ chuyên gia | C5: 1.5 | D5: 1 | E5: 3 | F5: 2 | G5: 2 | H5: 2 | N5: 3 | O5: =N5*C5 -> 4.5 | P5: =IF(O5>3,1,IF(O5>2,0.6,IF(O5>1,0.1,IF(O5>0,0.05,IF(O5<=0,0))))) -> 1
A6: Môi trường kiểm thử | B6: 0 = Không cần 3 = Không phức tạp 5 = Rất phức tạp | C6: 0.5 | D6: 5 | E6: 3 | F6: 2 | G6: 2 | H6: 2 | N6: 3 | O6: =N6*C6 -> 1.5 | P6: =IF(O6>3,1,IF(O6>2,0.6,IF(O6>1,0.1,IF(O6>0,0.05,IF(O6<=0,0))))) -> 0.1
A7: Dữ liệu kiểm thử | B7: 0 = Không cần 3 = Cần ít 5 = Cần rất nhiều | C7: 1 | D7: 3 | E7: 3 | F7: 2 | G7: 2 | H7: 2 | N7: 3 | O7: =N7*C7 -> 3 | P7: =IF(O7>3,1,IF(O7>2,0.6,IF(O7>1,0.1,IF(O7>0,0.05,IF(O7<=0,0))))) -> 0.6
A8: Có khả năng lãnh đạo Nhóm kiểm thử | B8: 0 = Không có kinh nghiệm 3 = Trung bình 5 = Trình độ chuyên gia | C8: 0.5 | D8: 1 | E8: 3 | F8: 2 | G8: 1 | H8: 2 | N8: 3 | O8: =N8*C8 -> 1.5 | P8: =IF(O8>3,1,IF(O8>2,0.6,IF(O8>1,0.1,IF(O8>0,0.05,IF(O8<=0,0))))) -> 0.1
A9: Tính chất năng động | B9: 0 = Không năng động 3 = Trung bình 5 = Cao | C9: 1 | D9: 2 | E9: 3 | F9: 2 | G9: 1 | H9: 0 | N9: 3 | O9: =N9*C9 -> 3 | P9: =IF(O9>3,1,IF(O9>2,0.6,IF(O9>1,0.1,IF(O9>0,0.05,IF(O9<=0,0))))) -> 0.6
A10: Độ ổn định của các yêu cầu | B10: 0 = Rất bất định 5 = Không hay thay đổi | C10: 2 | D10: 2 | E10: 1 | F10: 3 | G10: 2 | H10: 2 | N10: 3 | O10: =N10*C10 -> 6 | P10: =IF(O10>3,1,IF(O10>2,0.6,IF(O10>1,0.1,IF(O10>0,0.05,IF(O10<=0,0))))) -> 1
A11: Có sử dụng các nhân viên làm Part-time | B11: 0 = Không có NV Part-time 3 = Có nhân viên làm Part-time 5 = Tất cả đều làm Part-time | C11: -1 | D11: 0 | E11: 0 | F11: 0 | G11: 0 | H11: 0 | N11: 0 | O11: =N11*C11 -> 0 | P11: =IF(O11>3,1,IF(O11>2,0.6,IF(O11>1,0.1,IF(O11>0,0.05,IF(O11<=0,0))))) -> 0
A12: Cộng I (TEF) | B12: Total EF | O12: =SUM(O3:O11) -> 19.5
A13: Hệ số độ phức tạp về môi trường ECF (Environmental Complex Factor) | B13: ECF = 1,4+(-0,0362)* TEF | O13: =1.4-0.0362*O12 -> 0.6941

Sheet Bang luong
B1: Phân loại | C1: Giá trị
B2: Chọn Vùng/Khu vực | C2: I
B3: Hệ số điều chỉnh | C3: =IFERROR(HLOOKUP(C2,$C$30:$F$31,2,TRUE),"") -> 1.2
B4: Lương tối thiểu vùng | C4: =IFERROR(HLOOKUP(C2,$C$34:$F$35,2,TRUE),"") -> 4960000
A6: DIỄN GIẢI CHI PHÍ TIỀN LƯƠNG GIỜ THEO QĐ 129/QĐ-BTTTT NGÀY 3/2/2021
J7: Đơn vị tính: đồng
A8: TT | B8: Tiêu chí xác định | C8: Cấp bậc, hệ số, mức lương | K8: Ghi chú
A9: 1 | B9: Bậc thâm niên ngạch kỹ sư (A3) | C9: KS1 | D9: KS2 | E9: KS3 | F9: KS4 | G9: KS5 | H9: KS6 | I9: KS7 | J9: KS8
A10: 2 | B10: HCB (Hệ số lương) | C10: 2.34 | D10: 2.65 | E10: 2.96 | F10: 3.27 | G10: 3.58 | H10: 3.89 | I10: 4.2 | J10: 4.51 | K10: Quyết định 129/QĐ-BTTTT ngày 3/2/2021
A11: 3 | B11: MLCS (Mức lương cơ sở) | C11: 2340000 | D11: 2340000 | E11: 2340000 | F11: 2340000 | G11: 2340000 | H11: 2340000 | I11: 2340000 | J11: 2340000 | K11: Nghị định 73/2024/NĐ-CP ngày 30/6/2023 của Thủ tướng Chính phủ quy định mức lương cơ sở đối với cán bộ, công chức, viên chức và lực lượng vũ trang
A12: 4 | B12: HĐC (hệ số điều chỉnh tăng thêm tiền lương) | C12: =$C$3 -> 1.2 | D12: =$C$3 -> 1.2 | E12: =$C$3 -> 1.2 | F12: =$C$3 -> 1.2 | G12: =$C$3 -> 1.2 | H12: =$C$3 -> 1.2 | I12: =$C$3 -> 1.2 | J12: =$C$3 -> 1.2 | K12: ="Quyết định 129/QĐ-BTTTT ngày 3/2/2021, với địa bàn vùng "&TEXT(C2,0) -> Quyết định 129/QĐ-BTTTT ngày 3/2/2021, với địa bàn vùng I
B13: LCB (lương cơ bản/tháng) | C13: =C10*C11 -> 5475600 | D13: =D10*D11 -> 6201000 | E13: =E10*E11 -> 6926400 | F13: =F10*F11 -> 7651800 | G13: =G10*G11 -> 8377200 | H13: =H10*H11 -> 9102600 | I13: =I10*I11 -> 9828000 | J13: =J10*J11 -> 10553400 | K13: LCB=HCB*MLCS
A14: 4 | B14: MLCB (Mức lương cơ bản /tháng) | C14: =(1+C12)*C10*C11 -> 12046320 | D14: =(1+D12)*D10*D11 -> 13642200 | E14: =(1+E12)*E10*E11 -> 15238080 | F14: =(1+F12)*F10*F11 -> 16833960 | G14: =(1+G12)*G10*G11 -> 18429840 | H14: =(1+H12)*H10*H11 -> 20025720 | I14: =(1+I12)*I10*I11 -> 21621600 | J14: =(1+J12)*J10*J11 -> 23217480 | K14: MLCB=HCB*MLCS*(1+HĐC)
B15: LTT (Mức lương tối thiểu vùng) | C15: =$C$4 -> 4960000 | D15: =$C$4 -> 4960000 | E15: =$C$4 -> 4960000 | F15: =$C$4 -> 4960000 | G15: =$C$4 -> 4960000 | H15: =$C$4 -> 4960000 | I15: =$C$4 -> 4960000 | J15: =$C$4 -> 4960000 | K15: Mức lương tối thiểu vùng I
A16: 6 | B16: BHLĐ: Chi phí BHXH, BHYT, BHTN, KPCĐ của người sử dụng lao động | C16: =ROUND(IF(C13>=C15,0.235*C13,0.235*C15),0) -> 1286766 | D16: =ROUND(IF(D13>=D15,0.235*D13,0.235*D15),0) -> 1457235 | E16: =ROUND(IF(E13>=E15,0.235*E13,0.235*E15),0) -> 1627704 | F16: =ROUND(IF(F13>=F15,0.235*F13,0.235*F15),0) -> 1798173 | G16: =ROUND(IF(G13>=G15,0.235*G13,0.235*G15),0) -> 1968642 | H16: =ROUND(IF(H13>=H15,0.235*H13,0.235*H15),0) -> 2139111 | I16: =ROUND(IF(I13>=I15,0.235*I13,0.235*I15),0) -> 2309580 | J16: =ROUND(IF(J13>=J15,0.235*J13,0.235*J15),0) -> 2480049 | K16: BHXH: 17,5%; BHYT: 3% BHTN: 1% (Quyết định 595/QĐ-BHXH ngày 14/4/2017), KPCD là 2% (Nghị định 191/2013/NĐ-CP ngày 21/11/2013) Tổng là 23,5% BHLĐ được tính như sau: + nếu LCB<LTT thì BHLĐ=23,5%*LTT + Nếu LCB>=LTT thì BHLĐ=23,5%*LCB
A17: 7 | B17: Tổng lương/tháng | C17: =C14+C16 -> 13333086 | D17: =D14+D16 -> 15099435 | E17: =E14+E16 -> 16865784 | F17: =F14+F16 -> 18632133 | G17: =G14+G16 -> 20398482 | H17: =H14+H16 -> 22164831 | I17: =I14+I16 -> 23931180 | J17: =J14+J16 -> 25697529 | K17: MLCB+ BHLĐ
A18: 8 | B18: Mức lương lao động/ngày | C18: =ROUND((C14+C16)/26,0) -> 512811 | D18: =ROUND((D14+D16)/26,0) -> 580748 | E18: =ROUND((E14+E16)/26,0) -> 648684 | F18: =ROUND((F14+F16)/26,0) -> 716621 | G18: =ROUND((G14+G16)/26,0) -> 784557 | H18: =ROUND((H14+H16)/26,0) -> 852494 | I18: =ROUND((I14+I16)/26,0) -> 920430 | J18: =ROUND((J14+J16)/26,0) -> 988367 | K18: =(MLCB+ BHLĐ)/26 - 1 tháng: 26 ngày làm việc
A19: 9 | B19: Mức lương lao động/giờ | C19: =ROUND(C18/8,0) -> 64101 | D19: =ROUND(D18/8,0) -> 72594 | E19: =ROUND(E18/8,0) -> 81086 | F19: =ROUND(F18/8,0) -> 89578 | G19: =ROUND(G18/8,0) -> 98070 | H19: =ROUND(H18/8,0) -> 106562 | I19: =ROUND(I18/8,0) -> 115054 | J19: =ROUND(J18/8,0) -> 123546 | K19: - Thời gian lao động 08 giờ/ngày
B21: Ghi chú:
B22: - Lương cơ sở: Nghị định số 24/2023/NĐ-CP ngày 14/5/2023 - Các chi phí bảo hiểm căn cứ theo Quyết định 595/QĐ-BHXH ngày 14/4/2017 của BHXHVN ban hành quy trình thu BHXH,, BHYT, BHTN, BHTN lao động-bệnh nghề nghiệp, quản lý số BHXH, thẻ BHYT - Chi phí công đoàn căn cứ theo Nghị định 191/2013/NĐ-CP ngày 21/11/2013 quy định chi tiết về tài chính công đoàn - Quyết định số 129/QĐ-BTTTT ngày 03/02/2021 ban hành hướng dẫn xác định đơn giá nhân công trong quản lý chi phí đầu tư ứng dụng CNTT
B23: Giải thích:
B24: BHXH
B25: BHYT | C25: Tiền lương tháng đóng BHYT là tiền lương tháng đóng BHXH | I25: Điều 18 Quyết định 595/QĐ-BHXH
B26: BHTN | C26: Tiền lương tháng đóng BHTN là tiền lương làm căn cứ đóng BHXH | I26: Điều 15 Quyết định 595/QĐ-BHXH
B27: KPCĐ | C27: Kinh phí công đoàn của người sử dụng lao động làm căn cứ đóng BHXH | I27: Điều 5 Nghị định 191/2013/NĐ-CP ngày 21/11/2013
B29: Quyết định 129/QĐ-BTTTT ngày 3/2/2021
B30: Vùng | C30: I | D30: II | E30: III | F30: IV
B31: Hệ số điều chỉnh | C31: 1.2 | D31: 0.9 | E31: 0.7 | F31: 0.5
B33: Nghị định 38/2022/NĐ-CP quy định về mức lương tối thiểu vùng áp dụng đối với người lao động làm việc theo hợp đồng lao động
B34: Vùng | C34: I | D34: II | E34: III | F34: IV
B35: Mức lương tối thiểu vùng áp dụng đối với người lao động làm việc ở doanh nghiệp | C35: 4960000 | D35: 4410000 | E35: 3860000 | F35: 3450000
B37: Nghị định số 73/2024/NĐ-CP ngày 30/6/2024
B38: Mức lương cơ sở (Từ ngày 01 tháng 7 năm 2024) | C38: 2340000
A40: TT | B40: Tiêu chí xác định | C40: Cấp bậc, hệ số, mức lương | K40: Ghi chú
A41: 1 | B41: Bậc thâm niên ngạch công nhân | C41: CN1 | D41: CN2 | E41: CN3 | F41: CN4 | G41: CN5 | H41: CN6 | I41: CN7
A42: 2 | B42: HCB (Hệ số lương) | C42: 1.45 | D42: 1.71 | E42: 2.03 | F42: 2.39 | G42: 2.83 | H42: 3.34 | I42: 3.95 | K42: Quyết định 129/QĐ-BTTTT ngày 3/2/2021
A43: 3 | B43: MLCS (Mức lương cơ sở) | C43: =$C$38 -> 2340000 | D43: =$C$38 -> 2340000 | E43: =$C$38 -> 2340000 | F43: =$C$38 -> 2340000 | G43: =$C$38 -> 2340000 | H43: =$C$38 -> 2340000 | I43: =$C$38 -> 2340000 | K43: Nghị định 24/2023/NĐ-CP ngày 14/5/2023 của Thủ tướng Chính phủ quy định mức lương cơ sở đối với cán bộ, công chức, viên chức và lực lượng vũ trang
A44: 4 | B44: HĐC (hệ số điều chỉnh tăng thêm tiền lương) | C44: =$C$3 -> 1.2 | D44: =$C$3 -> 1.2 | E44: =$C$3 -> 1.2 | F44: =$C$3 -> 1.2 | G44: =$C$3 -> 1.2 | H44: =$C$3 -> 1.2 | I44: =$C$3 -> 1.2 | K44: Quyết định 129/QĐ-BTTTT ngày 3/2/2021, với địa bàn vùng I
B45: LCB (lương cơ bản/tháng) | C45: =C42*C43 -> 3393000 | D45: =D42*D43 -> 4001400 | E45: =E42*E43 -> 4750200 | F45: =F42*F43 -> 5592600 | G45: =G42*G43 -> 6622200 | H45: =H42*H43 -> 7815600 | I45: =I42*I43 -> 9243000 | K45: LCB=HCB*MLCS
A46: 4 | B46: MLCB (Mức lương cơ bản /tháng) | C46: =(1+C44)*C42*C43 -> 7464600 | D46: =(1+D44)*D42*D43 -> 8803080 | E46: =(1+E44)*E42*E43 -> 10450440 | F46: =(1+F44)*F42*F43 -> 12303720 | G46: =(1+G44)*G42*G43 -> 14568840 | H46: =(1+H44)*H42*H43 -> 17194320 | I46: =(1+I44)*I42*I43 -> 20334600 | K46: MLCB=HCB*MLCS*(1+HĐC)
...

Sheet 1688
B3: 2. Bảng số 1: Định mức chi phí quản lý dự án
B5: a) Hạng mục hạ tầng kỹ thuật công nghệ thông tin | L5: Đơn vị tính: tỷ lệ %
B6: STT | C6: Loại hạng mục | D6: Chi phí xây lắp và thiết bị (chưa có thuế GTGT) (tỷ đồng)
D7: ≤ 7 | E7: 15 | F7: 20 | G7: 30 | H7: 50 | I7: 100 | J7: 150 | K7: 200 | L7: 500 | M7: 1000
B8: 1 | C8: Hạng mục hạ tầng kỹ thuật công nghệ thông tin | D8: 2.644 | E8: 2.184 | F8: 1.913 | G8: 1.747 | H8: 1.324 | I8: 1.045 | J8: 1.007 | K8: 0.975 | L8: 0.841 | M8: 0.696
B9: 2 | C9: Hạng mục hạ tầng kỹ thuật công nghệ thông tin trong báo cáo Kinh tế - Kỹ thuật, ĐC DTCT | D9: =D8*0.84 -> 2.22096 | E9: =E8*0.84 -> 1.83456 | F9: =F8*0.84 -> 1.60692 | G9: =G8*0.84 -> 1.46748 | H9: =H8*0.84 -> 1.11216 | I9: =I8*0.84 -> 0.8778 | J9: =J8*0.84 -> 0.84588 | K9: =K8*0.84 -> 0.819 | ... M9: =M8*0.84 -> 0.58464
B11: Trường hợp báo cáo kinh tế - kỹ thuật, đề cương và dự toán chi tiết Hạng mục hạ tầng kỹ thuật công nghệ thông tin thì định mức chi phí quản lý dự án/chi phí quản lý tính bằng 0,84 lần định mức chi phí quản lý dự án, tương ứng với quy mô giá trị xây lắp và thiết bị.
B12: Trường hợp thuê dịch vụ Hạng mục hạ tầng kỹ thuật công nghệ thông tin có giá trị giá trị chi phí đầu tư xây dựng, phát triển hình thành dịch vụ công nghệ thông tin lớn hơn 15 tỷ thì định mức chi phí quản lý được tính bằng 0,84 lần định mức chi phí quản lý dự án Hạng mục hạ tầng kỹ thuật công nghệ thông tin, tương ứng với quy mô giá trị xây lắp và thiết bị.
B14: b) Hạng mục phần mềm nội bộ, cơ sở dữ liệu
J15: Đơn vị tính: tỷ lệ %
B16: STT | C16: Loại hạng mục | D16: Chi phí thiết bị (chưa có thuế GTGT) (tỷ đồng)
D17: ≤ 7 | E17: 15 | F17: 20 | G17: 30 | H17: 50 | I17: 100 | J17: 150 | K17: 200
B18: 2 | C18: Hạng mục phần mềm nội bộ, cơ sở dữ liệu | D18: 2.809 | E18: 2.133 | F18: 1.964 | G18: 1.782 | H18: 1.71 | I18: 1.346 | J18: 1.287 | K18: 1.248
B19: 3 | C19: Hạng mục phần mềm nội bộ, cơ sở dữ liệu trong Báo cáo kinh tế - kỹ thuật | D19: 1.855 | E19: 1.532
B21: Trường hợp đề cương và dự toán chi tiết Hạng mục phần mềm nội bộ, cơ sở dữ liệu thì định mức chi phí quản lý tính bằng định mức Hạng mục phần mềm nội bộ, cơ sở dữ liệu trong Báo cáo kinh tế - kỹ thuật tương ứng với quy mô giá trị thiết bị.
B22: Trường hợp thuê dịch vụ Hạng mục phần mềm nội bộ, cơ sở dữ liệu có giá trị chi phí đầu tư xây dựng, phát triển hình thành dịch vụ công nghệ thông tin lớn hơn 15 tỷ thì định mức chi phí quản lý được tính bằng định mức Hạng mục phần mềm nội bộ, cơ sở dữ liệu trong Báo cáo kinh tế - kỹ thuật tương ứng với quy mô giá trị thiết bị bằng 15 tỷ.
B24: 2.2. Bảng số 2: Định mức chi phí lập dự án đầu tư
B25: a) Hạng mục hạ tầng kỹ thuật công nghệ thông tin
L26: Đơn vị tính: tỷ lệ %
B27: STT | C27: Loại hạng mục | D27: Chi phí xây lắp và thiết bị (chưa có thuế GTGT) (tỷ đồng)
D28: ≤ 7 | E28: 15 | F28: 20 | G28: 30 | H28: 50 | I28: 100 | J28: 150 | K28: 200 | L28: 500 | M28: 1000
B29: 1 | C29: Hạng mục hạ tầng kỹ thuật công nghệ thông tin | D29: 0.992 | E29: 0.739 | F29: 0.652 | G29: 0.533 | H29: 0.42 | I29: 0.31 | J29: 0.253 | K29: 0.205 | L29: 0.164 | M29: 0.144
B30: 2 | C30: Hạng mục hạ tầng kỹ thuật công nghệ thông tin về định mức chi phí lập BC Kinh tế - kỹ thuật | D30: =D29*1.65 -> 1.6368 | E30: =E29*1.65 -> 1.21935 | F30: =F29*1.65 -> 1.0758 | G30: =G29*1.65 -> 0.87945 | H30: =H29*1.65 -> 0.693 | I30: =I29*1.65 -> 0.5115 | J30: =J29*1.65 -> 0.41745 | K30: =K29*1.65 -> 0.33825 | ... M30: =M29*1.65 -> 0.2376
B32: Định mức chi phí lập báo cáo kinh tế - kỹ thuật, đề cương và dự toán chi tiết Hạng mục hạ tầng kỹ thuật công nghệ thông tin được tính bằng 1,65 lần định mức chi phí lập dự án đầu tư, tương ứng với quy mô giá trị xây lắp và thiết bị.
B33: Trường hợp thuê dịch vụ Hạng mục hạ tầng kỹ thuật công nghệ thông tin có giá trị chi phí đầu tư xây dựng, phát triển hình thành dịch vụ công nghệ thông tin lớn hơn 15 tỷ thì định mức chi phí lập kế hoạch thuê/dự án thuê được tính bằng 1,65 lần định mức chi phí lập dự án đầu tư Hạng mục hạ tầng kỹ thuật công nghệ thông tin, tương ứng với quy mô giá trị xây lắp và thiết bị.
B35: b) Hạng mục phần mềm nội bộ, cơ sở dữ liệu
J36: Đơn vị tính: tỷ lệ %
B37: STT | C37: Loại hạng mục | D37: Chi phí thiết bị (chưa có thuế GTGT) (tỷ đồng)
D38: ≤ 7 | E38: 15 | F38: 20 | G38: 30 | H38: 50 | I38: 100 | J38: 150 | K38: 200
B39: 2 | C39: Hạng mục phần mềm nội bộ, cơ sở dữ liệu | D39: 0.992 | E39: 0.906 | F39: 0.812 | G39: 0.763 | H39: 0.648 | I39: 0.485 | J39: 0.437 | K39: 0.381
B40: 3 | C40: Hạng mục phần mềm nội bộ, cơ sở dữ liệu trong Báo cáo kinh tế - kỹ thuật | D40: 3.64 | E40: 3.24
B42: Định mức chi phí lập đề cương và dự toán chi tiết Hạng mục phần mềm nội bộ, cơ sở dữ liệu được tính bằng định mức chi phí lập báo cáo kinh tế kỹ thuật, tương ứng với quy mô giá trị thiết bị.
B43: Trường hợp thuê dịch vụ Hạng mục phần mềm nội bộ, cơ sở dữ liệu có giá trị chi phí đầu tư xây dựng, phát triển hình thành dịch vụ công nghệ thông tin lớn hơn 15 tỷ thì định mức chi phí lập kế hoạch thuê/dự án thuê được tính bằng định mức chi phí lập thiết kế thi công và dự toán Hạng mục phần mềm nội bộ, cơ sở dữ liệu (tại mục b Bảng số 3), tương ứng với quy mô giá trị xây lắp và thiết bị.
B44: Ghi chú:
C45: - Việc xác định tỷ trọng chi phí để thực hiện phần thuyết minh, thiết kế sơ bộ và tổng mức đầu tư trong chi phí lập dự án đầu tư, tỷ trọng chi phí để thực hiện phần thuyết minh, thiết kế và dự toán trong chi phí lập báo cáo kinh tế - kỹ thuật do các bên giao nhận thầu thực hiện công việc trên thỏa thuận.
C46: - Chi phí lập dự án đầu tư, chi phí lập báo cáo kinh tế - kỹ thuật, lập đề cương và dự toán chi tiết xác định theo định mức nhưng tối thiểu không nhỏ hơn 10.000.000 đồng đối với lập báo cáo kinh tế - kỹ thuật và 5.000.000 đồng đối với lập đề cương và dự toán chi tiết (chưa bao gồm thuế giá trị gia tăng).
B48: 3.2. Bảng số 3: Định mức chi phí lập thiết kế thi công và dự toán
B49: a) Hạng mục hạ tầng kỹ thuật công nghệ thông tin | L49: Đơn vị tính: tỷ lệ %
B50: STT | C50: Loại hạng mục | D50: Chi phí xây lắp và thiết bị (chưa có thuế GTGT) (tỷ đồng)
D51: ≤ 7 | E51: 15 | F51: 20 | G51: 30 | H51: 50 | I51: 100 | J51: 150 | K51: 200 | L51: 500 | M51: 1000
...
