Workbook
Name _: #REF!
Name _: #REF!
Name _________________________Goi8: {"'Sheet1'!$L$16"}
Name _________________________Goi8: {"'Sheet1'!$L$16"}
Name _________________________Lan1: {"'Sheet1'!$L$16"}
Name _________________________Lan1: {"'Sheet1'!$L$16"}
Name _________________________LAN3: {"'Sheet1'!$L$16"}
Name _________________________LAN3: {"'Sheet1'!$L$16"}
Name _________________________TM2: {"'Sheet1'!$L$16"}
Name _________________________TM2: {"'Sheet1'!$L$16"}
Name ________________________a1: {"'Sheet1'!$L$16"}
Name ________________________a1: {"'Sheet1'!$L$16"}
Name ________________________Goi8: {"'Sheet1'!$L$16"}
Name ________________________Goi8: {"'Sheet1'!$L$16"}
Name ________________________Lan1: {"'Sheet1'!$L$16"}
Name ________________________Lan1: {"'Sheet1'!$L$16"}
Name ________________________LAN3: {"'Sheet1'!$L$16"}
Name ________________________LAN3: {"'Sheet1'!$L$16"}
Name ________________________TM2: {"'Sheet1'!$L$16"}
Name ________________________TM2: {"'Sheet1'!$L$16"}
Name _______________________a1: {"'Sheet1'!$L$16"}
Name _______________________a1: {"'Sheet1'!$L$16"}
Name _______________________Goi8: {"'Sheet1'!$L$16"}
Name _______________________Goi8: {"'Sheet1'!$L$16"}
Name _______________________hu2: {"'Sheet1'!$L$16"}
Name _______________________hu2: {"'Sheet1'!$L$16"}
Name _______________________hu5: {"'Sheet1'!$L$16"}
Name _______________________hu5: {"'Sheet1'!$L$16"}
Name _______________________hu6: {"'Sheet1'!$L$16"}
Name _______________________hu6: {"'Sheet1'!$L$16"}
Name _______________________Lan1: {"'Sheet1'!$L$16"}
Name _______________________Lan1: {"'Sheet1'!$L$16"}
Name _______________________LAN3: {"'Sheet1'!$L$16"}
Name _______________________LAN3: {"'Sheet1'!$L$16"}
Name _______________________PA3: {"'Sheet1'!$L$16"}
Name _______________________PA3: {"'Sheet1'!$L$16"}
Name _______________________TM2: {"'Sheet1'!$L$16"}
Name _______________________TM2: {"'Sheet1'!$L$16"}
Name ______________________a1: {"'Sheet1'!$L$16"}
Name ______________________a1: {"'Sheet1'!$L$16"}
Name ______________________Goi8: {"'Sheet1'!$L$16"}
Name ______________________Goi8: {"'Sheet1'!$L$16"}
Name ______________________hu1: {"'Sheet1'!$L$16"}
Name ______________________hu1: {"'Sheet1'!$L$16"}
Name ______________________hu2: {"'Sheet1'!$L$16"}
Name ______________________hu2: {"'Sheet1'!$L$16"}
Name ______________________hu5: {"'Sheet1'!$L$16"}
Name ______________________hu5: {"'Sheet1'!$L$16"}
Name ______________________hu6: {"'Sheet1'!$L$16"}
Name ______________________hu6: {"'Sheet1'!$L$16"}
Name ______________________Lan1: {"'Sheet1'!$L$16"}
Name ______________________Lan1: {"'Sheet1'!$L$16"}
Name ______________________LAN3: {"'Sheet1'!$L$16"}
Name ______________________LAN3: {"'Sheet1'!$L$16"}
Name ______________________PA3: {"'Sheet1'!$L$16"}
Name ______________________PA3: {"'Sheet1'!$L$16"}
Name ______________________TM2: {"'Sheet1'!$L$16"}
Name ______________________TM2: {"'Sheet1'!$L$16"}
Name ______________________tt3: {"'Sheet1'!$L$16"}
Name ______________________tt3: {"'Sheet1'!$L$16"}

Sheet B1.TMĐT_DV CNTT
B2: BẢNG 1: BẢNG TỔNG MỨC ĐẦU TƯ
A3: BẢNG TỔNG MỨC ĐẦU TƯ
C4: Đơn vị tính: VNĐ
A5: STT | B5: Nội dung chi phí | C5: Giá trị sau thuế
A6: 1 | B6: Chi phí thuê DV CNTT | C6: =G17 -> 3.3330015e+09
A7: 2 | B7: Chi phí quản lý | C7: =G27 -> 74382286
A8: 3 | B8: Chi phí tư vấn | C8: =G30 -> 1.4657502e+08
A9: 4 | B9: Chi phí khác | C9: =G39 -> 3.9090067e+08
A10: 5 | B10: Chi phí dự phòng | C10: =G42 -> 1.9724297e+08
A11: TỔNG CỘNG (1+2+3+4+5) | C11: =SUM(C6:C10) -> 4.1421025e+09
A12: TỔNG CỘNG (Làm tròn) | C12: =ROUNDUP(C11,-6) -> 4143000000
A14: Diễn giải bảng Tổng mức đầu tư
H15: Đơn vị tính: Đồng
A16: TT | B16: Hạng mục chi phí | C16: Ký hiệu | D16: Giá trị trước thuế | E16: Thuế GTGT (%) | F16: Thuế GTGT | G16: Giá trị sau thuế | H16: Ghi chú
A17: I | B17: Chi phí thuê dịch vụ CNTT | C17: Gt | D17: =SUBTOTAL(9,D18:D26) -> 3.0377475e+09 | F17: =SUBTOTAL(9,F18:F26) -> 295254000 | G17: =SUBTOTAL(9,G18:G26) -> 3.3330015e+09
A18: 1 | B18: Chi phí thuê dịch vụ phần mềm nội bộ, CSDL | D18: =SUBTOTAL(9,D19:D20) -> 3.0377475e+09 | F18: =SUBTOTAL(9,F19:F20) -> 295254000 | G18: =SUBTOTAL(9,G19:G20) -> 3.3330015e+09
A19: 1.1 | B19: Chi phí thuê phần mềm Ecabinet 3 năm | D19: =G19/1.1 -> 2952540000 | E19: 0.1 | F19: =D19*E19 -> 295254000 | G19: ='B9. CP THUÊ PM'!E5 -> 3247794000 | H19: Tham chiếu Bảng 9. Chi phí thuê phần mềm
A20: 1.2 | B20: Chi phí đào tạo hướng dẫn sử dụng phần mềm | D20: ='B5. Đào tạo'!F16 -> 85207508 | E20: 0 | F20: =D20*E20 -> 0 | G20: =SUM(D20:F20) -> 85207508 | H20: Tham chiếu Bảng 5. Chi phí đào tạo
A21: 2 | B21: Chi phí dịch vụ hỗ trợ kỹ thuật, quản trị vận hành, bảo trì phần mềm 3 năm | D21: =SUBTOTAL(9,D22:D24) -> 0 | F21: =SUBTOTAL(9,F22:F24) -> 0 | G21: =SUBTOTAL(9,G22:G24) -> 0.3
A22: 2.1 | B22: Chi phí dịch vụ hỗ trợ kỹ thuật 3 năm | D22: 0 | E22: 0.1 | F22: =D22*E22 -> 0 | G22: =SUM(D22:F22) -> 0.1 | H22: Tham chiếu Bảng 4.1. Chi phí hỗ trợ kỹ thuật người dùng trực tiếp tại VPQH
A23: 2.2 | B23: Chi phí dịch vụ bảo trì phần mềm 3 năm | D23: 0 | E23: 0.1 | F23: =D23*E23 -> 0 | G23: =SUM(D23:F23) -> 0.1 | H23: Tham chiếu Bảng 4.2. Chi phí bảo trì phần mềm
A24: 2.3 | B24: Chi phí dịch vụ quản trị vận hành ứng dụng 3 năm | D24: 0 | E24: 0.1 | F24: =D24*E24 -> 0 | G24: =SUM(D24:F24) -> 0.1 | H24: Tham chiếu Bảng 4.3. Chi phí dịch vụ quản trị vận hành ứng dụng
A25: 3 | B25: Chi phí phần mềm thương mại | D25: =SUBTOTAL(9,D26) -> 0 | F25: =SUBTOTAL(9,F26) -> 0 | G25: =SUBTOTAL(9,G26) -> 0
A26: 3.1 | B26: Chi phí license OCR (bóc tách trường thông tin văn bản) | D26: 0 | E26: 0.1 | F26: =D26*E26 -> 0 | G26: 0 | H26: Tham chiếu Bảng 1.1. Chi phí thuê dịch vụ OCR bóc tách trường thông tin văn bản
A27: II | B27: Chi phí quản lý hoạt động thuê dịch vụ CNTT | C27: Gqlda | D27: =SUBTOTAL(9,D28:D29) -> 67620259 | F27: =SUBTOTAL(9,F28:F29) -> 6762025.9 | G27: =SUBTOTAL(9,G28:G29) -> 74382286 | H27: Chủ đầu tư tự thực hiện
A28: 1 | B28: Chi phí thực hiện quản lý dự án | C28: Gthqlda | D28: ='B4. Định mức QLDA & TV'!I18 -> 56350216 | E28: 0.08 | F28: =D28*0.1 -> 5635021.6 | G28: =ROUND(F28+D28,0) -> 61985238 | H28: * Căn cứ QĐ số 1688/QĐ-BTTTT ngày 11/10/2019
A29: 2 | B29: Chi phí giám sát, đánh giá hiệu quả đầu tư | C29: 20% x Gthqlda | D29: =D28*20% -> 11270043 | E29: 0.08 | F29: =D29*0.1 -> 1127004.3 | G29: =ROUND(F29+D29,0) -> 12397048 | H29: NĐ số 29/2021/NĐ-CP (Điều 88. Chi phí và nguồn vốn thực hiện giám sát, đánh giá đầu tư)
A30: III | B30: Chi phí tư vấn lập kế hoạch thuê | C30: Gtv | D30: =SUBTOTAL(9,D31:D38) -> 1.3571761e+08 | F30: =SUBTOTAL(9,F31:F38) -> 10857409 | G30: =SUBTOTAL(9,G31:G38) -> 1.4657502e+08
A31: 1 | B31: Chi phí tư vấn khảo sát và lập Kế hoạch thuê DV CNTT | C31: Gtvkhtdvcntt | D31: =G31/1.08 -> 1.0238334e+08 | E31: 0.08 | F31: =D31*E31 -> 8190667.3 | G31: ='B4. Định mức QLDA & TV'!I21 -> 110574009 | H31: Theo Hợp đồng số 1661/2024/HĐTV
A32: 2 | B32: Chi phí Thẩm tra tính hiệu quả và tính khả thi của Kế hoạch thuê DV CNTT | D32: ='B4. Định mức QLDA & TV'!I27 -> 3827562 | E32: 0.08 | F32: =D32*E32 -> 306204.96 | G32: =D32+F32 -> 4133767 | H32: Tham chiếu Bảng 2. Chi phí tư vấn theo Quyết số 1688/QĐ-BTTTT (Bảng số 4)
A33: 3 | B33: Chi phí lập hồ sơ mời thầu, đánh giá hồ sơ dự thầu | D33: =SUBTOTAL(9,D34:D35) -> 14884962 | F33: =SUBTOTAL(9,F34:F35) -> 1190797 | G33: =SUBTOTAL(9,G34:G35) -> 16075759
A34: 3.1 | B34: Chi phí lập hồ sơ mời thầu và đánh giá hồ sơ dự thầu gói thuê dịch vụ CNTT | D34: ='B4. Định mức QLDA & TV'!I39 -> 12302877 | E34: 0.08 | F34: =D34*E34 -> 984230.16 | G34: =D34+F34 -> 13287107 | H34: Tham chiếu Bảng 2. Chi phí tư vấn theo Quyết số 1688/QĐ-BTTTT (Bảng số 8)
A35: 3.2 | B35: Chi phí lập hồ sơ mời thầu, đánh giá hồ sơ dự thầu gói thầu kiểm thử độc lập | D35: ='B4. Định mức QLDA & TV'!I33 -> 2582085 | E35: 0.08 | F35: =D35*E35 -> 206566.8 | G35: =D35+F35 -> 2788651.8 | H35: Tham chiếu Bảng 6. Chi phí lập HSMT, đánh giá HSDT
A36: 4 | B36: Chi phí tư vấn thẩm định hồ sơ mời thầu và thẩm định kết quả lựa chọn nhà thầu | D36: =SUBTOTAL(9,D37:D38) -> 14621745 | F36: =SUBTOTAL(9,F37:F38) -> 1169739.6 | G36: =SUBTOTAL(9,G37:G38) -> 15791485 | H36: Tham chiếu Bảng 7. Chi phí thẩm định HSMT và thẩm định KQLCNT
A37: 4.1 | B37: Chi phí thẩm định hồ sơ mời thầu và thẩm định KQLCNT gói thuê dịch vụ CNTT | D37: =D17*0.1%*2 -> 6075495 | E37: 0.08 | F37: =D37*E37 -> 486039.6 | G37: =D37+F37 -> 6561534.6 | H37: Điều 12 NĐ 24/2024/NĐ-CP
A38: 4.2 | B38: Chi phí thẩm định hồ sơ mời thầu và thẩm định KQLCNT gói thầu kiểm thử độc lập | D38: ='B6+7.CP HSMT'!$V$14 -> 8546250 | E38: 0.08 | F38: =D38*E38 -> 683700 | G38: =D38+F38 -> 9229950 | H38: Tham chiếu Bảng 7. Chi phí thẩm định HSMT và thẩm định KQLCNT
A39: IV | B39: Chi phí khác | C39: Gk | D39: =SUBTOTAL(9,D40:D41) -> 3.8847048e+08 | F39: =SUBTOTAL(9,F40:F41) -> 2430198 | G39: =SUBTOTAL(9,G40:G41) -> 3.9090067e+08
A40: 1 | B40: Chi phí thẩm định giá | C40: Gt*1% | D40: =D17*1% -> 30377475 | E40: 0.08 | F40: =D40*E40 -> 2430198 | G40: =D40+F40 -> 32807673
A41: 2 | B41: Chi phí kiểm thử nghiệm thu phần mềm độc lập | C41: Gkt | D41: ='B12. CP Kiem thu doc lap'!D11 -> 358093000 | E41: 0 | F41: =D41*E41 -> 0 | G41: =D41 -> 358093000 | H41: Tham khảo Bảng 12. Chi phí kiểm thử độc lập
A42: V | B42: Chi phí dự phòng | C42: Gdp | D42: =5%*SUBTOTAL(9,D17:D41) -> 1.8147779e+08 | F42: =5%*SUBTOTAL(9,F17:F41) -> 15765182 | G42: =D42+F42 -> 1.9724297e+08 | H42: 5% Tổng (I + II + III +IV)
...

Sheet B1.1. THUÊ OCR
A1: Bảng 1.1. BẢNG TÍNH CHI PHÍ THUÊ DỊCH VỤ OCR BÓC TÁCH TRƯỜNG THÔNG TIN VĂN BẢN
A2: *Căn cứ tính toán: - Thông tư số 18/2024/TT-BTTTT ngày 30/12/2024 của Bộ Thông tin và Truyền thông: Quy định lập và quản lý chi phí đầu tư ứng dụng công nghệ thông tin, thuê dịch vụ công nghệ thông tin sử dụng nguồn vốn ngân sách nhà nước
A4: STT | B4: Nội dung | C4: Diễn giải | D4: Đơn vị tính | E4: Giá trị | F4: Ghi chú
A5: 1 | B5: Chi phí thuê dịch vụ CNTT theo yêu cầu riêng trong thời gian 5 năm | C5: Gtdv = Gdv*n | D5: đồng | E5: =E6*E13 -> 2718258000
A6: 2 | B6: Chi phí thuê dịch vụ CNTT theo yêu cầu riêng trong chu kỳ thanh toán | C6: Gdv =((Td*r*(1+r)^n - S*r)/ ((1+r)^n - 1))*(1+GTGT) | D6: đồng | E6: =ROUND((E7*E8*(1+E8)^E13-E11*E8)/(((1+E8)^E13-1))*1.1,-3) -> 453043000 | F6: 1. Theo công thức 2. Các chu kỳ thanh toán đều nhau 3. Tính cho phương án thanh toán vào cuối kỳ
A7: 2.1 | B7: Chi phí xây dựng, phát triển hình thành dịch vụ | C7: Td | D7: đồng | E7: ='B3. CP THUÊ THEO YC RIÊNG'!G8 -> 2300000000 | F7: Theo báo giá thị trường, đây là chi phí mua License OCR (trước thuế VAT)
A8: 2.2 | B8: Mức lãi suất cho thuê theo kỳ thanh toán | C8: r = N/k | D8: % | E8: =ROUND(E9/E10,4) -> 0.0209 | F8: Theo công thức
A9: 2.2.1 | B9: Bình quân lãi suất trung bình | C9: N | D9: % | E9: ='B10. Lãi suất'!G5 -> 0.0418 | F9: Tham chiếu Bảng 10. Bảng tính bình quân lãi suất trung bình của các ngân hàng
A10: 2.2.2 | B10: Số kỳ thanh toán trong một năm thuê dịch vụ theo yêu cầu riêng | C10: k | D10: kỳ | E10: 2 | F10: Số kỳ thanh toán trong 1 năm thuê dịch vụ.
A11: 2.4 | B11: Giá trị còn lại của tài sản cấu thành dịch vụ của bên cho thuê tại thời điểm kết thúc thời gian thuê dịch vụ theo yêu cầu riêng | C11: S = Td/kh*(kh-n) | D11: đồng | E11: =ROUND(E7/E12*(E12-C17),0) -> 0
A12: 2.4.1 | B12: Thời gian khấu hao | C12: kh | D12: năm | E12: 5
A13: 3 | B13: Số kỳ thanh toán trong thời gian thuê dịch vụ theo yêu cầu riêng | C13: n | D13: kỳ | E13: 6 | F13: Thanh toán 6 tháng/lần, 1 năm thanh toán 2 lần nên số kỳ thanh toán là 2 x 3 = 6 kỳ
B17: Số năm thuê dịch vụ | C17: 5 | D17: (năm)
B18: Số kỳ thanh toán trong 1 năm | C18: =E10 -> 2 | D18: (kỳ)
B19: Thời gian khấu hao | C19: 5 | D19: (năm)

Sheet B2. Tư vấn
A1: BẢNG 2: CHI PHÍ TƯ VẤN
B2: Bảng tổng hợp chi phí thiết bị
C3: Chưa VAT
B4: Hạng mục hạ tầng kỹ thuật CNTT | C4: 0
B5: Hạng mục phần mềm nội bộ, CSDL | C5: ='B3. CP THUÊ THEO YC RIÊNG'!G4 -> 4.3346505e+09
I7: Đơn vị tính: đồng
A8: STT | B8: QĐ số 1688/QĐ-BTTTT | C8: Gt | D8: Ga | E8: Gb | F8: Na | G8: Nb | H8: Nt | I8: Giá trị
A9: 1 | B9: Chi phí thẩm tra tính hiệu quả và tính khả thi (Bảng 4) | I9: =I10+I11 -> 6010444
B10: Hạng mục hạ tầng kỹ thuật CNTT | C10: =C4 -> 0 | D10: 0 | E10: 7000000000 | F10: 0.00105 | G10: 0.00105 | H10: =G10-((G10-F10)/(D10-E10)*(C10-E10)) -> 0.00105 | I10: =ROUND(C10*H10,0) -> 0
B11: Hạng mục phần mềm nội bộ, CSDL | C11: =$C$5 -> 4.3346505e+09 | D11: 7000000000 | E11: 15000000000 | F11: 0.00126 | G11: 0.00088 | H11: =G11-((G11-F11)/(D11-E11)*(C11-E11)) -> 0.0013866041 | I11: =ROUND(C11*H11,0) -> 6010444

Sheet B3. CP THUÊ THEO YC RIÊNG
A1: BẢNG 3 - TỔNG HỢP CHI PHÍ THIẾT BỊ HÌNH THÀNH DỊCH VỤ CNTT THEO YÊU CẦU RIÊNG
A3: TT | B3: Hạng mục | C3: Mô tả | D3: Đơn vị tính | E3: Đơn giá dự toán | F3: Số lượng | G3: Thành tiền (trước VAT) | H3: Ghi chú
A4: I | B4: Phần mềm nội bộ, cơ sở dữ liệu | G4: =SUBTOTAL(9,G5:G6) -> 4.3346505e+09
A5: 1 | B5: Chi phí xây dựng Phần mềm nội bộ, cơ sở dữ liệu | C5: Tham chiếu tới mô tả cụ thể, dự toán cho phần mềm nội bộ | D5: Phần mềm | E5: ='B11. Du toan GTPM '!D11 -> 4249443000 | F5: 1 | G5: =E5*F5 -> 4249443000 | H5: Tham chiếu Bảng 11 - Chi phí xây dựng phần mềm nội bộ * Quyết định 671/QĐ-BTTTT, ngày 26/04/2024, v/v "Ban hành hướng dẫn xác định chi phí PMNB"
A6: 2 | B6: Chi phí đào tạo hướng dẫn sử dụng phần mềm | C6: Tham chiếu tới mô tả cụ thể, dự toán chi phí đào tạo | D6: Dịch vụ | E6: ='B5. Đào tạo'!F16 -> 85207508 | F6: 1 | G6: =E6*F6 -> 85207508 | H6: Tham chiếu Bảng 5 - Chi phí đào tạo hướng dẫn sử dụng phần mềm
A7: II | B7: Hạ tầng kỹ thuật CNTT | G7: =SUBTOTAL(9,G8:G9) -> 2300000000
A8: 1 | B8: Chi phí phần mềm thương mại (License OCR bóc tách trường thông tin văn bản) | C8: Theo Báo giá thị trường | D8: License | E8: 2300000000 | F8: 1 | G8: =E8*F8 -> 2300000000 | H8: Theo Báo giá thị trường

Sheet B5. Đào tạo
A1: BẢNG 7: CHI PHÍ ĐÀO TẠO HƯỚNG DẪN SỬ DỤNG
A2: STT | B2: Khoản mục chi | C2: Đơn vị | D2: Số lượng | E2: Đơn giá (VNĐ) | F2: Thành tiền (VNĐ) | G2: Diễn giải
A3: I | B3: Đào tạo nghiệp vụ tại BTP | C3: Lớp | D3: 1 | F3: =F4 -> 80207508
B4: Chi phí tổ chức 1 lớp | F4: =SUM(F7:F13) -> 80207508
B5: Thời gian đào tạo | C5: Ngày | D5: 1
B6: Số lượng học viên / lớp | C6: Học viên | D6: 15
A7: 1 | B7: Chi phí photo, in ấn slide và tài liệu video hướng dẫn sử dụng, phiếu đóng góp ý kiến | C7: Bộ | D7: =D6*D5 -> 15 | E7: 100000 | F7: =D7*E7 -> 1500000 | G7: Mục a, Khoản 2, Điều 4 Thông tư 100/2018/TT-BTC theo thực tế
A8: 2 | B8: Chi văn phòng phẩm phục vụ cho đào tạo | C8: Người | D8: =D5*D6 -> 15 | E8: 20000 | F8: =D8*E8 -> 300000 | G8: Mục a, Khoản 2, Điều 4 Thông tư 100/2018/TT-BTC theo thực tế
A9: 3 | B9: Thù lao giảng viên chính (01 giảng viên) | C9: Người x ngày | D9: =D5*1 -> 1 | E9: 2000000 | F9: =D9*E9 -> 2000000 | G9: Mục a, Khoản 2, Điều 4 Thông tư 100/2018/TT-BTC theo thực tế
A10: 4 | B10: Thù lao trợ giảng (01 trợ giảng) | C10: Người x ngày | D10: 1 | E10: 1500000 | F10: =D10*E10 -> 1500000 | G10: Mục a, Khoản 2, Điều 4 Thông tư 100/2018/TT-BTC theo thực tế
A11: 5 | B11: Phụ cấp ăn uống giảng viên, trợ giảng | C11: Người x ngày | D11: =D5*2 -> 2 | E11: 300000 | F11: =D11*E11 -> 600000 | G11: Khoản 7, Điều 6 , Thông tư số 12/2025/TT-BTC
A12: 6 | B12: Nước uống (học viên) | C12: Người x ngày | D12: =D6*D5 -> 15 | E12: 40000 | F12: =D12*E12 -> 600000 | G12: Mục a, Khoản 2, Điều 4 Thông tư 100/2018/TT-BTC theo thực tế
A13: 7 | B13: Video | C13: Gói | D13: 1 | E13: ='B5.1. Xây dựng video bài giảng'!G15 -> 73707508 | F13: =D13*E13 -> 73707508 | G13: Tham chiếu đến Bảng 5.1. Chi phí xây dựng video bài giảng
B14: TỔNG CỘNG (I) | F14: =F3 -> 80207508
A15: II | B15: CHI PHÍ QUẢN LÝ CHUNG LỚP HỌC (chi thù lao người tổ chức lớp học, chi phí phục vụ khai giảng bế giảng, chi phí tổ chức lớp học,...) | C15: Khoá | D15: 1 | E15: 5000000 | F15: =E15*D15 -> 5000000 | G15: Mục a, Khoản 2, Điều 4 Thông tư 100/2018/TT-BTC theo thực tế
B16: TỔNG CHI PHÍ | F16: =F15+F14 -> 85207508

Sheet B5.1. Xây dựng video bài giảng
A1: BẢNG 5.1 - CHI PHÍ XÂY DỰNG VIDEO BÀI GIẢNG
A3: STT | B3: Công việc thực hiện | C3: Ngày công chuyên gia | G3: Thành tiền (Đồng) | H3: Ghi chú
C4: Mức 4 | D4: Mức 3 | E4: Mức 2 | F4: Mức 1
A5: I | B5: Chi phí chuyên gia (CG) | G5: =SUM(G6:G9) -> 41538462
A6: 1 | B6: Thu thập dữ liệu xây dựng video bài giảng | C6: 6 | D6: 6 | G6: =C6*$C$19+D6*$D$19+E6*$E$19 -> 16153846
A7: 2 | B7: Xây dựng video bài giảng | C7: 5 | D7: 5 | G7: =C7*$C$19+D7*$D$19+E7*$E$19 -> 13461538
A8: 3 | B8: Chỉnh lý, điều chỉnh video bài giảng | C8: 3 | D8: 3 | G8: =C8*$C$19+D8*$D$19+E8*$E$19 -> 8076923.1
A9: 4 | B9: Xuất bản video bài giảng | C9: 2 | D9: 1 | G9: =C9*$C$19+D9*$D$19+E9*$E$19 -> 3846153.8
A10: II | B10: Chi phí quản lý (55% của CG) (QL) | G10: =55%*G5 -> 22846154 | H10: Thông tư số 18/2024/TT-BTTTT
A11: III | B11: Chi phí khác (K) (văn phòng phẩm) | G11: 0
A12: IV | B12: Thu nhập chịu thuế tính trước (TN) 6% của (CG+QL+K) | G12: =6%*(G5+G10+G11) -> 3863076.9 | H12: Thông tư số 18/2024/TT-BTTTT
B13: Tổng trước VAT | G13: =G5+G10+G11+G12 -> 68247692
A14: V | B14: VAT: 8% của (CG+QL+K +TN) | G14: =8%*G13 -> 5459815.4
A15: Tổng cộng | G15: =G13+G14 -> 73707508
A17: Ghi chú: Lương chuyên gia tư vấn (CGTV) áp dụng thông tư 004/2025/TT-BNV của Bộ Nội vụ | C17: Lương CGTV Mức 4 | D17: Lương CGTV Mức 3 | E17: Lương CGTV Mức 2 | F17: Lương CGTV Mức 1
A18: Lương tháng | C18: 30000000 | D18: 40000000 | E18: 55000000 | F18: 70000000
A19: Đơn giá ngày công | C19: =C18/26 -> 1153846.2 | D19: =D18/26 -> 1538461.5 | E19: =E18/26 -> 2115384.6 | F19: =F18/26 -> 2692307.7

Sheet B6+7.CP HSMT
A1: BẢNG 6 - CHI PHÍ LẬP HỒ SƠ MỜI THẦU, ĐÁNH GIÁ HSDT | P1: BẢNG 7 - CHI PHÍ THẨM ĐỊNH HỒ SƠ MỜI THẦU VÀ THẨM ĐỊNH KQLCNT
A3: STT | B3: Công việc thực hiện | C3: Ngày công chuyên gia | G3: Thành tiền (Đồng) | H3: Ghi chú | P3: STT | Q3: Công việc thực hiện | R3: Ngày công chuyên gia | V3: Thành tiền (Đồng) | W3: Ghi chú
C4: Mức 4 | D4: Mức 3 | E4: Mức 2 | F4: Mức 1 | R4: Mức 4 | S4: Mức 3 | T4: Mức 2 | U4: Mức 1
A5: I | B5: Chi phí chuyên gia (CG) | G5: =SUM(G6:G10) -> 8000000 | P5: I | Q5: Chi phí chuyên gia (CG) | V5: =SUM(V6:V10) -> 5125000
A6: 1 | B6: Lập HSMT cho gói thầu, đánh giá HSDT của nhà thầu tham gia | C6: 2 | D6: 1 | G6: =C6*$C$20+D6*$D$20+E6*$E$20 -> 2500000 | P6: 1 | Q6: Thẩm định HSMT cho gói thầu | R6: 1 | S6: 0.5 | V6: =R6*$C$20+S6*$D$20 -> 1250000
A7: 2 | B7: Chỉnh sửa, hoàn thiện HSMT theo ý kiến thẩm định/thẩm tra (nếu có) | C7: 1 | D7: 0.5 | G7: =C7*$C$20+D7*$D$20+E7*$E$20 -> 1250000 | P7: 2 | Q7: Lập Báo cáo thẩm định HSMT | R7: 0.5 | S7: 0.5 | V7: =R7*$C$20+S7*$D$20 -> 875000
A8: 3 | B8: Kiểm tra, đánh giá tính hợp lệ của HSDT cho gói thầu | C8: 1 | D8: 0.5 | G8: =C8*$C$20+D8*$D$20+E8*$E$20 -> 1250000 | P8: 3 | Q8: Kiểm tra, đánh giá Báo cáo đánh giá HSDT | R8: 0.5 | S8: 0.5 | V8: =R8*$C$20+S8*$D$20 -> 875000
A9: 4 | B9: Đánh giá chi tiết hồ sơ dự thầu | C9: 1 | D9: 1 | G9: =C9*$C$20+D9*$D$20+E9*$E$20 -> 1750000 | P9: 4 | Q9: Kiểm tra, đánh giá KQLCNT | R9: 1 | S9: 0.5 | V9: =R9*$C$20+S9*$D$20 -> 1250000
A10: 5 | B10: Lập Báo cáo đánh giá HSDT | C10: 1 | D10: 0.5 | G10: =C10*$C$20+D10*$D$20+E10*$E$20 -> 1250000 | P10: 5 | Q10: Lập Báo cáo thẩm định KQLCNT | R10: 0.5 | S10: 0.5 | V10: =R10*$C$20+S10*$D$20 -> 875000
A11: II | B11: Chi phí quản lý (55% của CG) (QL) | G11: =55%*G5 -> 4400000 | H11: Thông tư số 18/2024/TT-BTTTT | P11: II | Q11: Chi phí quản lý (55% của CG) (QL) | V11: =55%*V5 -> 2818750 | W11: Thông tư số 18/2024/TT-BTTTT
A12: III | B12: Chi phí khác (K) (văn phòng phẩm) | G12: =N25 -> 118750 | H12: Dự toán chi tiết | P12: III | Q12: Chi phí khác (K) (văn phòng phẩm) | V12: =N25 -> 118750 | W12: Dự toán chi tiết
A13: IV | B13: Thu nhập chịu thuế tính trước (TN) 6% của (CG+QL+K) | G13: =6%*(G5+G11+G12) -> 751125 | H13: Thông tư số 18/2024/TT-BTTTT | P13: IV | Q13: Thu nhập chịu thuế tính trước (TN) 6% của (CG+QL+K) | V13: =6%*(V5+V11+V12) -> 483750 | W13: Thông tư số 18/2024/TT-BTTTT
B14: Tổng trước VAT | G14: =G5+G11+G12+G13 -> 13269875 | Q14: Tổng trước VAT | V14: =V5+V11+V12+V13 -> 8546250
A15: V | B15: VAT: 8% của (CG+QL+K +TN) | G15: =8%*G14 -> 1061590 | P15: V | Q15: VAT: 8% của (CG+QL+K +TN) | V15: =8%*V14 -> 683700
A16: Tổng cộng | G16: =G14+G15 -> 14331465 | P16: Tổng cộng | V16: =V14+V15 -> 9229950
A18: Ghi chú: Lương chuyên gia tư vấn (CGTV) áp dụng Thông tư số 02/2015/TT-BLĐTBXH của Bộ Lao động - Thương binh và Xã hội | C18: Lương CGTV Mức 4 | D18: Lương CGTV Mức 3 | E18: Lương CGTV Mức 2 | F18: Lương CGTV Mức 1 | P18: Ghi chú: Lương chuyên gia tư vấn (CGTV) áp dụng Thông tư số 02/2015/TT-BLĐTBXH của Bộ Lao động - Thương binh và Xã hội | R18: Lương CGTV Mức 4 | S18: Lương CGTV Mức 3 | T18: Lương CGTV Mức 2 | U18: Lương CGTV Mức 1
A19: Lương tháng | C19: 15000000 | D19: 20000000 | E19: 30000000 | F19: 40000000 | P19: Lương tháng | R19: 15000000 | S19: 20000000 | T19: 30000000 | U19: 40000000
A20: Đơn giá ngày công | C20: 750000 | D20: 1000000 | E20: 1500000 | F20: 2000000 | P20: Đơn giá ngày công | R20: 750000 | S20: 1000000 | T20: 1500000 | U20: 2000000
I21: TT | J21: Vật tư, vật liệu | K21: Đơn vị | L21: Khối lượng | M21: Đơn giá (đồng) | N21: Thành tiền (đồng)
I22: 1 | J22: Giấy in/photocopy A4 | K22: Ram | L22: 1 | M22: 60000 | N22: =L22*M22 -> 60000 | O22: https://vanphongphamhn.com.vn/giay-in-plus-a4-pd167300.html
I23: 2 | J23: Giấy bìa đóng quyển A4, bìa mica | K23: gam | L23: 1 | M23: =(32000+71500)/2 -> 51750 | N23: =L23*M23 -> 51750 | O23: https://vppminhduc.vn/?gad_source=1&gclid=Cj0KCQjwlN6wBhCcARIsAKZvD5iJ81ell2LmN8hL1tQFTXfRdR5cpRZ6iQULJuBnHa16My5ggjLrPc0aAoTuEALw_wcB
I24: 3 | J24: Băng dính | K24: Cuộn | L24: 1 | M24: 7000 | N24: =L24*M24 -> 7000
J25: Tổng cộng | N25: =SUM(N22:N24) -> 118750

Sheet B8.Dinh muc nhan cong
B1: BẢNG 8 - DIỄN GIẢI CHI TIẾT CHI PHÍ TIỀN LƯƠNG LAO ĐỘNG
B2: Theo Quyết định số 320/QĐ-BKHCN ngày 30/3/2025 của Bộ Khoa học và Công nghệ hướng dẫn xác định đơn giá nhân công trong quản lý chi phí đầu tư ứng dụng công nghệ thông tin sử dụng nguồn vốn ngân sách nhà nước
B3: Mức lương cơ sở (MLcs) | D3: 2340000 | E3: Nghị định số 73/2024/NĐ-CP ngày 30/06/2024
B4: Số ngày làm việc trong tháng | D4: 26
B5: Chọn phân loại Vùng/Khu vực | D5: I | E5: Chọn giá trị
B6: Hệ số điều chỉnh | D6: =IFERROR(HLOOKUP(D5,$D$28:$G$29,2,TRUE),"") -> 1.2 | E6: Tự động
B7: Lương tối thiểu theo vùng (MLttv) | D7: =IFERROR(HLOOKUP(D5,$D$32:$G$33,2,TRUE),"") -> 4960000 | E7: Tự động
A9: TT | B9: Tiêu chí xác định | C9: Mã ghi chú | D9: Cách tính | E9: Cấp bậc, hệ số, mức lương | M9: Ghi chú
A10: 1 | B10: Cấp bậc kỹ sư | C10: KSb | D10: Theo quy định | E10: KS1 | F10: KS2 | G10: KS3 | H10: KS4 | I10: KS5 | J10: KS6 | K10: KS7 | L10: KS8
A11: 2 | B11: Hệ số lương | C11: Hcb | D11: Theo quy định | E11: 2.34 | F11: 2.65 | G11: 2.96 | H11: 3.27 | I11: 3.58 | J11: 3.89 | K11: 4.2 | L11: 4.51 | M11: Quyết định số 320/QĐ-BKHCN ngày 30/3/2025 của Bộ Khoa học và Công nghệ
A12: 3 | B12: Mức lương cơ sở | C12: MLcs | D12: Theo quy định | E12: =$D$3 -> 2340000 | F12: =$D$3 -> 2340000 | G12: =$D$3 -> 2340000 | H12: =$D$3 -> 2340000 | I12: =$D$3 -> 2340000 | J12: =$D$3 -> 2340000 | K12: =$D$3 -> 2340000 | L12: =$D$3 -> 2340000
A13: 4 | B13: Hệ số điều chỉnh | C13: Hđc | D13: Theo quy định | E13: =$D$6 -> 1.2 | F13: =$D$6 -> 1.2 | G13: =$D$6 -> 1.2 | H13: =$D$6 -> 1.2 | I13: =$D$6 -> 1.2 | J13: =$D$6 -> 1.2 | K13: =$D$6 -> 1.2 | L13: =$D$6 -> 1.2 | M13: Quyết định số 320/QĐ-BKHCN ngày 30/3/2025 của Bộ Khoa học và Công nghệ, vùng I
A14: 5 | B14: Lương cơ bản/tháng | C14: Lcb | D14: MLcs*Hcb | E14: =E11*E12 -> 5475600 | F14: =F11*F12 -> 6201000 | G14: =G11*G12 -> 6926400 | H14: =H11*H12 -> 7651800 | I14: =I11*I12 -> 8377200 | J14: =J11*J12 -> 9102600 | K14: =K11*K12 -> 9828000 | L14: =L11*L12 -> 10553400
A15: 6 | B15: Mức lương lao động/tháng | C15: MLcb | D15: MLcs*Hcb *(1+Hđc) | E15: =E12*E11*(1+E13) -> 12046320 | F15: =F12*F11*(1+F13) -> 13642200 | G15: =G12*G11*(1+G13) -> 15238080 | H15: =H12*H11*(1+H13) -> 16833960 | I15: =I12*I11*(1+I13) -> 18429840 | J15: =J12*J11*(1+J13) -> 20025720 | K15: =K12*K11*(1+K13) -> 21621600 | L15: =L12*L11*(1+L13) -> 23217480
A16: 7 | B16: Các chi phí bảo hiểm | C16: CPBH | D16: BHxh+BHyt+BHtn+CĐP | E16: =SUBTOTAL(9,E17:E20) -> 1286766 | F16: =SUBTOTAL(9,F17:F20) -> 1457235 | G16: =SUBTOTAL(9,G17:G20) -> 1627704 | H16: =SUBTOTAL(9,H17:H20) -> 1798173 | I16: =SUBTOTAL(9,I17:I20) -> 1968642 | J16: =SUBTOTAL(9,J17:J20) -> 2139111 | K16: =SUBTOTAL(9,K17:K20) -> 2309580 | L16: =SUBTOTAL(9,L17:L20) -> 2480049
B17: - Bảo hiểm xã hội | C17: BHxh | D17: 17.5%*max(Lcb,MLttv) | E17: =IF(E$14>$D$7,E$11*E12*17.5%,$D$7*17.5%) -> 958230 | F17: =IF(F$14>$D$7,F$11*F12*17.5%,$D$7*17.5%) -> 1085175 | G17: =IF(G$14>$D$7,G$11*G12*17.5%,$D$7*17.5%) -> 1212120 | H17: =IF(H$14>$D$7,H$11*H12*17.5%,$D$7*17.5%) -> 1339065 | I17: =IF(I$14>$D$7,I$11*I12*17.5%,$D$7*17.5%) -> 1466010 | J17: =IF(J$14>$D$7,J$11*J12*17.5%,$D$7*17.5%) -> 1592955 | K17: =IF(K$14>$D$7,K$11*K12*17.5%,$D$7*17.5%) -> 1719900 | L17: =IF(L$14>$D$7,L$11*L12*17.5%,$D$7*17.5%) -> 1846845 | M17: 1. Điều 32. Luật Bảo hiểm xã hội số 41/2024/QH15 quy định: (1) 3% vào quỹ ốm đau và thai sản; (2) 14% vào quỹ hưu trí và tử tuất. 2. Điều 22 - Quyết định 595/QĐ-BHXH quy định từ ngày 01/06/2017: (1) 0.5% vào quỹ bảo hiểm tai nạn lao động, bệnh nghề nghiệp; (2) 0.5% Bảo hiểm tai nạn lao động 3. Nghị định 143/2018/NĐ-CP và Thông báo 4447/TB-BHXH ngày 22/12/2021
B18: - Bảo hiểm y tế | C18: BHyt | D18: 3%*max(Lcb,MLttv) | E18: =IF(E$14>$D$7,E$11*E12*3%,$D$7*3%) -> 164268 | F18: =IF(F$14>$D$7,F$11*F12*3%,$D$7*3%) -> 186030 | G18: =IF(G$14>$D$7,G$11*G12*3%,$D$7*3%) -> 207792 | H18: =IF(H$14>$D$7,H$11*H12*3%,$D$7*3%) -> 229554 | I18: =IF(I$14>$D$7,I$11*I12*3%,$D$7*3%) -> 251316 | J18: =IF(J$14>$D$7,J$11*J12*3%,$D$7*3%) -> 273078 | K18: =IF(K$14>$D$7,K$11*K12*3%,$D$7*3%) -> 294840 | L18: =IF(L$14>$D$7,L$11*L12*3%,$D$7*3%) -> 316602 | M18: Điều 18 Quyết định số 595/QĐ-BHXH
B19: - Bảo hiểm thất nghiệp | C19: BHtn | D19: 1%*max(Lcb,MLttv) | E19: =IF(E$14>$D$7,E$11*E12*1%,$D$7*1%) -> 54756 | F19: =IF(F$14>$D$7,F$11*F12*1%,$D$7*1%) -> 62010 | G19: =IF(G$14>$D$7,G$11*G12*1%,$D$7*1%) -> 69264 | H19: =IF(H$14>$D$7,H$11*H12*1%,$D$7*1%) -> 76518 | I19: =IF(I$14>$D$7,I$11*I12*1%,$D$7*1%) -> 83772 | J19: =IF(J$14>$D$7,J$11*J12*1%,$D$7*1%) -> 91026 | K19: =IF(K$14>$D$7,K$11*K12*1%,$D$7*1%) -> 98280 | L19: =IF(L$14>$D$7,L$11*L12*1%,$D$7*1%) -> 105534 | M19: Điều 14 Quyết định 595/QĐ-BHXH
B20: - Công đoàn phí | C20: CĐP | D20: 2%*max(Lcb,MLttv) | E20: =IF(E$14>$D$7,E$11*E12*2%,$D$7*2%) -> 109512 | F20: =IF(F$14>$D$7,F$11*F12*2%,$D$7*2%) -> 124020 | G20: =IF(G$14>$D$7,G$11*G12*2%,$D$7*2%) -> 138528 | H20: =IF(H$14>$D$7,H$11*H12*2%,$D$7*2%) -> 153036 | I20: =IF(I$14>$D$7,I$11*I12*2%,$D$7*2%) -> 167544 | J20: =IF(J$14>$D$7,J$11*J12*2%,$D$7*2%) -> 182052 | K20: =IF(K$14>$D$7,K$11*K12*2%,$D$7*2%) -> 196560 | L20: =IF(L$14>$D$7,L$11*L12*2%,$D$7*2%) -> 211068 | M20: Điều 5 Nghị định 191/2013/NĐ-CP ngày 21/11/2013
A21: 8 | B21: Giá nhân công trực tiếp/tháng | C21: NCt | D21: MLcb+CPBH | E21: =E15+E16 -> 13333086 | F21: =F15+F16 -> 15099435 | G21: =G15+G16 -> 16865784 | H21: =H15+H16 -> 18632133 | I21: =I15+I16 -> 20398482 | J21: =J15+J16 -> 22164831 | K21: =K15+K16 -> 23931180 | L21: =L15+L16 -> 25697529
A22: 9 | B22: Giá nhân công trực tiếp/ngày | C22: NCn | D22: NCt/26 | E22: =E21/26 -> 512811 | F22: =F21/26 -> 580747.5 | G22: =G21/26 -> 648684 | H22: =H21/26 -> 716620.5 | I22: =I21/26 -> 784557 | J22: =J21/26 -> 852493.5 | K22: =K21/26 -> 920430 | L22: =L21/26 -> 988366.5 | M22: 1 tháng: 26 ngày làm việc
A23: 10 | B23: Giá nhân công trực tiếp/giờ | C23: NCg | D23: NCn/8 | E23: =ROUND(E22/8,0) -> 64101 | F23: =ROUND(F22/8,0) -> 72593 | G23: =ROUND(G22/8,0) -> 81086 | H23: =ROUND(H22/8,0) -> 89578 | I23: =ROUND(I22/8,0) -> 98070 | J23: =ROUND(J22/8,0) -> 106562 | K23: =ROUND(K22/8,0) -> 115054 | L23: =ROUND(L22/8,0) -> 123546 | M23: Một ngày: 8h làm việc
B27: Hệ số điều chỉnh theo vùng (căn cứ Quyết định số 320/QĐ-BKHCN ngày 30/3/2025 của Bộ Khoa học và Công nghệ)
B28: Vùng | D28: I | E28: II | F28: III | G28: IV
B29: Hệ số điều chỉnh | D29: 1.2 | E29: 0.9 | F29: 0.7 | G29: 0.5
B31: Nghị định 74/2024/NĐ-CP quy định về mức lương tối thiểu vùng áp dụng đối với người lao động làm việc theo hợp đồng lao động
B32: Vùng | D32: I | E32: II | F32: III | G32: IV
B33: Mức lương tối thiểu vùng áp dụng đối với người lao động làm việc ở doanh nghiệp | D33: 4960000 | E33: 4410000 | F33: 3860000 | G33: 3450000
B35: Nghị định số 73/2024/NĐ-CP ngày 30/06/2024
B36: Mức lương cơ sở (Từ ngày 01 tháng 7 năm 2024) | D36: 2340000
A41: DIỄN GIẢI CHI PHÍ THUÊ CHUYÊN GIA THỰC HIỆN CÁC CÔNG TÁC TƯ VẤN
A42: - Căn cứ lập dự toán: + Thông tư 004/2025/TT-BNV của Bộ Nội vụ , ngày 07 tháng 05 năm 2015, v.v "QUY ĐỊNH MỨC LƯƠNG CỦA CHUYÊN GIA TƯ VẤN TRONG NƯỚC LÀM CƠ SỞ CHO VIỆC XÁC ĐỊNH GIÁ GÓI THẦU"
B44: Lương chuyên gia tư vấn (CGTV) áp dụng thông tư 004/2025/TT-BNV của Bộ Nội vụ | D44: MỨC CHUYÊN GIA
D45: Mức 4 (dưới 5 năm kinh nghiệm) | F45: Mức 3 (đến 10 năm kinh nghiệm) | H45: Mức 2 (Đến 15 năm kinh nghiệm) | J45: Mức 1 (từ 15 năm kinh nghiệm trở lên)
B46: Trường hợp cần thiết, đối với dự án, công trình có quy mô lớn, kỹ thuật phức tạp, sử dụng công nghệ hiện đại đòi hỏi chuyên gia tư vấn có trình độ chuyên môn kỹ thuật đặc biệt, khả năng cung ứng của thị trường lao động còn hạn chế hoặc điều kiện làm việc khó khăn, ở vùng sâu, vùng xa, chủ đầu tư hoặc bên mời thầu lựa chọn, báo cáo người có thẩm quyền xem xét, quyết định mức lương chuyên gia tư vấn cao hơn nhưng tối đa không quá 1.5 lần so với mức lương quy định | D46: * Hoặc là Chuyên gia tư vấn có bằng đại học đúng chuyên ngành tư vấn và có dưới 5 năm kinh nghiệm trong chuyên ngành tư vấn. * Hoặc là Chuyên gia tư vấn có bằng thạc sĩ trở lên đúng chuyên ngành tư vấn và có dưới 3 năm kinh nghiệm trong chuyên ngành tư vấn. | F46: * Hoặc là Chuyên gia tư vấn có bằng đại học đúng chuyên ngành tư vấn và có từ 5 đến dưới 10 năm kinh nghiệm trong chuyên ngành tư vấn. * Hoặc là Chuyên gia tư vấn có bằng thạc sĩ trở lên và có từ 3 đến dưới 5 năm kinh nghiệm trong chuyên ngành tư vấn. | H46: * Hoặc là Chuyên gia tư vấn có bằng đại học đúng chuyên ngành tư vấn và có từ 10 đến dưới 15 năm kinh nghiệm trong chuyên ngành tư vấn; * Hoặc là Chuyên gia tư vấn có bằng thạc sĩ trở lên đúng chuyên ngành tư vấn và có từ 5 đến dưới 8 năm kinh nghiệm trong chuyên ngành tư vấn; * Hoặc là Chuyên gia tư vấn đảm nhiệm chức danh chủ trì triển khai một hoặc một số hạng mục thuộc gói thầu tư vấn. | J46: * Hoặc là Chuyên gia tư vấn có bằng đại học đúng chuyên ngành tư vấn và có từ 15 năm kinh nghiệm trở lên trong chuyên ngành tư vấn; * Hoặc là Chuyên gia tư vấn có bằng thạc sĩ trở lên đúng chuyên ngành tư vấn và có từ 8 năm kinh nghiệm trở lên trong chuyên ngành tư vấn. * Hoặc là Chuyên gia tư vấn đảm nhiệm chức danh Trưởng nhóm tư vấn hoặc chủ trì tổ chức, điều hành gói thầu tư vấn.
B47: Lương tháng (đ/tháng) Tại Điều 3 Thông tư | D47: 30000000 | F47: 40000000 | H47: 55000000 | J47: 70000000
B48: Lương ngày (đ/ngày) Tại điều 3 Thông tư Mức lương theo ngày áp dụng đối với chuyên gia tư vấn có thời gian làm việc đủ 8 giờ, được xác định trên cơ sở mức lương theo tháng quy định tại khoản 1 Điều này chia cho 26 ngày. | D48: =D47/26 -> 1153846.2 | F48: =F47/26 -> 1538461.5 | H48: =H47/26 -> 2115384.6 | J48: =J47/26 -> 2692307.7
B52: Mã hiệu | C52: Nhân sự theo ngạch bậc | D52: Phát triển phần mềm
D53: Số lượng | E53: Giờ công (VND/người/giờ)
B54: KS1 | C54: KS bậc 1/8 | D54: 0 | E54: =HLOOKUP(B54,$A$10:$L$23,14,FALSE) -> 64101
...

Sheet B9. CP THUÊ PM
A1: Bảng 9. BẢNG TÍNH CHI PHÍ THUÊ DỊCH VỤ CNTT THEO YÊU CẦU RIÊNG (Gtdv)
A2: *Căn cứ tính toán: - Thông tư số 18/2024/TT-BTTTT ngày 30/12/2024 của Bộ Thông tin và Truyền thông: Quy định lập và quản lý chi phí đầu tư ứng dụng công nghệ thông tin, thuê dịch vụ công nghệ thông tin sử dụng nguồn vốn ngân sách nhà nước
A4: STT | B4: Nội dung | C4: Diễn giải | D4: Đơn vị tính | E4: Giá trị | F4: Ghi chú
A5: 1 | B5: Chi phí thuê dịch vụ CNTT theo yêu cầu riêng trong thời gian 3 năm | C5: Gtdv = Gdv*n | D5: đồng | E5: =E6*E13 -> 3247794000
A6: 2 | B6: Chi phí thuê dịch vụ CNTT theo yêu cầu riêng trong chu kỳ thanh toán | C6: Gdv =((Td*r*(1+r)^n - S*r)/ ((1+r)^n - 1))*(1+GTGT) | D6: đồng | E6: =ROUND((E7*E8*(1+E8)^E13-E11*E8)/(((1+E8)^E13-1))*1.1,-3) -> 541299000 | F6: 1. Theo công thức 2. Các chu kỳ thanh toán đều nhau 3. Tính cho phương án thanh toán vào cuối kỳ
A7: 2.1 | B7: Chi phí xây dựng, phát triển hình thành dịch vụ | C7: Td | D7: đồng | E7: ='B11. Du toan GTPM '!D11 -> 4249443000 | F7: Tham chiếu Chi phí xây dựng phát triển hình thành Hệ thống quản lý văn bản và điều hành điện tử tại Bảng 11 - Bảng tính toán giá trị phần mềm
A8: 2.2 | B8: Mức lãi suất cho thuê theo kỳ thanh toán | C8: r = N/k | D8: % | E8: =ROUND(E9/E10,4) -> 0.0209 | F8: Theo công thức
A9: 2.2.1 | B9: Bình quân lãi suất trung bình | C9: N | D9: % | E9: ='B10. Lãi suất'!G5 -> 0.0418 | F9: Tham chiếu Bảng 10. Bảng tính bình quân lãi suất trung bình của các ngân hàng
A10: 2.2.2 | B10: Số kỳ thanh toán trong một năm thuê dịch vụ theo yêu cầu riêng | C10: k | D10: kỳ | E10: 2 | F10: Số kỳ thanh toán trong 1 năm thuê dịch vụ.
A11: 2.4 | B11: Giá trị còn lại của tài sản cấu thành dịch vụ của bên cho thuê tại thời điểm kết thúc thời gian thuê dịch vụ theo yêu cầu riêng | C11: S = Td/kh*(kh-n) | D11: đồng | E11: =ROUND(E7/E12*(E12-C17),0) -> 1699777200
A12: 2.4.1 | B12: Thời gian khấu hao | C12: kh | D12: năm | E12: 5
A13: 3 | B13: Số kỳ thanh toán trong thời gian thuê dịch vụ theo yêu cầu riêng | C13: n | D13: kỳ | E13: 6 | F13: Thanh toán 6 tháng/lần, 1 năm thanh toán 2 lần nên số kỳ thanh toán là 2 x 3 = 6 kỳ
B17: Số năm thuê dịch vụ | C17: 3 | D17: (năm)
B18: Số kỳ thanh toán trong 1 năm | C18: =E10 -> 2 | D18: (kỳ)
B19: Thời gian khấu hao | C19: 5 | D19: (năm)

Sheet B10. Lãi suất
A1: Bảng 10. BẢNG TÍNH BÌNH QUÂN LÃI SUẤT TRUNG BÌNH CỦA NGÂN HÀNG
A3: STT | B3: Ngân hàng | C3: Lãi suất huy động tiền gửi Việt Nam đồng | E3: Lãi suất trung bình | F3: Bình quân lãi suất trung bình
C4: Kỳ hạn 01 năm | D4: Kỳ hạn 05 năm
A5: 1 | B5: Vietcombank | C5: 0.041 | D5: 0.042 | E5: =ROUND((C5+D5)/2,4) -> 0.0415 | F5: =ROUND(SUM(E5:E7)/3,4) -> 0.0418 | G5: =F5 -> 0.0418
A6: 2 | B6: BIDV | C6: 0.042 | D6: =C6 -> 0.042 | E6: =ROUND((C6+D6)/2,4) -> 0.042
A7: 3 | B7: Vietinbank | C7: 0.042 | D7: =C7 -> 0.042 | E7: =ROUND((C7+D7)/2,4) -> 0.042

Sheet B11. Du toan GTPM 
A2: BẢNG 11: BẢNG TÍNH TOÁN GIÁ TRỊ PHẦN MỀM
A3: Căn cứ: - Quyết định số 671/QĐ-BTTTT, ngày 26 tháng 4 năm 2024, v/v Ban hành hướng dẫn xác định chi phí phần mềm nội bộ - Quyết định số 129/QĐ-BTTTT, ngày 03/02/2021, v/v Ban hành hướng dẫn xác định đơn giá nhân công trong quản lý chi phí đầu tư ứng dụng công nghệ thông tin sử dụng nguồn vốn ngân sách nhà nước Lưu ý: Cách viết thống nhất số thập phân (sử dụng ký tự "." hoặc "," cần nhất quán trong tài liệu)
A5: GIÁ TRỊ DỰ TOÁN PHẦN MỀM NỘI BỘ
A6: TT | B6: Khoản mục chi phí | C6: Diễn giải | D6: Giá trị | E6: Ghi chú
A7: 1 | B7: Chi phí trực tiếp xây dựng, phát triển, nâng cấp, mở rộng phần mềm nội bộ (G) | C7: G = 1.4*E*P*H | D7: =D25 -> 2.4296411e+09
A8: 2 | B8: Chi phí chung (C) | C8: C = 65%*G | D8: =65%*D7 -> 1.5792667e+09
A9: 3 | B9: Thu nhập chịu thuế tính trước (TL) | C9: TL = 6%*(G + C) | D9: =6%*(D7+D8) -> 2.4053447e+08
A10: 4 | B10: Chi phí của phần mềm (Gpm) | C10: Gpm = G + C + TL | D10: =SUM(D7+D8+D9) -> 4.2494423e+09
A11: TỔNG CỘNG | C11: Gpm (làm tròn) | D11: =ROUNDUP(D10,-3) -> 4249443000
A13: DIỄN GIẢI CHI PHÍ TRỰC TIẾP XÂY DỰNG, PHÁT TRIỂN, NÂNG CẤP, MỞ RỘNG PHẦN MỀM NỘI BỘ
A14: TT | B14: Hạng mục | C14: Diễn giải | D14: Giá trị | E14: Ghi chú
A15: I | B15: Tính điểm trường hợp sử dụng - Use case
A16: 1 | B16: Điểm Actor (TAW) | D16: ='B11.2.Diem tac nhan'!F7 -> 19 | E16: Tham chiếu bảng 11.2 - Bảng tính toán điểm các tác nhân (actors) tương tác, trao đổi thông tin với phần mềm
A17: 2 | B17: Điểm Use-case (TBF) | D17: ='B11.1.Tong hop Usecases'!F18 -> 657 | E17: Tham chiếu bảng 11.1 - Bảng tính toán điểm các trường hợp sử dụng
A18: 3 | B18: Tính điểm UUCP | C18: UUCP = TAW +TBF | D18: =D17+D16 -> 676 | E18: Theo công thức
A19: 4 | B19: Hệ số phức tạp KT-CN (TCF) | C19: TCF = 0.6 + (0.01 x TFW) | D19: ='B11.3.He so Cong nghe'!E20 -> 1.03 | E19: Tham chiếu bảng 11.3 - Bảng tính toán hệ số phức tạp kỹ thuật - công nghệ
A20: 5 | B20: Hệ số phức tạp về môi trường (EF) | C20: EF = 1.4 + (-0.03 x EFW) | D20: ='B11.4.He so Moi truong'!F15 -> 0.86 | E20: Tham chiếu bảng 11.4 - Bảng tính toán hệ số tác động môi trường và nhóm làm việc, hệ số phức tạp về môi trường, xác định độ ổn định kinh nghiệm và nội suy thời gian lao động
A21: 6 | B21: Tính điểm AUCP | C21: AUCP = UUCP x TCF x EF | D21: =D18*D19*D20 -> 598.8008 | E21: Theo công thức
A22: II | B22: Nội suy thời gian lao động (P) | C22: P: người/giờ/AUCP | D22: ='B11.4.He so Moi truong'!G17 -> 23.954545 | E22: Nội suy từ độ ổn định kinh nghiệm (ES), tham chiếu bảng 11.4
A23: III | B23: Giá trị nỗ lực thực tế (E) | C23: E = 10/6 x AUCP | D23: =ROUNDUP(D21*10/6,3) -> 998.002 | E23: Theo công thức
A24: IV | B24: Mức lương lao động bình quân (H) | C24: H = Giá nhân công trực tiếp/giờ | D24: ='B8.Dinh muc nhan cong'!E62 -> 72593 | E24: Tham chiếu bảng 8 - Diễn giải chi tiết chi phí tiền lương lao động
A25: V | B25: Giá trị phần mềm nội bộ (G) | C25: G = 1.4 x E x P x H | D25: =1.4*D23*D22*D24 -> 2.4296411e+09
B26: Làm tròn | D26: =ROUNDDOWN(D25,-6) -> 2429000000

Sheet B11.1.Tong hop Usecases
A2: BẢNG 11.1 - BẢNG TÍNH TOÁN ĐIỂM CÁC TRƯỜNG HỢP SỬ DỤNG (USE-CASE) - TBF
A4: STT | B4: Loại | C4: Trọng số | D4: Hệ số BMT | E4: Số trường hợp sử dụng | F4: Điểm của từng loại trường hợp sử dụng | G4: Ghi chú
A5: 1 | B5: B | E5: =SUBTOTAL(9,E6:E8) -> 60 | G5: Trường hợp sử dụng có các giao dịch mô tả yêu cầu chức năng nghiệp vụ của phần mềm, không bao gồm chức năng được phân loại M và T.
B6: Đơn giản | C6: 5 | D6: 1 | E6: ='B11.5.DS.Usecase'!C489 -> 21 | F6: =C6*D6*E6 -> 105 | G6: Có số lượng giao dịch < 4
B7: Trung bình | C7: 10 | D7: 1 | E7: ='B11.5.DS.Usecase'!C490 -> 39 | F7: =C7*D7*E7 -> 390 | G7: Có số lượng giao dịch từ 4 đến 7
B8: Phức tạp | C8: 15 | D8: 1 | E8: ='B11.5.DS.Usecase'!C491 -> 0 | F8: =C8*D8*E8 -> 0 | G8: Có số lượng giao dịch > 7
A9: 2 | B9: M | E9: =SUBTOTAL(9,E10:E12) -> 27 | G9: Trường hợp sử dụng có các giao dịch mô tả yêu cầu chức năng kết nối, liên thông, chia sẻ dữ liệu với các hệ thống hạ tầng kỹ thuật, phần mềm, CSDL liên quan.
B10: Đơn giản | C10: 5 | D10: 1.2 | E10: ='B11.5.DS.Usecase'!C493 -> 27 | F10: =C10*D10*E10 -> 162 | G10: Có số lượng giao dịch < 4
B11: Trung bình | C11: 10 | D11: 1.2 | E11: ='B11.5.DS.Usecase'!C494 -> 0 | F11: =C11*D11*E11 -> 0 | G11: Có số lượng giao dịch từ 4 đến 7
B12: Phức tạp | C12: 15 | D12: 1.2 | E12: ='B11.5.DS.Usecase'!C495 -> 0 | F12: =C12*D12*E12 -> 0 | G12: Có số lượng giao dịch > 7
A13: 3 | B13: T | E13: =SUBTOTAL(9,E14:E16) -> 0 | G13: Trường hợp sử dụng có các giao dịch mô tả yêu cầu chức năng ứng dụng công nghệ trí tuệ nhân tạo (AI), chuỗi khhối (blockchain), thực tế ảo/thực tế tăng cường (VR/AR), Datamining, Digital Twin… để hỗ trợ ra quyết định
B14: Đơn giản | C14: 5 | D14: 1.5 | E14: ='B11.5.DS.Usecase'!C497 -> 0 | F14: =C14*D14*E14 -> 0 | G14: Có số lượng giao dịch < 4
B15: Trung bình | C15: 10 | D15: 1.5 | E15: ='B11.5.DS.Usecase'!C498 -> 0 | F15: =C15*D15*E15 -> 0 | G15: Có số lượng giao dịch từ 4 đến 7
B16: Phức tạp | C16: 15 | D16: 1.5 | E16: ='B11.5.DS.Usecase'!C499 -> 0 | F16: =C16*D16*E16 -> 0 | G16: Có số lượng giao dịch > 7
A17: Cộng (1+2+3) | E17: TBF
A18: TỔNG HỢP | E18: =SUBTOTAL(9,E5:E16) -> 87 | F18: =SUBTOTAL(9,F5:F16) -> 657

Sheet B11.2.Diem tac nhan
A1: BẢNG 11.2 - BẢNG TÍNH TOÁN ĐIỂM CÁC TÁC NHÂN (ACTORS) TƯƠNG TÁC, TRAO ĐỔI THÔNG TIN VỚI PHẦN MỀM (TAW)
A3: TT | B3: Loại Actor | C3: Mô tả | D3: Trọng số | E3: Số tác nhân | F3: Điểm của từng loại tác nhân
A4: 1 | B4: Đơn giản | C4: Giao diện lập trình ứng dụng (API) | D4: 1 | E4: =COUNTIF($B$12:$B$21,B4) -> 5 | F4: =D4*E4 -> 5
A5: 2 | B5: Trung bình | C5: Giao diện dòng lệnh (CLI) hoặc giao diện thông qua một giao thức nào đó nhưng không phải giao diện lậo trình ứng dụng (API) | D5: 2 | E5: =COUNTIF($B$12:$B$21,B5) -> 1 | F5: =D5*E5 -> 2
A6: 3 | B6: Phức tạp | C6: Nếu tác nhân là một tương tác của người dùng với hệ thống thông qua một giao diện đồ họa | D6: 3 | E6: =COUNTIF($B$12:$B$21,B6) -> 4 | F6: =D6*E6 -> 12
A7: TAW - Cộng (1+2+3) | F7: =SUBTOTAL(9,F4:F6) -> 19
A10: DANH SÁCH ACTOR (TÁC NHÂN)
A11: TT | B11: Phân loại | C11: Danh sách tác nhân | D11: Trọng số | E11: Mô tả
A12: 1 | B12: Phức tạp | C12: Quản trị hệ thống | D12: 3
A13: 2 | B13: Phức tạp | C13: Chuyên viên nhập liệu | D13: 3
A14: 3 | B14: Phức tạp | C14: Chuyên viên khai thác | D14: 3
A15: 4 | B15: Phức tạp | C15: Lãnh đạo | D15: 3
A16: 5 | B16: Trung bình | C16: Công dân, Tổ chức ngoài | D16: 2
A17: 6 | B17: Đơn giản | C17: Phần mềm quản lý văn bản, điều hành và phòng họp không giấy tờ | D17: 1
A18: 7 | B18: Đơn giản | C18: Hệ thống quản trị tổng thể (ứng dụng di động và cổng truy cập web) | D18: 1
A19: 8 | B19: Đơn giản | C19: Hệ thống định danh và xác thực điện tử | D19: 1
A20: 9 | B20: Đơn giản | C20: Hệ thống kho dữ liệu dùng chung | D20: 1
A21: 10 | B21: Đơn giản | C21: Nền tảng kết nối chia sẻ của Bộ Tư pháp (LGSP) | D21: 1
A22: Các dòng mới phải được thêm trên dòng này

Sheet B11.3.He so Cong nghe
A2: BẢNG 11.3 - BẢNG TÍNH TOÁN HỆ SỐ PHỨC TẠP KỸ THUẬT-CÔNG NGHỆ (TCF)
A4: STT | B4: Các hệ số KT | C4: Trọng số | D4: Giá trị xếp hạng | E4: Kết quả | F4: Ghi chú
A5: I | B5: Hệ số KT - CN (TFW)
A6: 1 | B6: Xử lý phân tán | C6: 1 | D6: 4 | E6: =D6*C6 -> 4 | F6: - Hệ thống sử dụng kiến trúc Microservice, có khả năng xử lý phân tán. Trong đó, dữ liệu được truyền theo 2 chiều
A7: 2 | B7: Mức độ quan trọng của hiệu năng | C7: 1 | D7: 3 | E7: =D7*C7 -> 3 | F7: - Thời gian xử lý cần đảm bảo ở tốc độ cao, hệ thống có thời gian phản hồi trung bình dưới 10 giây đối với mỗi luồng công việc chính riêng rẽ và không bao gồm các luồng mang tính chất thống kê, báo cáo (thời gian phản hồi được tính từ khi người sử dụng gửi yêu cầu đáp ứng tới hệ thống cho đến khi nhận được dữ liệu phản hồi từ hệ thống). Hệ thống có thời gian phản hồi chậm nhất dưới 30 giây đối với toàn bộ các thao tác trên toàn trang và đảm bảo người dùng không có cảm giác về độ trễ của chương trình. Khi chương trình có độ trễ nhất định cho tác vụ, hệ thống cần có công cụ hiển thị lời thông báo hoặc biểu tượng hiển thị cho người dùng nhận biết được rằng hệ thống vẫn đang hoạt động. - Độ phức tạp xử lý của các chức năng phần mềm cần đảm bảo các chức năng thỏa mãn yêu cầu nghiệp vụ của người dùng hệ thống và đảm bảo tính logic về nghiệp vụ giữa các chức năng. - Hệ thống cần phải chú ý đến việc truy vấn dữ liệu với tốc độ xử lý nhanh nhất bằng cách phân thành nhiều thao tác nếu chức năng đó có nhiều thao tác truy vấn dữ liệu, hạn chế truy vấn có độ phức tạp cao sẽ dẫn đến hết thời gian (Time out) truy vấn dữ liệu
A8: 3 | B8: Hiệu quả sử dụng cho người dùng | C8: 1 | D8: 3 | E8: =D8*C8 -> 3 | F8: - Giao diện hệ thống cần được trình bày khoa học, hợp lý, thuận tiện cho người sử dụng và đảm bảo mỹ thuật hài hòa, giúp cho các thao tác nhập và khai thác, tra cứu dữ liệu được thuận tiện, nhanh chóng; - Hệ thống cần có khả năng hỗ trợ sử dụng các bộ gõ tiếng Việt khác nhau trong nhập liệu; sử dụng bảng mã Unicode để mã hóa và lưu trữ dữ liệu. - Hệ thống cần sử dụng các chuẩn về truy cập thông tin. - Với mỗi người sử dụng cần có phương án thực hiện hiển thị các chức năng tương ứng với phần việc chuyên trách, giúp Người sử dụng sử dụng dễ dàng và hiệu quả. - Có tài liệu HDSD trực tuyến. - Sử dụng nhiều màu sắc và hình ảnh nổi bật trong màn hình. - Có các ràng buộc đơn giản.
A9: 4 | B9: Độ phức tạp của xử lý bên trong | C9: 2 | D9: 3 | E9: =D9*C9 -> 6 | F9: - Trong quá trình sử dụng nếu xảy ra lỗi cú pháp lập trình, hệ thống đảm bảo không bị treo, hiển thị thông báo lỗi, dữ liệu đang thao tác trả về nguyên trạng trước khi xảy ra lỗi. - Hệ thống có cơ chế kiểm tra tính đúng đắn của dữ liệu đầu vào và thông báo cho người sử dụng. - Quy định về lỗi quy trình nghiệp vụ: Đảm bảo đúng và đầy đủ quy trình nghiệp vụ theo thiết kế thi công. - Yêu cầu xử lý nhiều loại thông tin đầu vào, đầu ra.
A10: 5 | B10: Khả năng tái sử dụng mã nguồn | C10: 1 | D10: 3 | E10: =D10*C10 -> 3 | F10: - Yêu cầu ứng dụng được đóng gói riêng và tài liệu hóa nhằm tạo điều kiện cho việc tái sử dụng lại. Có yêu cầu có thể tùy chỉnh ứng dụng để tái sử dụng bằng cách điều chỉnh mã nguồn.
A11: 6 | B11: Dễ cài đặt | C11: 0.5 | D11: 3 | E11: =D11*C11 -> 1.5 | F11: - Hệ thống có khả năng triển khai dễ dàng, cho phép người dùng là Cán bộ quản trị có thể tự cài đặt, cấu hình hệ thống hoặc cập nhật các bản vá lỗi hệ thống khi cần thiết.
A12: 7 | B12: Dễ vận hành | C12: 0.5 | D12: 3 | E12: =D12*C12 -> 1.5 | F12: - Việc vận hành hệ thống thực hiện theo quy trình, có yêu cầu phải lập quy trình vận hành hệ thống.
A13: 8 | B13: Khả năng chuyển đổi | C13: 1 | D13: 3 | E13: =D13*C13 -> 3 | F13: - Hệ thống có khả năng triển khai cài đặt trên các nền tảng hệ điều hành phổ biến như Windows, Linux. - Người dùng có khả năng truy cập hệ thống thông qua các trình duyệt web phổ biến như Chrome, Firefox, Edge, …
A14: 9 | B14: Dễ bảo trì | C14: 1 | D14: 3 | E14: =D14*C14 -> 3 | F14: - Có yêu cầu về việc chỉnh sửa hệ thống trong tương lai mà không cần lập trình lại từ đầu.
A15: 10 | B15: Xử lý đồng thời | C15: 1 | D15: 3 | E15: =D15*C15 -> 3 | F15: - Hệ thống cần đảm bảo sẵn sàng cho phép người dùng là các cán bộ quản trị tham gia đồng thời thực hiện các hoạt động nghiệp vụ trên hệ thống.
A16: 11 | B16: Mức độ bảo mật | C16: 2 | D16: 3 | E16: =D16*C16 -> 6 | F16: - Yêu cầu bảo mật mức 3
A17: 12 | B17: Sự phụ thuộc vào mã lệnh của bên thứ ba | C17: 1 | D17: 3 | E17: =D17*C17 -> 3 | F17: - Sử dụng thư viện có sẵn để xây dựng chức năng Hỗ trợ soạn thảo, nhưng cần phải sử lỗi và phát triển thêm để đáp ứng nhu cầu nghiệp vụ.
A18: 13 | B18: Mức độ hỗ trợ đào tạo người sử dụng | C18: 1 | D18: 3 | E18: =D18*C18 -> 3 | F18: Cần thực hiện đào tạo, hướng dẫn sử dụng cho các đối tượng người dùng của hệ thống đảm bảo người dùng nắm được nghiệp vụ và sử dụng hệ thống thành thạo
B19: Cộng I (TFW) | E19: =SUM(E6:E18) -> 43
A20: II | B20: Hệ số phức tạp về kỹ thuật (TCF): TCF = 0,6 + (0,01 x TFW) | E20: =(0.6+(0.01*E19)) -> 1.03
A23: Hệ số “Xử lý phân tán” (TFW1)
A24: Giá trị xếp hạng | B24: Yêu cầu cụ thể cho giá trị
A25: 0 | B25: Không yêu cầu xử lý phân tán.
A26: 1 | B26: Yêu cầu một lớp/thành phần của hệ thống tạo dữ liệu và truyền cho các lớp/thành phần khác của hệ thống để xử lý thủ công (có sự can thiệp của con người).
A27: 2 | B27: Yêu cầu một lớp/thành phần của hệ thống tạo dữ liệu và truyền cho các lớp/thành phần khác của hệ thống để xử lý tự động (không cần con người can thiệp vào việc xử lý).
A28: 3 | B28: Yêu cầu xử lý phân tán, dữ liệu được truyền theo một chiều (dữ liệu được xử lý tại một lớp/thành phần của hệ thống và được truyền qua lớp/thành phần khác của hệ thống xử lý tiếp).
A29: 4 | B29: Yêu cầu xử lý phân tán, dữ liệu được truyền theo hai chiều (dữ liệu được xử lý tại một lớp/thành phần của hệ thống và được truyền qua lớp/thành phần khác của hệ thống xử lý tiếp, sau khi xử lý xong, dữ liệu được truyền ngược lại cho lớp/thành phần ban đầu của hệ thống)
A30: 5 | B30: Yêu cầu hệ thống có thể tự động phân bổ tài nguyên (CPU, RAM, ...) một cách hợp lý cho các lớp/thành phần của hệ thống khi xử lý phân tán hoặc yêu cầu hệ thống tự động lựa chọn lớp/thành phần thích hợp nhất để xử lý.
A32: Hệ số “Mức độ quan trọng của hiệu năng” (TFW2)
A33: Giá trị xếp hạng | B33: Yêu cầu cụ thể cho giá trị
A34: 0 | B34: Không có yêu cầu về hiệu năng.
A35: 1 | B35: Có yêu cầu về hiệu năng nhưng không cụ thể
A36: 2 | B36: Yêu cầu cụ thể về hiệu năng trong giờ cao điểm. Không có yêu cầu thiết kế riêng biệt về sử dụng tài nguyên hệ thống để đáp ứng yêu cầu hiệu năng trong giờ cao điểm.
A37: 3 | B37: Yêu cầu cụ thể hiệu năng trong toàn bộ thời gian tác nghiệp. Không có yêu cầu thiết kế riêng biệt về sử dụng tài nguyên hệ thống để đáp ứng yêu cầu hiệu năng, yêu cầu cụ thể về thời gian phản hồi đối với các giao dịch được xử lý với các hệ thống (tích hợp) khác.
A38: 4 | B38: Gồm các yêu cầu trong trường hợp “Giá trị xếp hạng” = 3 và có yêu cầu phân tích cụ thể, rõ ràng hiệu năng trong thiết kế trên cơ sở các yêu cầu về hiệu năng được nêu.
A39: 5 | B39: Gồm các yêu cầu trong trường hợp “Giá trị xếp hạng” = 4 và yêu cầu có công cụ phân tích hiệu năng để sử dụng trong các giai đoạn phát triển, triển khai nhằm chứng minh việc đáp ứng các yêu cầu về hiệu năng đã đặt ra.
A41: Hệ số “Hiệu quả sử dụng cho người dùng” (TFW3)
A42: Giá trị xếp hạng | B42: Yêu cầu cụ thể cho giá trị
A43: 0 | B43: Không có yêu cầu nào về hiệu quả sử dụng theo các tiêu chí nêu dưới đây.
A44: 1 | B44: Yêu cầu đáp ứng từ 1 đến 3 tiêu chí nêu bên dưới
A45: 2 | B45: Yêu cầu đáp ứng từ 4 đến 5 tiêu chí nêu bên dưới
A46: 3 | B46: Yêu cầu đáp ứng từ 6 tiêu chí nêu bên dưới trở lên.
...

Sheet B11.4.He so Moi truong
A1: BẢNG 11.4 - BẢNG TÍNH TOÁN HỆ SỐ TÁC ĐỘNG MÔI TRƯỜNG VÀ NHÓM LÀM VIỆC, HỆ SỐ PHỨC TẠP VỀ MÔI TRƯỜNG, XÁC ĐỊNH ĐỘ ỔN ĐỊNH KINH NGHIỆM VÀ NỘI SUY THỜI GIAN LAO ĐỘNG
A3: STT | B3: Các hệ số tác động môi trường | C3: Mức xếp hạng (Từ 0 đến 5) | D3: Trọng số chuẩn | E3: Giá trị xếp hạng | F3: Kết quả (KQ) | G3: Đánh giá độ ổn định KN
A4: I | B4: Hệ số tác động môi trường và nhóm dự án (EFW) | F4: =SUBTOTAL(9,F5:F14) -> 18
B5: Đánh giá cho từng thành viên
A6: F1 | B6: Có áp dụng quy trình phát triển phần mềm | C6: 0 = Dưới 10% các thành viên nhóm phát triển có kinh nghiệm 1 = Yêu cầu ít nhất 10% thành viên nhóm phát triển có kinh nghiệm 2 = Yêu cầu ít nhất 20% thành viên nhóm phát triển có kinh nghiệm 3 = Yêu cầu ít nhất 30% thành viên nhóm phát triển có kinh nghiệm 4 = Yêu cầu ít nhất 40% thành viên nhóm phát triển có kinh nghiệm 5 = Yêu cầu ít nhất 50% thành viên nhóm phát triển có kinh nghiệm | D6: 1.5 | E6: 3 | F6: =D6*E6 -> 4.5 | G6: =IF(F6>3,1,IF(F6>2,0.6,IF(F6>1,0.1,IF(F6>0,0.05,0)))) -> 1
A7: F2 | B7: Kinh nghiệm phát triển ứng dụng tương tự | D7: 0.5 | E7: 2 | F7: =D7*E7 -> 1 | G7: =IF(F7>3,1,IF(F7>2,0.6,IF(F7>1,0.1,IF(F7>0,0.05,0)))) -> 0.05
A8: F3 | B8: Kinh nghiệm về hướng đối tượng | D8: 1 | E8: 3 | F8: =D8*E8 -> 3 | G8: =IF(F8>3,1,IF(F8>2,0.6,IF(F8>1,0.1,IF(F8>0,0.05,0)))) -> 0.6
A9: F4 | B9: Kinh nghiệm của trưởng nhóm lập trình | C9: 0 = Không yêu cầu về kinh nghiệm của trưởng nhóm lập trình. 1 = Yêu cầu trưởng nhóm lập trình đã có kinh nghiệm làm trưởng nhóm lập trình 1 dự án/nhiệm vụ. 2 = Yêu cầu trưởng nhóm lập trình đã có kinh nghiệm làm trưởng nhóm lập trình 2 dự án/nhiệm vụ. 3 = Yêu cầu trưởng nhóm lập trình đã có kinh nghiệm làm trưởng nhóm lập trình 3 dự án/nhiệm vụ. 4 = Yêu cầu trưởng nhóm lập trình đã có kinh nghiệm làm trưởng nhóm lập trình 5 dự án/nhiệm vụ. 5 = Yêu cầu trưởng nhóm lập trình đã có kinh nghiệm làm trưởng nhóm lập trình 5 dự án/nhiệm vụ. | D9: 0.5 | E9: 3 | F9: =D9*E9 -> 1.5 | G9: =IF(F9>3,1,IF(F9>2,0.6,IF(F9>1,0.1,IF(F9>0,0.05,0)))) -> 0.1
A10: F5 | B10: Tính chủ động | C10: 0 = Yêu cầu nhóm phát triển có kế hoạch cụ thể công việc (hằng ngày), lập báo cáo công việc hằng ngày. 1 = Yêu cầu nhóm phát triển thực hiện báo cáo công việc hàng tuần. 2 = Yêu cầu nhóm phát triển thực hiện báo cáo công việc theo tháng. 3 = Yêu cầu nhóm phát triển thực hiện báo cáo công việc quý. 4 = Yêu cầu nhóm phát triển thực hiện báo cáo công việc theo các mốc công việc/sản phẩm trong kế hoạch thực hiện nhưng không yêu cầu lập báo cáo công việc định kỳ. 5 = Không yêu cầu nhóm phát triển thực hiện báo cáo theo các mốc công việc/sản phẩm trong kế hoạch thực hiện. | D10: 1 | E10: 4 | F10: =D10*E10 -> 4 | G10: =IF(F10>3,1,IF(F10>2,0.6,IF(F10>1,0.1,IF(F10>0,0.05,0)))) -> 1
B11: Đánh giá chung cho Dự án
A12: F6 | B12: Độ ổn định của các yêu cầu | C12: 0 = Các yêu cầu hệ thống không có độ ổn định, có thể có trên 50% số lượng Use case liên quan đến những yêu cầu nghiệp vụ cần phân tích, đặc tả cụ thể, chi tiết hơn. 1 = Các yêu cầu hệ thống có độ ổn định rất thấp, có thể có từ 30% đến 50% số lượng Use case liên quan đến những yêu cầu nghiệp vụ cần phân tích, đặc tả cụ thể, chi tiết hơn. 2 = Các yêu cầu hệ thống có độ ổn định thấp, có thể có từ 10% đến 30% số lượng Use case liên quan đến những yêu cầu nghiệp vụ cần phân tích, đặc tả cụ thể, chi tiết hơn. 3 = Các yêu cầu hệ thống tương đối ổn định, có thể có dưới 10% số lượng Use case liên quan đến những yêu cầu nghiệp vụ cần phân tích, đặc tả cụ thể, chi tiết hơn. 4 = Các yêu cầu hệ thống ổn định, trong giai đoạn xây dựng, phát triển, mở rộng phần mềm chỉ cho phép điều chỉnh giao diện về mặt mỹ thuật. 5 = Các yêu cầu hệ thống hoàn toàn ổn định. | D12: 2 | E12: 3 | F12: =D12*E12 -> 6 | G12: =IF(F12>3,1,IF(F12>2,0.6,IF(F12>1,0.1,IF(F12>0,0.05,0)))) -> 1
A13: F7 | B13: Sử dụng nhân viên bán thời gian | C13: 0 = Không sử dụng nhân viên làm bán thời gian. 1 = Cho phép tối đa 10% nhân viên làm bán thời gian. 2 = Cho phép tối đa 20% nhân viên làm bán thời gian. 3 = Cho phép tối đa 30% nhân viên làm bán thời gian. 4 = Cho phép tối đa 40% nhân viên làm bán thời gian. 5 = Cho phép trên 40% trở lên nhân viên làm bán thời gian. | D13: -1 | E13: 0 | F13: =D13*E13 -> 0 | G13: =IF(F13>3,1,IF(F13>2,0.6,IF(F13>1,0.1,IF(F13>0,0.05,0)))) -> 0
A14: F8 | B14: Kinh nghiệm sử dụng ngôn ngữ lập trình | C14: 0 = Không yêu cầu thành viên nhóm lập trình có kinh nghiệm sử dụng ngôn ngữ lập trình dự kiến. 1 = Yêu cầu ít nhất 20% thành viên nhóm lập trình có kinh nghiệm lập trình. 2 = Yêu cầu ít nhất 40% thành viên nhóm lập trình có kinh nghiệm lập trình. 3 = Yêu cầu ít nhất 60% thành viên nhóm lập trình có kinh nghiệm lập trình. 4 = Yêu cầu ít nhất 80% thành viên nhóm lập trình có kinh nghiệm lập trình. 5 = Yêu cầu tất cả các thành viên trong nhóm lập trình có kinh nghiệm lập trình. | D14: -1 | E14: 2 | F14: =D14*E14 -> -2 | G14: =IF(F14>3,1,IF(F14>2,0.6,IF(F14>1,0.1,IF(F14>0,0.05,0)))) -> 0
A15: II | B15: Hệ số độ phức tạp về môi trường (Environmental Factor) | C15: EF = 1.4 + (-0.03 x EFW) | F15: =1.4+(-0.03*F4) -> 0.86
A16: III | B16: Độ ổn định kinh nghiệm (Experience Stable) | C16: ES | G16: =SUM(G6:G14) -> 3.75
A17: IV | B17: Nội suy năng suất P | C17: P= người/giờ/AUCP | G17: =IF(G16>=3,26 - (G16-3)*(6/2.2),IF(G16>=1,40-(G16-1)*7, 48 -G16* 8)) -> 23.954545

Sheet B11.6. DSYC
A1: BẢNG 11.6: BẢNG CHUYỂN ĐỔI YÊU CẦU CHỨC NĂNG SANG TRƯỜNG HỢP SỬ DỤNG (USE-CASE) | E1: Yêu cầu truy vấn
A2: STT | B2: Use case | C2: Mô tả trường sử dụng | D2: Phân loại
A3: A | B3: PHIÊN BẢN WEB
A4: I | B4: Quản trị hệ thống
A5: 1 | B5: Quản lý người dùng
C6: Quản trị hệ thống có thể tìm kiếm thông tin người dùng. Hệ thống hiển thị kết quả tìm kiếm | D6: Yêu cầu truy vấn
C7: Quản trị hệ thống có thể thêm mới thông tin người dùng. Hệ thống hiển thị kết quả thêm mới | D7: Dữ liệu đầu vào
C8: Quản trị hệ thống có thể thêm mới người dùng bằng tệp mẫu. Hệ thống hiển thị kết quả thêm mới | D8: Dữ liệu đầu vào
C9: Quản trị hệ thống có thể xuất thông tin người dùng ra file excel. Hệ thống thực hiện tải xuống file excel | D9: Dữ liệu đầu ra
C10: Quản trị hệ thống có thể tải tệp mẫu thêm mới người dùng. Hệ thống thực hiện tải xuống file mẫu | D10: Dữ liệu đầu ra
C11: Quản trị hệ thống có thể cập nhật thông tin người dùng. Hệ thống hiển thị kết quả cập nhật | D11: Dữ liệu đầu vào
C12: Quản trị hệ thống có thể đổi chữ ký. Hệ thống hiển thị đã đổi chữ ký thành công | D12: Dữ liệu đầu vào
C13: Quản trị hệ thống có thể gán vai trò cho người dùng. Hệ thống hiển thị gán vai trò thành công | D13: Dữ liệu đầu vào
C14: Quản trị hệ thống có thể reset mật khẩu người dùng. Hệ thống hiển thị cập nhật mật khẩu thành công | D14: Dữ liệu đầu vào
C15: Quản trị hệ thống có thể khóa/mở khoá thông tin người dùng. Hệ thống hiển thị người dùng đã bị khóa/mở khoá | D15: Dữ liệu đầu vào
A16: 2 | B16: Quản lý vai trò
C17: Quản trị hệ thống có thể điều chỉnh số bản ghi hiển thị trong danh sách vai trò. Hệ thống hiển thị đúng số bản ghi đã điều chỉnh | D17: Dữ liệu đầu vào
C18: Quản trị hệ thống có thể thêm mới thông tin vai trò. Hệ thống hiển thị kết quả thêm mới | D18: Dữ liệu đầu vào
C19: Quản trị hệ thống có thể cập nhật thông tin vai trò. Hệ thống hiển thị kết quả cập nhật | D19: Dữ liệu đầu vào
C20: Quản trị hệ thống có thể tìm kiếm thông tin vai trò. Hệ thống hiển thị kết quả tìm kiếm | D20: Yêu cầu truy vấn
C21: Quản trị hệ thống có thể cấu hình chức năng cho vai trò. Hệ thống hiển thị đã cấu hình chức năng cho vai trò thành công | D21: Dữ liệu đầu vào
C22: Quản trị hệ thống có thể khóa/mở khoá vai trò. Hệ thống hiển thị vai trò đã bị khóa/mở khoá | D22: Dữ liệu đầu vào
C23: Quản trị hệ thống có thể xóa vai trò. Hệ thống hiển thị đã xoá vai trò thành công | D23: Dữ liệu đầu vào
A24: 3 | B24: Quản lý đơn vị
C25: Quản trị hệ thống có thể xem danh sách đơn vị theo cây đơn vị. Hệ thống hiển thị cây đơn vị | D25: Dữ liệu đầu vào
C26: Quản trị hệ thống có thể thêm mới thông tin đơn vị cấp dưới. Hệ thống hiển thị kết quả thêm mới | D26: Dữ liệu đầu vào
C27: Quản trị hệ thống có thể thêm mới thông tin đơn vị cấp dưới bằng tệp mẫu. Hệ thống hiển thị kết quả thêm mới | D27: Dữ liệu đầu vào
C28: Quản trị hệ thống có thể cập nhật thông tin đơn vị cấp dưới. Hệ thống hiển thị kết quả cập nhật | D28: Dữ liệu đầu vào
C29: Quản trị hệ thống có thể tải tệp mẫu thêm mới đơn vị cấp dưới. Hệ thống thực hiện tải xuống tệp mẫu | D29: Dữ liệu đầu ra
C30: Quản trị hệ thống có thể xoá đơn vị cấp dưới khỏi đơn vị. Hệ thống hiển thị kết quả xoá đơn vị cấp dưới khỏi đơn vị | D30: Dữ liệu đầu vào
C31: Quản trị hệ thống có thể xem chi tiết đơn vị cấp dưới. Hệ thống hiển thị chi tiết đơn vị cấp dưới | D31: Dữ liệu đầu vào
C32: Quản trị hệ thống có thể xem cá nhân thuộc đơn vị. Hệ thống hiển thị danh sách cá nhân thuộc đơn vị | D32: Dữ liệu đầu vào
A33: 4 | B33: Quản lý luồng
C34: Quản trị hệ thống có thể xem danh sách luồng. Hệ thống hiển thị danh sách tất cả luồng | D34: Dữ liệu đầu vào
C35: Quản trị hệ thống có thể tìm kiếm luồng. Hệ thống hiển thị kết quả tìm kiếm | D35: Yêu cầu truy vấn
C36: Quản trị hệ thống có thể thêm mới luồng. Hệ thống hiển thị kết quả thêm mới | D36: Dữ liệu đầu vào
C37: Quản trị hệ thống có thể cập nhật thông tin luồng. Hệ thống hiển thị kết quả cập nhật | D37: Dữ liệu đầu vào
C38: Quản trị hệ thống có thể cấu hình luồng. Hệ thống hiển thị cấu hình thành công | D38: Dữ liệu đầu vào
C39: Quản trị hệ thống có thể khóa/mở khoá luồng. Hệ thống hiển thị luồng đã bị khóa/mở khoá | D39: Dữ liệu đầu vào
C40: Quản trị hệ thống có thể xóa luồng. Hệ thống hiển thị luồng đã được xoá | D40: Dữ liệu đầu vào
...

Sheet B12. CP Kiem thu doc lap
A1: BẢNG 12: BẢNG TÍNH CHI PHÍ KIỂM THỬ PHẦN MỀM NỘI BỘ
A3: Căn cứ: - Công văn số 3787/BTTTT-THH ngày 26/12/2014 - Thông tư số 24/2020/TT-BTTTT ngày 09/9/2020
A4: GIÁ TRỊ DỰ TOÁN CHI PHÍ KIỂM THỬ PHẦN MỀM NỘI BỘ
A5: TT | B5: Khoản mục chi phí | C5: Cách tính | D5: Giá trị | E5: Ghi chú
A6: 1 | B6: Giá trị kiểm thử phần mềm (G) | C6: G = ExH | D6: =D24 -> 2.0474154e+08
A7: 2 | B7: Chi phí chung (C) | C7: C = G x 65% | D7: =65%*D6 -> 1.33082e+08
A8: 3 | B8: Thu nhập chịu thuế tính trước (TL) | C8: TL = (G + C) x 6% | D8: =6%*(D6+D7) -> 20269412
A9: 4 | B9: Thuế giá trị gia tăng (GTGT) | C9: (G+C+TL) x 0% | D9: =(D6+D7+D8)*0% -> 0
A10: 5 | B10: Chi phí kiểm thử phần mềm (Gkt) | C10: Gkt = G + C + TL | D10: =SUBTOTAL(9,D6:D9) -> 3.5809295e+08
A11: TỔNG CỘNG | C11: Gpm (làm tròn) | D11: =ROUNDUP(D10,-3) -> 358093000
A13: DIỄN GIẢI GIÁ TRỊ KIỂM THỬ PHẦN MỀM
A14: TT | B14: Khoản mục chi phí | C14: Diễn giải | D14: Giá trị | E14: Ghi chú
A15: 1 | B15: Giá trị điểm các tác nhân (AW) | C15: Actor TAW | D15: ='B11.2.Diem tac nhan'!F7 -> 19 | E15: Theo bảng tổng hợp tác nhân của phần mềm
A16: 2 | B16: Giá trị điểm các trường hợp sử dụng (UCW) | C16: Diem UC UUCP | D16: ='B11.1.Tong hop Usecases'!F18 -> 657 | E16: Theo bảng tổng hợp các trường hợp sử dụng của phần mềm
