Workbook
Name ___b3: #REF!
Name ___B7: #REF!
Name __b3: #REF!
Name __B7: #REF!
Name __CON1: #REF!
Name __CON2: #REF!
Name __cpd1: #REF!
Name __cpd2: #REF!
Name __ddn400: #REF!
Name __ddn600: #REF!
Name __EXC1: #REF!
Name __EXC2: #REF!
Name __FIL2: #REF!
Name __HTD1: #REF!
Name __HTN1: #REF!
Name __lap1: #REF!
Name __lap2: #REF!
Name __LCB1: #REF!
Name __MAC12: #REF!
Name __MAC46: #REF!
Name __NCL100: #REF!
Name __NCL200: #REF!
Name __NCL250: #REF!
Name __nin190: #REF!
Name __NO1: #REF!
Name __Ph30: #REF!
Name __PXB80: #REF!
Name __pZ1: #REF!
Name __pZ2: #REF!
Name __pZ3: #REF!
Name __RFZ3: #REF!
Name __ro1: #REF!
Name __rp95: #REF!
Name __sc1: #REF!
Name __SC2: #REF!
Name __sc3: #REF!
Name __SHR1: #REF!
Name __SHR2: #REF!
Name __SN3: #REF!
Name __tax1: #REF!
Name __tax2: #REF!
Name __tax3: #REF!
Name __tax4: #REF!
Name __TB1: #REF!
Name __tg427: #REF!
Name __TL1: #REF!
Name __TL2: #REF!
Name __TL3: #REF!
Name __TLA120: #REF!
Name __TLA35: #REF!
Name __TLA50: #REF!
Name __TLA70: #REF!
Name __TLA95: #REF!
Name __TX1: #REF!
Name __tz593: #REF!
Name __vl1: #REF!
Name __VL100: #REF!
Name __VL250: #REF!
Name __xb80: #REF!
Name __xo1: #REF!

Sheet Yêu cầu
B2: 1 | C2: Cấu trúc lại các nhóm chức năng theo Công văn 631
B3: 2 | C3: Cập nhật lại tên UC, các trường hợp sử dụng phù hợp với Công văn 631
B4: 3 | C4: Liệt kê (hoặc commment trực tiếp vào từng UC) các sửa đổi so với UC cũ

Sheet CongVan 631
A1: LGSP: Nền tảng chia sẻ, tích hợp dùng chung | I1: LDOP: Nền tảng chia sẻ, điều phối dữ liệu ngành/khối cơ quan - Là hạ tầng kết nối, tích hợp, chia sẻ và điều phối dữ liệu - Là phương thức kết nối, chia sẻ dữ liệu bắt buộc - Máy chủ bảo mật điểm kết nối (Agent Node) là thành phần của Nền tảng chia sẻ, điều phối dữ liệu có chức năng bảo mật điểm kết nối phục vụ trao đổi, chia sẻ dữ liệu giữa các cơ sở dữ liệu, hệ thống thông tin
C2: 1. Yêu cầu với phần mềm nền tảng
C4: TT | D4: Thành phần | E4: Yêu cầu | F4: Chức năng | G4: Yêu cầu kỹ thuật
C5: 1 | D5: Trục tích hợp | E5: Bắt buộc | F5: Các chức năng liên quan đến kết nối | G5: - Bộ thích ứng kết nối (Adapters): Cung cấp các bộ Adapter được xây dựng sẵn để kết nối đến các hệ thống đang được vận hành và khai thác khác nhau như Hệ thống thanh toán, Cổng dịch vụ công, Hệ thống báo cáo quốc gia…. Các Adapter có thể dễ dàng được phát triển mới và tích hợp vào trục tích hợp khi cần thiết. | I5: Nền tảng chia sẻ, điều phối dữ liệu quốc gia NDOP cung cấp các thành phần chính:
G6: - Truyền tải (Transports): Hỗ trợ nhiều giao thức truyền tải như HTTP, HTTPS, WebSocket, POP, IMAP, SMTP, JMS 1.1, JMS 2.0, AMQP, RabbitMQ, FIX, TCP, UDP, FTPS, SFTP, MLLP , SMS, MQTT, Apache Kafka. | I6: - Thành phần Tích hợp dữ liệu quốc gia: thực hiện chức năng thu thập, tích hợp dữ liệu từ các cơ quan chủ quản dữ liệu về Cơ sở dữ liệu tổng hợp quốc gia theo thời gian thực hoặc định kỳ.
G7: - Định dạng dữ liệu (Formats): Hỗ trợ nhiều chuẩn dữ liệu như JSON, XML, SOAP 1.1, SOAP 1.2, WS-*, HTML, EDI, HL7, OAGIS, Hessian, Text, JPEG, MP4, CORBA/IIOP và các định dạng phổ biến khác. | I7: - Thành phần Phân phối dữ liệu quốc gia: thực hiện chức năng phân phối dữ liệu từ Cơ sở dữ liệu tổng hợp quốc gia tới cơ quan sử dụng dữ liệu theo yêu cầu hoặc chủ động.
F8: Các chức năng liên quan đến định tuyến, xử lý và chuyển đổi bản tin | G8: - Định tuyến (Routing): Định tuyến dựa vào Header hoặc body của gói tin; định tuyến dựa vào luật (Rule). | I8: - Thành phần Chia sẻ dữ liệu quốc gia: thực hiện chức năng kết nối, giám sát và trung gian cho phép các cơ quan trao đổi dữ liệu trực tiếp với nhau sau khi xác thực và đăng ký dữ liệu và dịch vụ trao đổi dữ liệu.
G9: - Xử lý nghiệp vụ (Mediator): Hỗ trợ sẵn các bộ chuyển đổi để xử lý các nghiệp vụ khác nhau như cache, kết nối CSDL, kết nối File, logging,… | I9: - Thành phần bảo mật điểm kết nối AGN (Agent Node) là thành phần của nền tảng NDOP được triển khai tại các cơ quan, tổ chức, bộ ngành, địa phương bảo đảm về an toàn bảo mật điểm kết nối và trao đổi dữ liệu giữa nền tảng LDOP với nền tảng NDOP tại Trung tâm dữ liệu quốc gia để thực hiện điều phối dữ liệu.
G10: - Chuyển đổi (Transformation): XSLT 1.0/2.0, XPath, XQuery và Smooks. | I10: Nền tảng LDOP bao gồm các thành phần cơ bản có chức năng tương tự như nền tảng NDOP (tích hợp dữ liệu; phân phối dữ liệu; chia sẻ dữ liệu) và trao đổi dữ liệu với Nền tảng NDOP thông qua thành phần bảo mật điểm kết nối AGN.
G11: - Công cụ ánh xạ dữ liệu (Data Mapping): Ánh xạ dữ liệu giữa đầu vào Input và đầu ra Output để chuyển đổi dữ liệu.
F12: Các chức năng như Gateway cho bản tin, API, bảo mật | G12: - Cho phép công khai các ứng dụng và dịch vụ đang có theo các định dạng bản tin và định dạng giao thức khác nhau để các hệ thống khác dễ dàng tích hợp: | I12: - Thành phần Phân phối dữ liệu quốc gia: thực hiện chức năng phân phối dữ liệu từ Cơ sở dữ liệu tổng hợp quốc gia tới cơ quan sử dụng dữ liệu theo yêu cầu hoặc chủ động.
G13: + Không làm ảnh hưởng tới các dịch vụ bên trong.
G14: + Tạo ra các dịch vụ theo chuẩn từ các dịch vụ không theo chuẩn hoặc các hệ thống đã tồn tại.
G15: + Công khai các dịch vụ và ứng dụng qua các giao thức thông dụng như SOAP, REST và XML-RPC.
G16: - Áp dụng các chính sách bảo mật tập trung, bao gồm nhận thực, phân quyền; hỗ trợ các tính năng bảo mật như: WS- Security, LDAP, Kerberos, OpenID, SAML, XACML, Oauth; Quản lý và ràng buộc chính sách thông qua dữ liệu cấu hình.
G17: - Hỗ trợ các cơ chế kiểm soát (audit), cơ chế logging, theo dõi hoạt động hệ thống thông qua SLA.
G18: - Hỗ trợ các tính năng về cân bằng tải, khả năng mở rộng nâng cấp hệ thống, khả năng failover để tăng khả năng HA cho hệ thống.
F19: Khả năng quản trị phát triển dễ dàng, thuận tiện cho người phát triển hệ thống | G19: - Các chế độ cấu hình sửa lỗi (Debug) và bắt lỗi quá trình xử lý bản tin (Message mediation). | I19: - Thành phần Chia sẻ dữ liệu quốc gia: thực hiện chức năng kết nối, giám sát và trung gian cho phép các cơ quan trao đổi dữ liệu trực tiếp với nhau sau khi xác thực và đăng ký dữ liệu và dịch vụ trao đổi dữ liệu.
G20: - Hỗ trợ giao diện cấu hình tham số hệ thống.
G21: - Cho phép cấu hình các bộ Mediator để điều khiển các lỗi trong quá trình vận hành.
G22: - Cho phép khả năng tùy biến toàn bộ các chức năng được triển khai trên máy chủ theo yêu cầu sử dụng.
G23: - Mở rộng ngôn ngữ cấu hình sử dụng DSL tùy chỉnh thông qua các mẫu được dựng sẵn.
G24: - Các bộ Mediator được tùy biến bằng cách sử dụng mã ngôn ngữ kịch bản nhúng trong Javascript, JRuby, Groovy,…
G25: - Xây dựng và triển khai thông qua tích hợp với SVN, Maven, Ant và các công cụ tiêu chuẩn khác.
G26: - Khả năng tích hợp với các công cụ lập trình phổ biến như: IDE Eclipse... | I26: - Thành phần bảo mật điểm kết nối AGN (Agent Node) là thành phần của nền tảng NDOP được triển khai tại các cơ quan, tổ chức, bộ ngành, địa phương bảo đảm về an toàn bảo mật điểm kết nối và trao đổi dữ liệu giữa nền tảng LDOP với nền tảng NDOP tại Trung tâm dữ liệu quốc gia để thực hiện điều phối dữ liệu.
F27: Các chức năng hỗ trợ khả năng quản lý và theo dõi | G27: - Đảm bảo quản lý toàn diện và giám sát qua giao diện Web. | I27: Nền tảng LDOP bao gồm các thành phần cơ bản có chức năng tương tự như nền tảng NDOP (tích hợp dữ liệu; phân phối dữ liệu; chia sẻ dữ liệu) và trao đổi dữ liệu với Nền tảng NDOP thông qua thành phần bảo mật điểm kết nối AGN.
G28: - Cho phép xây dựng các thành phần dùng chung và theo dõi truy cập và thống kê hiệu năng hệ thống.
G29: - Tích hợp với phần mềm giám sát để thực hiện kiểm soát, giám sát tình hình hoạt động hệ thống và đánh giá KPI hệ thống.
G30: - Hỗ trợ các chế độ cấu hình log theo nhiều cấp độ log.
G31: - Bảo đảm quản lý cấu hình tập trung trên các môi trường khác nhau với vòng đời và phiên bản.
F32: Giám sát | G32: - Công khai các thống kê báo cáo về Mediation bản tin qua các giao diện báo cáo, Dashboard.
G33: - Tạo ra các báo cáo Dashboard tùy biến và phân quyền cho người dùng.
G34: - Theo dõi các dữ liệu mang tính chất thống kê cho tất cả các kiểu tài nguyên (Artifact) và hiệu năng hệ thống.
G35: - Thiết lập khả năng trace bất kỳ luồng xử lý Mediation để xác định các điểm nghẽn cổ chai trong luồng xử lý.
C36: 2 | D36: Quản lý quy trình nghiệp vụ (BPM) | E36: Tùy chọn (BỎ) | F36: Quản lý quy trình nghiệp vụ | G36: Phần mềm quy trình nghiệp vụ cần có các tính năng kỹ thuật chính như sau:
G37: - Định nghĩa và chạy quy trình nghiệp vụ: Hỗ trợ BPMN 2.0, WS- BPEL 2.0, BPEL4WS 1.1.
G38: - Định nghĩa các luồng nghiệp vụ có tương tác với con người: Hỗ trợ User Task trong luồng quy trình BPMN.
G39: - Điều khiển truy cập dựa trên vai trò người dùng cho các bước trong quy trình.
G40: - Hỗ trợ tạo Form người dùng tương tác cho các bước cần xử lý bởi người dùng.
G41: - Công cụ hỗ trợ Thiết kế và triển khai quy trình động.
...

Sheet DinhMuc
A1: Định mức tỷ lệ chi phí quản lý dự án, tư vấn, chi khác
A2: Quyết định số 1688/QĐ-BTTTT ngày 11/10/2019 của Bộ Thông tin và Truyền thông, áp dụng tương tự Hạng mục phần mềm nội bộ, cơ sở dữ liệu trong Báo cáo kinh tế - kỹ thuật
A4: stt | B4: Tên hạng mục | C4: Ga (cận trên) (đồng) | D4: Gb (cận dưới) (đồng) | E4: Gt (đồng) | F4: Na (cận trên) | G4: Nb (cận dưới) | H4: Nt | I4: Ghi chú
A5: 1 | B5: Quản lý dự án
B6: Phần mềm thương mại | E6: 0 | F6: 2.184 | G6: 2.644 | H6: =G6*0.84 -> 2.22096 | I6: =Nb * 0,84
B7: Phần mềm nội bộ, tạo lập cơ sở dữ liệu và đào tạo chuyển giao | C7: 15000000000 | D7: 7000000000 | E7: =PM_LGSP.VIII!I10+'2.4.Khac'!F5 -> 7011370000 | F7: 1.532 | G7: 1.855 | H7: =G7-((G7-F7)/(C7-D7))*(E7-D7) -> 1.8545409
A8: 2 | B8: Tư vấn lập Kế hoạch thuê dịch vụ CNTT
B9: Phần mềm thương mại | E9: =E6 -> 0 | F9: 0.739 | G9: 0.992 | H9: =G9*1.65 -> 1.6368 | I9: =Nb*1,65
B10: Phần mềm nội bộ, tạo lập cơ sở dữ liệu và đào tạo chuyển giao | C10: 15000000000 | D10: 7000000000 | E10: =E7 -> 7011370000 | F10: 3.24 | G10: 3.64 | H10: =G10-((G10-F10)/(C10-D10))*(E10-D10) -> 3.6394315
A11: 3 | B11: ='[1]1Tonghop'!B18 -> Tư vấn thẩm tra tính hiệu quả và tính khả thi
B12: =B9 -> Phần mềm thương mại | E12: =E9 -> 0 | G12: 0.105 | H12: =G12*40/100 -> 0.042 | I12: =Nb*40%
B13: =B10 -> Phần mềm nội bộ, tạo lập cơ sở dữ liệu và đào tạo chuyển giao | C13: =C10 -> 15000000000 | D13: =D10 -> 7000000000 | E13: =E10 -> 7011370000 | F13: 0.088 | G13: 0.126 | H13: =(G13-((G13-F13)/(C13-D13))*(E13-D13))*40% -> 0.050378397 | I13: =Nb *40%
A14: 4 | B14: Tư vấn thẩm tra kế hoạch
B15: =B12 -> Phần mềm thương mại | E15: =E12 -> 0 | G15: 0.087 | H15: =G15*70/100 -> 0.0609 | I15: =Nb*70%
B16: =B13 -> Phần mềm nội bộ, tạo lập cơ sở dữ liệu và đào tạo chuyển giao | C16: =C13 -> 15000000000 | D16: =D13 -> 7000000000 | E16: =E13 -> 7011370000 | F16: 0.066 | G16: 0.095 | H16: =(G16-((G16-F16)/(C16-D16))*(E16-D16))*70% -> 0.066471149 | I16: =Nb*70%
A17: 5 | B17: ='[1]1Tonghop'!B20 -> Tư vấn thẩm tra dự toán
B18: =B15 -> Phần mềm thương mại | E18: =E15 -> 0 | G18: 0.078 | H18: =G18*70% -> 0.0546 | I18: '=Nb*70%
B19: =B16 -> Phần mềm nội bộ, tạo lập cơ sở dữ liệu và đào tạo chuyển giao | C19: =C16 -> 15000000000 | D19: =D16 -> 7000000000 | E19: =E16 -> 7011370000 | F19: 0.054 | G19: 0.085 | H19: =(G19-((G19-F19)/(C19-D19))*(E19-D19))*70% -> 0.059469159 | I19: =Nb*70%
A20: 6 | B20: ='[1]1Tonghop'!B21 -> Tư vấn lập hồ sơ mời thầu và đánh giá hồ sơ dự thầu
B21: =B18 -> Phần mềm thương mại | E21: =E18 -> 0 | G21: 0.283 | H21: =G21 -> 0.283
B22: =B19 -> Phần mềm nội bộ, tạo lập cơ sở dữ liệu và đào tạo chuyển giao | C22: =C19 -> 15000000000 | D22: =D19 -> 7000000000 | E22: =E19 -> 7011370000 | F22: 0.336 | G22: 0.405 | H22: =(G22-((G22-F22)/(C22-D22))*(E22-D22)) -> 0.40490193
A23: 7 | B23: ='[1]1Tonghop'!B23 -> Tư vấn giám sát
B24: =B21 -> Phần mềm thương mại | E24: =E21 -> 0 | G24: 0.718 | H24: =G24 -> 0.718
B25: Không giám sát hạng mục phần mềm nội bộ, chỉ giám sát hạng mục chuyển đổi dữ liệu và đào tạo chuyển giao | C25: =C22 -> 15000000000 | D25: =D22 -> 7000000000 | E25: ='[2]1Tonghop'!D9+'[2]1Tonghop'!D10 -> 54356565 | F25: 1.931 | G25: 2.063 | H25: 2.063
A28: ĐỊNH MỨC TỶ LỆ CHI PHÍ KIỂM TOÁN, THẨM TRA, PHÊ DUYỆT QUYẾT TOÁN (Căn cứ Nghị định 99/2021/NĐ-CP ngày 11/11/2021 của Chính phủ)
A30: stt | B30: Tên hạng mục | C30: Ga (cận trên) (đồng) | D30: Gb (cận dưới) (đồng) | E30: Gi (đồng) | F30: Ka (cận trên) | G30: Kb (cận dưới) | H30: Ki | I30: Ghi chú
A31: 1 | B31: Chi phí kiểm toán độc lập | C31: 50000000000 | D31: 10000000000 | E31: ='1.TongDT'!E32 -> 12901700000 | F31: 0.45 | G31: 0.645 | H31: =(G31-((G31-F31)/(C31-D31))*(E31-D31)) -> 0.63085421 | I31: NĐ số 99/2021/NĐ-CP
A32: 2 | B32: Chi phí thẩm tra, phê duyệt quyết toán | C32: 50000000000 | D32: 10000000000 | E32: ='1.TongDT'!E32 -> 12901700000 | F32: 0.285 | G32: 0.39 | H32: =(G32-((G32-F32)/(C32-D32))*(E32-D32)) -> 0.38238304

Sheet Luong
B2: Bảng lương nhân công kỹ sư công nghệ thông tin
B3: Đơn vị tính: đồng
B4: TT | C4: Tiêu chí xác định | L4: Ghi chú
B5: 1 | C5: Cấp bậc kỹ sư CNTT | D5: KS-B1 | E5: KS-B2 | F5: KS-B3 | G5: KS-B4 | H5: KS-B5 | I5: KS-B6 | J5: KS-B7 | K5: KS-B8
B6: 2 | C6: Hệ số lương (Hcb) | D6: 2.34 | E6: 2.65 | F6: 2.96 | G6: 3.27 | H6: 3.58 | I6: 3.89 | J6: 4.2 | K6: 4.51 | L6: Quyết định 129/QĐ-BTTTT ngày 3/2/2021 của Bộ TTTT
B7: 3 | C7: Hệ số phụ cấp (Hpc) | D7: 0 | E7: 0 | F7: 0 | G7: 0 | H7: 0 | I7: 0 | J7: 0 | K7: 0
B8: 4 | C8: Mức lương cơ sở (MLcs) | D8: 2340000 | E8: 2340000 | F8: 2340000 | G8: 2340000 | H8: 2340000 | I8: 2340000 | J8: 2340000 | K8: 2340000 | L8: Nghị định 73/2024/NĐ-CP ngày 30/6/2024 của Chính phủ
B9: 5 | C9: Mức lương cơ bản (MLcb) | D9: =D6*D8 -> 5475600 | E9: =E6*E8 -> 6201000 | F9: =F6*F8 -> 6926400 | G9: =G6*G8 -> 7651800 | H9: =H6*H8 -> 8377200 | I9: =I6*I8 -> 9102600 | J9: =J6*J8 -> 9828000 | K9: =K6*K8 -> 10553400
B10: 6 | C10: Điều chỉnh tăng thêm tiền lương (Hđc 1.2) | D10: =D9*1.2 -> 6570720 | E10: =E9*1.2 -> 7441200 | F10: =F9*1.2 -> 8311680 | G10: =G9*1.2 -> 9182160 | H10: =H9*1.2 -> 10052640 | I10: =I9*1.2 -> 10923120 | J10: =J9*1.2 -> 11793600 | K10: =K9*1.2 -> 12664080 | L10: Quyết định 129/QĐ-BTTTT ngày 3/2/2021 của Bộ TTTT
B11: 7 | C11: BHXH, BHYT, BHTN, kinh phí công đoàn (23,5%) | D11: =23.5%*D9 -> 1286766 | E11: =23.5%*E9 -> 1457235 | F11: =23.5%*F9 -> 1627704 | G11: =23.5%*G9 -> 1798173 | H11: =23.5%*H9 -> 1968642 | I11: =23.5%*I9 -> 2139111 | J11: =23.5%*J9 -> 2309580 | K11: =23.5%*K9 -> 2480049 | L11: Nghị định 58/2020/NĐ-CP, Nghị định 191/2013/NĐ-CP Quyết định 595/QĐ-BHXH.
B12: 8 | C12: Mức lương lao động/Tháng | D12: =D9+D10+D11 -> 13333086 | E12: =E9+E10+E11 -> 15099435 | F12: =F9+F10+F11 -> 16865784 | G12: =G9+G10+G11 -> 18632133 | H12: =H9+H10+H11 -> 20398482 | I12: =I9+I10+I11 -> 22164831 | J12: =J9+J10+J11 -> 23931180 | K12: =K9+K10+K11 -> 25697529
B13: 9 | C13: Mức lương lao động/Ngày | D13: =D12/26 -> 512811 | E13: =E12/26 -> 580747.5 | F13: =F12/26 -> 648684 | G13: =G12/26 -> 716620.5 | H13: =H12/26 -> 784557 | I13: =I12/26 -> 852493.5 | J13: =J12/26 -> 920430 | K13: =K12/26 -> 988366.5 | L13: Thời gian lao động để tính mức lương lao động bình quân tháng là 26 ngày
B14: 10 | C14: Mức lương lao động/Giờ | D14: =D13/8 -> 64101.375 | E14: =E13/8 -> 72593.438 | F14: =F13/8 -> 81085.5 | G14: =G13/8 -> 89577.562 | H14: =H13/8 -> 98069.625 | I14: =I13/8 -> 106561.69 | J14: =J13/8 -> 115053.75 | K14: =K13/8 -> 123545.81 | L14: Thời gian lao động 08 giờ/ngày
B15: 11 | C15: Mức lương lao động bình quân (H) | E15: =(D14+E14)/2 -> 68347.406 | L15: Tối thiểu kỹ sư bậc 1, 2

Sheet 1.TongDT
A1: Tổng hợp dự toán
C2: Đơn vị tính: Đồng
A3: Stt | B3: Nội dung chi phí | C3: Giá trị sau thuế
A4: 1 | B4: Chi phí thuê dịch vụ công nghệ thông tin | C4: =E17 -> 10697715600
A5: 2 | B5: Chi phí quản lý | C5: =E19 -> 180358000
A6: 3 | B6: Chi phí tư vấn | C6: =E20 -> 113921000
A7: 4 | B7: Chi phí khác | C7: =E25 -> 433043000
A8: 5 | B8: Chi phí dự phòng | C8: =C10-(C4+C5+C6+C7) -> 1476662400
B9: TỔNG CỘNG (1+2+3+4+5) | C9: =SUM(C4:C8) -> 12901700000
C10: 12901700000
B11: Chủ trương | C11: 12901700000
A13: Bảng tổng hợp dự toán thuê dịch vụ CNTT
A14: Thông tư số 04/2020/TT-BTTTT
F15: Đơn vị tính: Đồng
A16: Stt | B16: Nội dung chi phí | C16: Giá trị trước thuế | D16: Thuế GTGT | E16: Giá trị sau thuế | F16: Ghi chú
A17: I | B17: Chi phí thuê dịch vụ công nghệ thông tin | C17: =C18 -> 9725196000 | D17: =D18 -> 972519600 | E17: =C17+D17 -> 10697715600
A18: 1 | B18: Chi phí thuê dịch vụ theo yêu cầu riêng Nền tảng tích hợp, chia sẻ dữ liệu (LGSP) | C18: ='2.CP5nam'!C6+'2.CP5nam'!C7+'2.CP5nam'!C8+'2.CP5nam'!C9 -> 9725196000 | D18: =C18*10% -> 972519600 | E18: =C18+D18 -> 10697715600 | F18: 12/2020/TT-BTTTT
A19: II | B19: Chi phí quản lý kế hoạch | C19: =ROUND(DinhMuc!H7%*'1.TongDT'!C18,-3) -> 180358000 | D19: 0 | E19: =C19+D19 -> 180358000 | F19: 1688/QĐ-BTTTT
A20: III | B20: Chi phí tư vấn | C20: =ROUND(SUM(C21:C24),-3) -> 103564000 | D20: =SUM(D21:D24) -> 10357000 | E20: =SUM(E21:E24) -> 113921000
A21: 1 | B21: Chi phí lập Kế hoạch thuê DVCNTT | C21: 0 | D21: =C21*10% -> 0 | E21: =C21+D21 -> 0 | F21: Trung tâm Chuyển đổi số và Thống kê nông nghiệp tự thực hiện
A22: 2 | B22: Chi phí tư vấn lập HSMT và đánh giá HSDT | C22: =ROUND(DinhMuc!H22%*C18,-3) -> 39378000 | D22: =ROUND(C22*10%,-3) -> 3938000 | E22: =C22+D22 -> 43316000 | F22: 1688/QĐ-BTTTT
C23: =ROUND(2*0.2%*E17,-3) -> 42791000 | D23: =ROUND(C23*10%,-3) -> 4279000 | E23: =C23+D23 -> 47070000 | F23: 24/2024/NĐ-CP
A24: 3 | B24: Chi phí thẩm định HSMT và thẩm định KQLCNT | C24: =ROUND(2*0.1%*E17,-3) -> 21395000 | D24: =ROUND(C24*10%,-3) -> 2140000 | E24: =C24+D24 -> 23535000 | F24: 24/2024/NĐ-CP
A25: IV | B25: Chi phí khác | C25: =C26 -> 433043000 | D25: =D26 -> 0 | E25: =E26 -> 433043000
A26: 1 | B26: Chi phí kiểm thử | C26: =Kiemthu!D20 -> 433043000 | D26: 0 | E26: =C26+D26 -> 433043000 | F26: 3787/BTTTT-THH
A27: 2 | B27: Chi phí thẩm định | C27: =ROUND(0.019%*E31,-3) -> 2451000 | D27: 0 | E27: =C27+D27 -> 2451000 | F27: 28/2023/TT-BTC
A28: 3 | B28: Chi phí kiểm toán độc lập | C28: =ROUND(E32*DinhMuc!H31%,-3) -> 81391000 | D28: =ROUND(C28*10%,-3) -> 8139000 | E28: =C28+D28 -> 89530000 | F28: 99/2021/NĐ-CP
A29: 4 | B29: Chi phí thẩm tra, phê duyệt quyết toán | C29: =ROUND(E32*DinhMuc!H32%,-3) -> 49334000 | D29: 0 | E29: =C29+D29 -> 49334000 | F29: 99/2021/NĐ-CP
A30: V | B30: Chi phí dự phòng | E30: =E32-(E17+E19+E20+E25) -> 1476662400
B31: TỔNG CỘNG | E31: =E17+E19+E20+E25+E30 -> 12901700000
E32: 12901700000

Sheet 2.CP5nam
A1: Dự toán chi phí thuê dịch vụ công nghệ thông tin theo yêu cầu riêng
A2: Thông tư số 12/2020/TT-BTTTT
I3: Đơn vị tính: Đồng
A4: STT | B4: Hạng mục | C4: Tổng cộng | D4: KINH PHÍ THEO NĂM | I4: Ghi chú
D5: Năm 1-2025 | E5: Năm 2-2026 | F5: Năm 3-2027 | G5: Năm 4-2028 | H5: Năm 5-2029
A6: 1 | B6: Chi phí dịch vụ | C6: =SUM(D6:H6) -> 7909560000 | D6: ='2.1.DV_LGSP'!E16 -> 1581912000 | E6: ='2.1.DV_LGSP'!E16 -> 1581912000 | F6: ='2.1.DV_LGSP'!E16 -> 1581912000 | G6: ='2.1.DV_LGSP'!E16 -> 1581912000 | H6: ='2.1.DV_LGSP'!E16 -> 1581912000 | I6: Bảng 2.1
A7: 2 | B7: Chi phí quản trị, vận hành dịch vụ | C7: ='2.2.Qtri'!E10 -> 1636854000 | D7: =C7/5 -> 327370800 | E7: =C7/5 -> 327370800 | F7: =C7/5 -> 327370800 | G7: =C7/5 -> 327370800 | H7: =C7/5 -> 327370800 | I7: Bảng 2.2
A8: 3 | B8: Chi phí bảo trì dịch vụ | C8: ='2.3.Btri'!F10 -> 170412000 | D8: =C8/5 -> 34082400 | E8: =C8/5 -> 34082400 | F8: =C8/5 -> 34082400 | G8: =C8/5 -> 34082400 | H8: =C8/5 -> 34082400 | I8: Bảng 2.3
A9: 4 | B9: Chi phí khác liên quan đến cung cấp dịch vụ | C9: =SUM(D9:H9) -> 8370000 | D9: =D10 -> 8370000 | E9: 0 | F9: 0 | G9: 0 | H9: 0
B10: Chi phí đào tạo cho cán bộ quản trị hệ thống | C10: =SUM(D10:H10) -> 8370000 | D10: ='2.4.Khac'!F5 -> 8370000 | E10: 0 | F10: 0 | G10: 0 | H10: 0 | I10: Bảng 2.4
B11: Chi phí hạ tầng thiết bị máy chủ | C11: 0 | D11: 0 | E11: 0 | F11: 0 | G11: 0 | H11: 0 | I11: Sử dụng hạ tầng của Bộ NN&PTNT
A12: 5 | B12: Chi phí quản lý kế hoạch | C12: =SUM(D12:H12) -> 180358000 | D12: ='1.TongDT'!C19 -> 180358000 | E12: 0 | F12: 0 | G12: 0 | H12: 0
A13: 6 | B13: Chi phí tư vấn | C13: =SUM(D13:H13) -> 103564000 | D13: ='1.TongDT'!C20 -> 103564000 | E13: 0 | F13: 0 | G13: 0 | H13: 0
A14: 7 | B14: Chi phí kiểm thử | C14: =SUM(D14:H14) -> 433043000 | D14: ='1.TongDT'!E26 -> 433043000 | E14: 0 | F14: 0 | G14: 0 | H14: 0
A15: 8 | B15: Chi phí dự phòng | C15: =D15 -> 1476662400 | D15: ='1.TongDT'!E30 -> 1476662400 | E15: 0 | F15: 0 | G15: 0 | H15: 0
B16: Tổng (trước VAT) | C16: =C6+C7+C8+C9+C12+C13+C14+C15 -> 11918823400 | D16: =D6+D7+D8+D9+D12+D13+D14+D15 -> 4145362600 | E16: =E6+E7+E8+E9+E12+E13+E14+E15 -> 1943365200 | F16: =F6+F7+F8+F9+F12+F13+F14+F15 -> 1943365200 | G16: =G6+G7+G8+G9+G12+G13+G14+G15 -> 1943365200 | H16: =H6+H7+H8+H9+H12+H13+H14+H15 -> 1943365200
B17: Thuế VAT | C17: =ROUND((C6+C7+C8+C9+C13)*10%,-2) -> 982876000 | D17: =(D6+D7+D8+D9+D13)*10% -> 205529920 | E17: =(E6+E7+E8+E9+E13)*10% -> 194336520 | F17: =(F6+F7+F8+F9+F13)*10% -> 194336520 | G17: =(G6+G7+G8+G9+G13)*10% -> 194336520 | H17: =(H6+H7+H8+H9+H13)*10% -> 194336520
B18: TỔNG CỘNG | C18: =C16+C17 -> 12901699400 | D18: =D16+D17 -> 4350892520 | E18: =E16+E17 -> 2137701720 | F18: =F16+F17 -> 2137701720 | G18: =G16+G17 -> 2137701720 | H18: =H16+H17 -> 2137701720
B19: TỔNG CỘNG (làm tròn) | C19: =ROUND(C18,-3) -> 12901699000 | D19: =ROUND(D18,-3) -> 4350893000 | E19: =ROUND(E18,-3) -> 2137702000 | F19: =ROUND(F18,-3) -> 2137702000 | G19: =ROUND(G18,-3) -> 2137702000 | H19: =ROUND(H18,-3) -> 2137702000

Sheet 2.1.DV_LGSP
B1: Chi phí dịch vụ theo kỳ thanh toán (Gdv)
B2: Kỳ thanh toán: Thanh toán 12 tháng/lần
E3: Đơn vị tính: Đồng
B4: STT | C4: Nội dung | D4: Ký hiệu | E4: Giá trị
B5: 1 | C5: Chi phí xây dựng, phát triển hình thành dịch vụ (Nền tảng chia sẻ, tích hợp) | D5: Tđ | E5: =PM_LGSP.VIII!I10 -> 7003000000
B6: 2 | C6: Thời gian thuê dịch vụ (năm) | D6: tthuê | E6: 5
B7: 3 | C7: Mức lãi suất cho thuê theo kỳ thanh toán (%) | D7: r | E7: =E8/E12 -> 0.042
B8: 3.1 | C8: Bình quân lãi suất trung bình | D8: N | E8: =SUM(E9:E11)/3 -> 0.042
C9: Ngân hàng thương mại cổ phần Ngoại thương Việt Nam | E9: 0.042
C10: Ngân hàng thương mại cổ phần Đầu tư và Phát triển Việt Nam | E10: 0.042
C11: Ngân hàng thương mại cổ phần Công thương Việt Nam | E11: 0.042
B12: 3.2 | C12: Số kỳ thanh toán trong 01 năm thuê dịch vụ | D12: k | E12: 1
B13: 4 | C13: Giá trị còn lại của tài sản cấu thành dịch vụ của bên cho thuê tại thời điểm kết thúc thời gian thuê dịch vụ theo yêu cầu riêng sau khi trích khấu hao theo quy định (sử dụng phương pháp khấu hao theo đường thẳng) | D13: S | E13: 0
B14: 5 | C14: Số kỳ thanh toán trong thời gian thuê dịch vụ | D14: n | E14: =E6*E12 -> 5
B15: 6 | C15: Chi phí thuê dịch vụ công nghệ thông tin theo kỳ thanh toán 01 năm (thanh toán vào cuối kỳ) | E15: =ROUND((E5*E7*((1+E7)^E14)-(E13*E7))/(((1+E7)^E14)-1),-3) -> 1581912000 | F15: trước VAT
B16: 7 | C16: Chi phí thuê dịch vụ công nghệ thông tin trong 01 năm | E16: =E15 -> 1581912000
H20: =(#REF!+#REF!+#REF!)/3*100 -> #REF!

Sheet 2.2.Qtri
B2: Dự toán kinh phí quản trị, vận hành (Gv)
B3: Phụ lục 05 ban hành kèm theo Thông tư số 04/2020/TT-BTTTT
G4: Đơn vị tính: Đồng
B5: TT | C5: Nội dung | D5: Diễn giải | E5: Thành tiền | F5: Ký hiệu | G5: Ghi chú
B6: 1 | C6: Chi phí chuyên gia trực tiếp | E6: =H20 -> 935880000 | F6: Ccg
B7: 2 | C7: Chi phí quản lý | D7: 65%*Ccg | E7: =65%*E6 -> 608322000 | F7: Cql
B8: 3 | C8: Chi phí khác | E8: 0 | F8: Ck
B9: 4 | C9: Thu thập chịu thuế tính trước | D9: 6%*(Ccg+Cql+Ck) | E9: =ROUND(6%*(E6+E7+E8),-3) -> 92652000 | F9: TN
C10: Tổng cộng (trước VAT) | D10: Ccg+Cql+Ck+TN | E10: =ROUND(SUM(E6:E9),-3) -> 1636854000
B11: 5 | C11: Thuế giá trị gia tăng | D11: 10%*(Ccg+Cql+Ck+TN) | E11: =ROUND(10%*E10,-3) -> 163685000 | F11: VAT
C12: Tổng cộng | D12: Ccg+Cql+Ck+TN+VAT | E12: =E10+E11 -> 1800539000 | F12: Cv
B15: Chuyên gia quản trị, vận hành dịch vụ trực tiếp
B16: Phụ lục 02 ban hành kèm theo Công văn số 3127/BTTTT-CĐSQG
H17: Đơn vị tính: Đồng
B18: STT | C18: Nội dung công việc | D18: Số lượng nhân sự | E18: Số lượng ngày công 1 năm | F18: Đơn giá ngày công | G18: Chi phí 01 năm | H18: Chi phí 5 năm
D19: Bậc 1 | E19: Bậc 1 | F19: Bậc 1
B20: 1 | C20: Quản trị, vận hành dịch vụ định kỳ | D20: 1 | E20: 365 | F20: =Luong!D13 -> 512811 | G20: =ROUND(E20*F20,-3) -> 187176000 | H20: =G20*5 -> 935880000
C21: - Quản trị phần mềm - Quản trị hoạt động người sử dụng - Tiếp nhận, kiểm tra và hỗ trợ các yêu cầu không liên quan đến cập nhật dữ liệu - Tiếp nhận, kiểm tra và hỗ trợ các yêu cầu liên quan đến xử lý dữ liệu - Lập quy trình hướng dẫn xử lý các tình huống thường gặp

Sheet 2.3.Btri
B2: Dự toán chi phí bảo trì dịch vụ (Gbt)
B3: Phụ lục 05 ban hành kèm theo Thông tư số 04/2020/TT-BTTTT
H4: Đơn vị tính: Đồng
B5: TT | C5: Nội dung | D5: Diễn giải | F5: Thành tiền | G5: Ký hiệu | H5: Ghi chú
B6: 1 | C6: Chi phí chuyên gia trực tiếp | F6: =H20 -> 97434000 | G6: Ccg
B7: 2 | C7: Chi phí quản lý | D7: 65%*Ccg | F7: =65%*F6 -> 63332100 | G7: Cql
B8: 3 | C8: Chi phí khác | F8: 0 | G8: Ck
B9: 4 | C9: Thu thập chịu thuế tính trước | D9: 6%*(Ccg+Cql+Ck) | F9: =ROUND(6%*(F6+F7+F8),-3) -> 9646000 | G9: TN
C10: Tổng cộng (trước VAT) | D10: Ccg+Cql+Ck+TN | F10: =ROUND(SUM(F6:F9),-3) -> 170412000
B11: 5 | C11: Thuế giá trị gia tăng | D11: 10%*(Ccg+Cql+Ck+TN) | F11: =ROUND(10%*F10,-3) -> 17041000 | G11: VAT
C12: Tổng cộng | D12: Ccg+Cql+Ck+TN+VAT | F12: =F10+F11 -> 187453000 | G12: Cbt
B15: Chi phí chuyên gia bảo trì trực tiếp
B16: Phụ lục 02 ban hành kèm theo Công văn số 3127/BTTTT-CĐSQG
I17: Đơn vị tính: Đồng
B18: STT | C18: Nội dung công việc | D18: Số lượng nhân sự | E18: Số lượng ngày công 1 năm | F18: Đơn giá ngày công | G18: Chi phí 1 năm | H18: Chi phí 5 năm | I18: Ghi chú
D19: Bậc 1 | E19: Bậc 1 | F19: Bậc 1
C20: Tổng cộng | G20: =G21+G23 -> 19486800 | H20: =H21+H23 -> 97434000
B21: 1 | C21: Bảo trì định kỳ hàng tháng | D21: 1 | E21: 24 | F21: =Luong!D13 -> 512811 | G21: =ROUND(E21*F21,-2) -> 12307500 | H21: =G21*5 -> 61537500
C22: - Kiểm tra, theo dõi hiện trạng hoạt động của phần mềm nội bộ. - Sao lưu cơ sở dữ liệu, mã nguồn định kỳ hàng tháng hoặc khi xảy ra sự cố, nâng cấp phần mềm. - Sửa lỗi phần mềm trong phạm vi các chức năng đã có của phần mềm; hỗ trợ cập nhật các bản nâng cấp, vá lỗi. - Kiểm tra tính toàn vẹn các cơ sở dữ liệu sau khi sao lưu. - Kiểm tra hiệu suất và khả năng chịu tải của phần mềm. - Thiết lập tối ưu hóa hệ cơ sở dữ liệu của phần mềm. - Hỗ trợ trong việc cài đặt phần mềm. - Kiểm tra và cập nhật các bản vá lỗi, bản vá lỗ hổng An toàn thông tin đối với hệ điều hành, hệ quản trị cơ sở dữ liệu, máy chủ web (Webserver), ... và các thành phần cấu thành nên hệ thống phần mềm. | I22: Theo báo giá
B23: 2 | C23: Xử lý sự cố, khắc phục lỗi phát sinh | G23: =SUM(G24:G26) -> 7179300 | H23: =SUM(H24:H26) -> 35896500
C24: Cấp độ 1: Dịch vụ gián đoạn hoàn toàn hoặc bị gián đoạn trong phần lớn thời gian hoặc/và các chức năng quan trọng, thiết yếu không hoạt động hoặc hoạt động không ổn định (dự đoán trung bình 06 tháng xảy ra 01 lần, 02 ngày công cho mỗi lần xử lý) | E24: 4 | F24: =Luong!D13 -> 512811 | G24: =ROUND(E24*F24,-2) -> 2051200 | H24: =G24*5 -> 10256000 | I24: Theo báo giá
C25: Cấp độ 2: Dịch vụ bị gián đoạn đôi lúc hoặc/và các chức năng quan trọng vẫn hoạt động ở mức chấp nhận được khi tiến hành các giải pháp tạm thời (dự đoán trung bình 03 tháng xảy ra 01 lần, 01 ngày công cho mỗi lần xử lý) | E25: 4 | F25: =Luong!D13 -> 512811 | G25: =ROUND(E25*F25,-2) -> 2051200 | H25: =G25*5 -> 10256000
C26: Cấp độ 3: Dịch vụ bị ảnh hưởng nhẹ, không ổn định trong thời gian ngắn. Các chức năng quan trọng hoạt động bình thường mà không cần tiến hành các giải pháp tạm thời (dự đoán trung bình 01 tháng xảy ra 01 lần, 1/2 ngày công cho mỗi lần xử lý) | E26: 6 | F26: =Luong!D13 -> 512811 | G26: =ROUND(E26*F26,-2) -> 3076900 | H26: =G26*5 -> 15384500

Sheet 2.4.Khac
A1: Chi phí khác (ck)
A2: Phụ lục 02 ban hành kèm theo Công văn số 3127/BTTTT-CĐSQG
G3: Đơn vị tính: Đồng
A4: STT | B4: Nội dung chi phí | C4: ĐVT | D4: Số lượng | E4: Đơn giá | F4: Thành tiền | G4: Ghi chú
A5: I | B5: Chi khác (Gk) | F5: =F6 -> 8370000
A6: 1 | B6: Đào tạo cho cán bộ quản trị hệ thống | D6: 1 | F6: =SUM(F10:F13) -> 8370000
B7: Số lượng học viên | C7: Người | D7: 3
B8: Thời gian đào tạo 1 lớp | C8: Ngày | D8: 2
B9: Số lượng giảng viên | C9: Người | D9: 1
B10: Chi thù lao giảng viên | C10: Người x ngày | D10: 2 | E10: 4000000 | F10: =D10*E10 -> 8000000 | G10: TT 36/2018/TTBTC
B11: Chi phí nước uống cho học viên và giảng viên | C11: Người x ngày | D11: 4 | E11: 40000 | F11: =D11*E11 -> 160000
B12: Chi phí in tài liệu cho học viên | C12: Quyển | D12: 3 | E12: 50000 | F12: =D12*E12 -> 150000
B13: Chi văn phòng phẩm | C13: Bộ | D13: 3 | E13: 20000 | F13: =D13*E13 -> 60000

Sheet PM_LGSP.VIII
A2: Bảng tính toán chi phí trực tiếp xây dựng phần mềm | F2: Chi phí phần mềm nội bộ
A3: Phụ lục VIII ban hành kèm theo Quyết định số 671/QĐ-BTTTT | F3: Phụ lục 03 ban hành kèm theo Thông tư số 18/2024/TT-BTTTT
C4: Đơn vị tính: Đồng | I4: Đơn vị tính: Đồng
A5: TT | B5: Hạng mục | C5: Diễn giải | D5: Giá trị | F5: TT | G5: Khoản mục chi phí | H5: Cách tính | I5: Giá trị | J5: Ký hiệu
A6: I | B6: Tính điểm trường hợp sử dụng (Use-case) | F6: 1 | G6: Giá trị phần mềm | H6: 1,4 x E x P x H | I6: =D16 -> 4004148000 | J6: G
A7: 1 | B7: Điểm Actor (TAW) | C7: TAW | D7: =Actors.I.IV!G8 -> 8 | F7: 2 | G7: Chi phí chung | H7: G x 65% | I7: =ROUND(I6*0.65,-3) -> 2602696000 | J7: C
A8: 2 | B8: Điểm Use-case (TBF) | C8: TBF | D8: =TH.UC.V!G18 -> 1673 | F8: 3 | G8: Thu nhập chịu thuế tính trước | H8: (G+C) x 06% | I8: =ROUND((I6+I7)*0.06,-3) -> 396411000 | J8: TL
A9: 3 | B9: Tính điểm UUCP | C9: UUCP = TAW +TBF | D9: =SUM(D7:D8) -> 1681 | F9: 4 | G9: Chi phí phần mềm | H9: G + C + TL | I9: =ROUND(SUM(I6:I8),-6) -> 7003000000 | J9: Gpm
A10: 4 | B10: Hệ số phức tạp về KT-CN (TCF) | C10: TCF = 0,6 + (0,01 x TFW) | D10: ='TCF-3.7.EF.VI.VII'!E19 -> 1.06 | G10: TỔNG CỘNG | H10: Gpm (làm tròn) | I10: =I9 -> 7003000000
A11: 5 | B11: Hệ số phức tạp về môi trường (EF) | C11: EF = 1,4 + (-0,03 x EFW) | D11: ='TCF-3.7.EF.VI.VII'!L14 -> 0.62
A12: 6 | B12: Tính điểm AUCP | C12: AUCP = UUCP x TCF x EF | D12: =ROUND(D9*D10*D11,2) -> 1104.75
A13: II | B13: Nội suy thời gian lao động (P) | C13: P : người/giờ/AUCP | D13: ='TCF-3.7.EF.VI.VII'!M16 -> 22.727273
A14: III | B14: Giá trị nỗ lực thực tế (E) | C14: E = 10/6 x AUCP | D14: =ROUND(10/6*D12,2) -> 1841.25 | I14: 7000000000
A15: IV | B15: Mức lương lao động bình quân (H) | C15: H: người/giờ | D15: =Luong!E15 -> 68347.406
A16: V | B16: Giá trị phần mềm nội bộ (G) | C16: G = 1,4 x E x P x H | D16: =ROUND(ROUND(1.4*D14*D13*D15,0),-3) -> 4004148000

Sheet Actors.I.IV
A2: Bảng tính toán điểm các tác nhân (actors) tương tác, trao đổi thông tin với phần mềm
A3: Phụ lục IV ban hành kèm theo Quyết định số 671/QĐ-BTTTT
B4: TT | C4: Loại Actor | D4: Mô tả | E4: Trọng số | F4: Số tác nhân | G4: Điểm của từng loại tác nhân
B5: 1 | C5: Đơn giản | D5: Giao diện lập trình ứng dụng (API) | E5: 1 | F5: 5 | G5: =E5*F5 -> 5
B6: 2 | C6: Trung bình | D6: Giao diện dòng lệnh (CLI) hoặc giao diện thông qua một giao thức nào đó nhưng không phải giao diện lập trình ứng dụng (API) | E6: 2 | F6: 0 | G6: =E6*F6 -> 0
B7: 3 | C7: Phức tạp | D7: Giao diện đồ họa người dùng (GUI) | E7: 3 | F7: 1 | G7: =E7*F7 -> 3
C8: Cộng (1+2+3) | D8: TAW | G8: =SUM(G5:G7) -> 8
B10: Bảng danh sách các tác nhân tham gia vào hệ thống (actors)
B11: Phụ lục I ban hành kèm theo Quyết định số 671/QĐ-BTTTT
B13: STT | C13: Tên tác nhân | D13: Mô tả tác nhân | E13: Phân loại tác nhân | F13: Ghi chú
B14: 1 | C14: Quản trị hệ thống | D14: Giao diện đồ họa người dùng (GUI) | E14: Phức tạp
B15: 2 | C15: HTTT&CSDL chuyên ngành | D15: Giao diện lập trình ứng dụng (API) | E15: Đơn giản
B16: 3 | C16: CSDL dùng chung | D16: Giao diện lập trình ứng dụng (API) | E16: Đơn giản
B17: 4 | C17: CSDL Tổng hợp, phân tích | D17: Giao diện lập trình ứng dụng (API) | E17: Đơn giản
B18: 5 | C18: NDOP | D18: Giao diện lập trình ứng dụng (API) | E18: Đơn giản
B19: 6 | C19: NDXP | D19: Giao diện lập trình ứng dụng (API) | E19: Đơn giản
D22: HTTT&CSDL chuyên ngành | E22: (nhận dữ liệu)
D23: HTTT&CSDL chuyên ngành | E23: (gửi dữ liệu)
D24: NDOP, NDXP | E24: (gửi dữ liệu)
D25: NDOP, NDXP | E25: (nhận dữ liệu)
D26: CSDL Dùng chung | E26: (gửi dữ liệu)
D27: CSDL Dùng chung | E27: (nhận dữ liệu)
D28: CSDL Tổng hợp, phân tích
D29: LGSP

Sheet Funtion.II_15.11
B2: Bảng danh sách các yêu cầu chức năng của phần mềm
B3: Phụ lục II ban hành kèm theo Quyết định số 671/QĐ-BTTTT
B4: STT | C4: Mô tả yêu cầu | E4: Phân loại | F4: Ghi chú
B5: I | C5: Quản trị người dùng, danh tính số
B6: =IF(E6="","",SUBTOTAL(3,$E$6:E6)) -> 1 | C6: Quản lý tài khoản người dùng | E6: Dữ liệu đầu vào
B7: =IF(E7="","",SUBTOTAL(3,$E$6:E7)) -> 2 | C7: Phân quyền người dùng theo vai trò | E7: Dữ liệu đầu vào
B8: =IF(E8="","",SUBTOTAL(3,$E$6:E8)) -> 3 | C8: Quản lý nhóm người dùng | E8: Dữ liệu đầu vào
B9: =IF(E9="","",SUBTOTAL(3,$E$6:E9)) -> 4 | C9: Quản lý vai trò hệ thống | E9: Dữ liệu đầu vào
B10: =IF(E10="","",SUBTOTAL(3,$E$6:E10)) -> 5 | C10: Đăng nhập/đăng xuất (SSO) | E10: Dữ liệu đầu vào
B11: =IF(E11="","",SUBTOTAL(3,$E$6:E11)) -> 6 | C11: Quản lý phiên làm việc | E11: Dữ liệu đầu vào
B12: II | C12: Quản lý hệ thống & cấu hình động
B13: =IF(E13="","",SUBTOTAL(3,$E$6:E13)) -> 7 | C13: Cấu hình tham số hệ thống động | D13: Khi admin thay đổi cấu hình → các microservice nhận bản cập nhật ngay lập tức. Không cần build code, không restart. | E13: Dữ liệu đầu vào
C14: Quản lý phiên bản cấu hình | D14: Mọi thay đổi được lưu lại, có thể rollback cấu hình cũ
B15: =IF(E15="","",SUBTOTAL(3,$E$6:E15)) -> 8 | C15: Quản lý nhật ký hệ thống, nhật ký bảo mật, nhật ký API | E15: Dữ liệu đầu vào
C16: Quản trị tài nguyên hệ thống | D16: Quản trị tài nguyên: CPU, RAM, Storage, Queue, API Gateway
B17: =IF(E17="","",SUBTOTAL(3,$E$6:E17)) -> 9 | C17: Giám sát trạng thái hệ thống | D17: Tạo phân hệ giám sát riêng | E17: Dữ liệu đầu vào
B18: =IF(E18="","",SUBTOTAL(3,$E$6:E18)) -> 10 | C18: Giám sát hoạt động các dịch vụ | E18: Dữ liệu đầu vào
B19: =IF(E19="","",SUBTOTAL(3,$E$6:E19)) -> 11 | C19: Thiết lập cảnh báo sự cố | E19: Dữ liệu đầu vào
C20: Quản lý phần mềm, đơn vị tích hợp
B21: =IF(E21="","",SUBTOTAL(3,$E$6:E21)) -> 12 | C21: Danh mục mã định danh phần mềm tích hợp | E21: Dữ liệu đầu vào
B22: =IF(E22="","",SUBTOTAL(3,$E$6:E22)) -> 13 | C22: Danh mục mã định danh đơn vị tích hợp | E22: Dữ liệu đầu vào
C23: thay tên mới:
C24: Quản lý đơn vị tích hợp | D24: Tên đơn vị, mã định danh, địa chỉ. Người phụ trách kỹ thuật. Thông tin liên hệ (email, số điện thoại). Trạng thái hoạt động: đang hoạt động / tạm dừng / thu hồi.
C25: Quản lý phần mềm tích hợp | D25: Thông tin phần mềm Mục đích tích hợp. Hình thức kết nối (REST/SOAP/File/Batch).
C26: Đăng ký API được phép sử dụng | D26: Liệt kê danh sách API mà phần mềm được sử dụng. Phân quyền theo loại dữ liệu.
C27: Giám sát sử dụng dịch vụ | D27: Danh sách các dịch vụ sử dụng, tần xuất sử dụng, Lịch sử thành công / lỗi.
C28: Nhật ký truy vết | D28: Theo dõi mọi thay đổi thông tin đăng ký phần mềm, đơn vị tích hợp
C30: Quản lý API, Cổng API
B31: =IF(E31="","",SUBTOTAL(3,$E$6:E31)) -> 14 | C31: Danh mục loại dữ liệu | E31: Dữ liệu đầu vào
B32: =IF(E32="","",SUBTOTAL(3,$E$6:E32)) -> 15 | C32: Danh mục lược đồ XML dữ liệu | D32: XML/JSON Schema Governance | E32: Dữ liệu đầu vào
B33: =IF(E33="","",SUBTOTAL(3,$E$6:E33)) -> 16 | C33: Danh mục dịch vụ chia sẻ | E33: Dữ liệu đầu vào
B34: =IF(E34="","",SUBTOTAL(3,$E$6:E34)) -> 17 | C34: Danh mục API chia sẻ | E34: Dữ liệu đầu vào
C35: Danh mục phân loại API | D35: Gắn nhãn, phân loại API theo nhóm dịch vụ.
C36: Đăng ký thông tin API | D36: Đăng ký thông tin API: URL, phương thức, giao thức. Hỗ trợ đa giao thức kết nối: REST/JSON; SOAP/XML; File/batch (CSV, XML, JSON); Upload/download file (SFTP/FTPS nếu cần). Mô tả API: input, output, tham số, schema.
C37: Quản lý vòng đời API | D37: Tạo mới – Cập nhật – Ngưng hoạt động Phiên bản API (API Versioning).
C38: Ghép chuỗi xử lý nhiều API (workflow).
C39: Quản lý lỗi & phản hồi API | D39: Chuẩn hóa mã lỗi, Ghi log lỗi cơ bản, Response chuẩn
B40: II | C40: Tích hợp dữ liệu
C41: Tích hợp dữ liệu theo thời gian thực
B42: =IF(E42="","",SUBTOTAL(3,$E$6:E42)) -> 18 | C42: Thiết lập kết nối dữ liệu thời gian thực | E42: Dữ liệu đầu vào
...

Sheet Funtion.II
B2: Bảng danh sách các yêu cầu chức năng của phần mềm
B3: Phụ lục II ban hành kèm theo Quyết định số 671/QĐ-BTTTT
B4: STT | C4: Mô tả yêu cầu | D4: Phân loại | E4: Phân loại | F4: Ghi chú
B5: I | C5: Quản lý kết nối, định tuyến, xử lý và chuyển đổi
B6: 1 | C6: Quản lý các dịch vụ trung gian (Proxy services) | D6: Dữ liệu đầu vào | E6: Trung bình
B7: 2 | C7: Tạo mới các dịch vụ trung gian (proxy services) | D7: Dữ liệu đầu vào | E7: Trung bình
B8: 3 | C8: Thiết lập dịch vụ Pass Through Proxy (dữ liệu vào của dịch vụ trung gian) | D8: Dữ liệu đầu vào | E8: Trung bình
B9: 4 | C9: Thiết lập dịch vụ Transformer Proxy | D9: Dữ liệu đầu vào | E9: Trung bình
B10: 5 | C10: Thiết lập dịch vụ Secure Proxy | D10: Dữ liệu đầu vào | E10: Trung bình
B11: 6 | C11: Thiết lập dịch vụ Logging Proxy | D11: Dữ liệu đầu vào | E11: Trung bình
B12: 7 | C12: Thiết lập dịch vụ WSDL Based Proxy | D12: Dữ liệu đầu vào | E12: Trung bình
B13: 8 | C13: Thiết lập dịch vụ Custom proxy | D13: Dữ liệu đầu vào | E13: Trung bình
B14: 9 | C14: Xem chi tiết thông tin dịch vụ trung gian | D14: Dữ liệu đầu ra | E14: Trung bình
B15: 10 | C15: Quản lý chuỗi xử lý dữ liệu (Sequences) | D15: Dữ liệu đầu vào | E15: Trung bình
B16: 11 | C16: Thiết lập chuỗi xử lý dữ liệu (Sequences) | D16: Dữ liệu đầu vào | E16: Trung bình
B17: 12 | C17: Quản lý các điểm truy cập cuối(endpoint) | D17: Dữ liệu đầu vào | E17: Trung bình
... B25: 20 | C25: Quản lý các Modules | D25: Dữ liệu đầu vào | E25: Trung bình
B26: II | C26: Quản lý thông tin đăng ký sử dụng dữ liệu
B27: II.1 | C27: Đăng ký tích hợp dữ liệu
B28: 21 | C28: Quản lý đăng ký tích hợp dữ liệu | D28: Dữ liệu đầu vào | E28: Trung bình
B29: 22 | C29: Danh sách phần mềm đăng ký tích hợp dữ liệu | D29: Dữ liệu đầu ra | E29: Trung bình
B30: 23 | C30: Danh sách dữ liệu đăng ký tích hợp | D30: Dữ liệu đầu ra | E30: Trung bình
B31: 24 | C31: Danh sách API đăng ký tích hợp | D31: Dữ liệu đầu ra | E31: Trung bình
B32: II.2 | C32: Đăng ký phân phối dữ liệu
B33: 25 | C33: Quản lý đăng ký phân phối dữ liệu | D33: Dữ liệu đầu vào | E33: Trung bình
B34: 26 | C34: Danh sách phần mềm đăng ký phân phối dữ liệu | D34: Dữ liệu đầu ra | E34: Trung bình
B35: 27 | C35: Danh sách dữ liệu đăng ký phân phối | D35: Dữ liệu đầu ra | E35: Trung bình
B36: 28 | C36: Danh sách API đăng ký phân phối | D36: Dữ liệu đầu ra | E36: Trung bình
B37: II.3 | C37: Đăng ký chia sẻ dữ liệu
B38: 29 | C38: Quản lý đăng ký chia sẻ dữ liệu | D38: Dữ liệu đầu vào | E38: Trung bình
B39: 30 | C39: Danh sách phần mềm đăng ký chia sẻ dữ liệu | D39: Dữ liệu đầu ra | E39: Trung bình
B40: 31 | C40: Danh sách dữ liệu đăng ký chia sẻ | D40: Dữ liệu đầu ra | E40: Trung bình
B41: 32 | C41: Danh sách API đăng ký chia sẻ | D41: Dữ liệu đầu ra | E41: Trung bình
B42: IV | C42: QUẢN LÝ TÍCH HỢP DỮ LIỆU
B43: IV.1 | C43: Tích hợp dữ liệu thời gian thực
B44: 33 | C44: Danh sách dịch vụ cung cấp dữ liệu tích hợp thời gian thực | D44: Dữ liệu đầu ra | E44: Trung bình
B45: 34 | C45: Bật/tắt dịch vụ sử dụng thời gian thực | D45: Dữ liệu đầu vào | E45: Trung bình
B46: 35 | C46: Danh sách dịch vụ đang sử dụng theo thời gian thực | D46: Dữ liệu đầu ra | E46: Trung bình
B47: 36 | C47: Danh sách các hệ thống đang sử dụng dịch vụ theo thời gian thực | D47: Dữ liệu đầu ra | E47: Trung bình
B48: 37 | C48: Danh sách các gói tin theo thời gian thực | D48: Dữ liệu đầu ra | E48: Trung bình
...

Sheet Funtion.II.V1
B2: Bảng danh sách các yêu cầu chức năng của phần mềm
B3: Phụ lục II ban hành kèm theo Quyết định số 671/QĐ-BTTTT
B4: STT | C4: Mô tả yêu cầu | D4: Phân loại | E4: Ghi chú
B5: A | C5: Bộ phần mềm nền tảng LGSP
B6: I | C6: Trục tích hợp
B7: I.1 | C7: Quản lý kết nối, định tuyến, xử lý và chuyển đổi
B8: 1 | C8: Quản lý các dịch vụ trung gian (Proxy services) | D8: Dữ liệu đầu vào
B9: 2 | C9: Tạo mới các dịch vụ trung gian (proxy services) | D9: Dữ liệu đầu ra
B10: 3 | C10: Thiết lập dịch vụ Pass Through Proxy (dữ liệu vào của dịch vụ trung gian) | D10: Dữ liệu đầu vào
B11: 4 | C11: Thiết lập dịch vụ Transformer Proxy | D11: Dữ liệu đầu vào
B12: 5 | C12: Thiết lập dịch vụ Secure Proxy | D12: Dữ liệu đầu vào
B13: 6 | C13: Thiết lập dịch vụ Logging Proxy | D13: Dữ liệu đầu vào
B14: 7 | C14: Thiết lập dịch vụ WSDL Based Proxy | D14: Dữ liệu đầu vào
B15: 8 | C15: Thiết lập dịch vụ Custom proxy | D15: Dữ liệu đầu vào
B16: 9 | C16: Xem chi tiết thông tin dịch vụ trung gian | D16: Dữ liệu đầu vào
B17: 10 | C17: Quản lý chuỗi xử lý dữ liệu (Sequences) | D17: Dữ liệu đầu vào
B18: 11 | C18: Thiết lập chuỗi xử lý dữ liệu (Sequences) | D18: Dữ liệu đầu vào
B19: 12 | C19: Quản lý các điểm truy cập cuối(endpoint) | D19: Dữ liệu đầu vào
... B27: 20 | C27: Tải lên modules | D27: Dữ liệu đầu vào
B28: I.2 | C28: Dịch vụ API
B29: 21 | C29: Quản lý các dịch vụ API | D29: Dữ liệu đầu vào
B30: 22 | C30: Tạo mới các dịch vụ API | D30: Dữ liệu đầu vào
B31: I.3 | C31: Quản trị cấu hình hệ thống
B32: 23 | C32: Quản lý cấu hình danh mục (menu) | D32: Dữ liệu đầu vào
B33: 24 | C33: Quản lý cấu hình hệ thống | D33: Dữ liệu đầu vào
B34: 25 | C34: Quản lý nguồn dữ liệu | D34: Dữ liệu đầu vào
B35: 26 | C35: Quản lý máy chủ nhận dữ liệu | D35: Dữ liệu đầu vào
B36: 27 | C36: Quản lý máy chủ xử lý dữ liệu | D36: Dữ liệu đầu ra
B37: 28 | C37: Quản lý máy chủ chia sẻ dữ liệu | D37: Dữ liệu đầu ra
B38: I.4 | C38: Giám sát dịch vụ
B39: 29 | C39: Tra cứu nhật ký ứng dụng | D39: Dữ liệu đầu ra
B40: 30 | C40: Tra cứu nhật ký hệ thống | D40: Dữ liệu đầu ra
B41: 31 | C41: Xem thống kê hệ thống | D41: Dữ liệu đầu ra
B42: 32 | C42: Xem luồng đi của tin nhắn | D42: Dữ liệu đầu ra
B43: II | C43: Quản lý bảo mật và xác thực tập trung
B44: II.1 | C44: Quản lý tài khoản, quản lý người dùng
B45: 33 | C45: Quản lý tài khoản | D45: Dữ liệu đầu ra
B46: 34 | C46: Quản lý sử dụng tài khoản | D46: Dữ liệu đầu ra
B47: 35 | C47: Thống kê số lượng truy cập | D47: Dữ liệu đầu ra
B48: 36 | C48: Quản lý người dùng | D48: Dữ liệu đầu ra
...

Sheet UC.III.V1
A2: Bảng chuyển đổi yêu cầu chức năng sang trường hợp sử dụng (USE CASE) | I2: =PM_LGSP.VIII!I10 -> 7003000000
A3: Phụ lục III ban hành kèm theo Quyết định số 671/QĐ-BTTTT
A5: TT | B5: Tên Use-case | C5: Tên tác nhân | D5: Giao dịch (Transaction) | E5: Phân loại theo độ phức tạp | F5: Phân loại theo BMT | G5: Sử dụng
A6: I | B6: HỆ THỐNG QUẢN TRỊ
B7: Quản trị hệ thống
A8: =IF(C8="","",SUBTOTAL(3,$C$8:C8)) -> 1 | B8: Quản trị hệ thống | C8: Quản trị hệ thống | E8: =IF(G8<4,"Đơn giản",IF(G8<=7,"Trung bình","Phức tạp")) -> Phức tạp | F8: B | G8: =COUNTA(D9:D17) -> 9
A9: =IF(C9="","",SUBTOTAL(3,$C$8:C9)) | D9: Quản trị hệ thống có thể xem danh sách người dùng
A10: =IF(C10="","",SUBTOTAL(3,$C$8:C10)) | D10: Quản trị hệ thống có thể thêm mới người dùng
A11: =IF(C11="","",SUBTOTAL(3,$C$8:C11)) | D11: Quản trị hệ thống có thể sửa thông tin người dùng
A12: =IF(C12="","",SUBTOTAL(3,$C$8:C12)) | D12: Quản trị hệ thống có thể xóa người dùng
A13: =IF(C13="","",SUBTOTAL(3,$C$8:C13)) | D13: Quản trị hệ thống có thể lựa chọn xóa nhiều người dùng
A14: =IF(C14="","",SUBTOTAL(3,$C$8:C14)) | D14: Quản trị hệ thống có thể xem chi tiết người dùng
A15: =IF(C15="","",SUBTOTAL(3,$C$8:C15)) | D15: Quản trị hệ thống có thể tìm kiếm người dùng
A16: =IF(C16="","",SUBTOTAL(3,$C$8:C16)) | D16: Quản trị hệ thống có thể xem kết quả tìm kiếm
A17: =IF(C17="","",SUBTOTAL(3,$C$8:C17)) | D17: Quản trị hệ thống có thể xem phân trang người dùng nếu số lượng nhiều
A18: =IF(C18="","",SUBTOTAL(3,$C$8:C18)) -> 2 | B18: Quản trị vai trò, phân quyền người dùng | C18: Quản trị hệ thống | E18: =IF(G18<4,"Đơn giản",IF(G18<=7,"Trung bình","Phức tạp")) -> Phức tạp | F18: B | G18: =COUNTA(D19:D27) -> 9
A19: =IF(C19="","",SUBTOTAL(3,$C$8:C19)) | D19: Quản trị hệ thống có thể xem danh sách vai trò
A20: =IF(C20="","",SUBTOTAL(3,$C$8:C20)) | D20: Quản trị hệ thống có thể thêm mới vai trò
A21: =IF(C21="","",SUBTOTAL(3,$C$8:C21)) | D21: Quản trị hệ thống có thể sửa thông tin vai trò
A22: =IF(C22="","",SUBTOTAL(3,$C$8:C22)) | D22: Quản trị hệ thống có thể xóa vai trò
A23: =IF(C23="","",SUBTOTAL(3,$C$8:C23)) | D23: Quản trị hệ thống có thể xem chi tiết vai trò
A24: =IF(C24="","",SUBTOTAL(3,$C$8:C24)) | D24: Quản trị có thể tìm kiếm vai trò
A25: =IF(C25="","",SUBTOTAL(3,$C$8:C25)) | D25: Quản trị có thể xem kết quả tìm kiếm
A26: =IF(C26="","",SUBTOTAL(3,$C$8:C26)) | D26: Quản trị có thể gán vai trò cho người dùng
A27: =IF(C27="","",SUBTOTAL(3,$C$8:C27)) | D27: Quản trị có thể gán vai trò cho nhóm người dùng
A28: =IF(C28="","",SUBTOTAL(3,$C$8:C28)) -> 3 | B28: Quản lý nhóm người dùng | C28: Quản trị hệ thống | E28: =IF(G28<4,"Đơn giản",IF(G28<=7,"Trung bình","Phức tạp")) -> Phức tạp | F28: B | G28: =COUNTA(D29:D38) -> 10
A29: =IF(C29="","",SUBTOTAL(3,$C$8:C29)) | D29: Quản trị hệ thống có thể xem danh sách nhóm người dùng
A30: =IF(C30="","",SUBTOTAL(3,$C$8:C30)) | D30: Quản trị hệ thống có thể thêm mới nhóm người dùng
A31: =IF(C31="","",SUBTOTAL(3,$C$8:C31)) | D31: Quản trị hệ thống có thể sửa nhóm người dùng
A32: =IF(C32="","",SUBTOTAL(3,$C$8:C32)) | D32: Quản trị hệ thống có thể xóa nhóm người dùng
A33: =IF(C33="","",SUBTOTAL(3,$C$8:C33)) | D33: Quản trị hệ thống có thể lựa chọn xóa nhiều nhóm người dùng
A34: =IF(C34="","",SUBTOTAL(3,$C$8:C34)) | D34: Quản trị hệ thống có thể xem danh sách người dùng trong nhóm
A35: =IF(C35="","",SUBTOTAL(3,$C$8:C35)) | D35: Quản trị hệ thống có thể gán quyền cho nhóm
A36: =IF(C36="","",SUBTOTAL(3,$C$8:C36)) | D36: Quản trị hệ thống có thể tìm kiếm nhóm người dùng
A37: =IF(C37="","",SUBTOTAL(3,$C$8:C37)) | D37: Quản trị hệ thống có thể xem kết quả tìm kiếm
A38: =IF(C38="","",SUBTOTAL(3,$C$8:C38)) | D38: Quản trị hệ thống có thể xem phân trang nhóm người dùng nếu số lượng nhiều
A39: =IF(C39="","",SUBTOTAL(3,$C$8:C39)) -> 4 | B39: Quản trị tham số hệ thống | C39: Quản trị hệ thống | E39: =IF(G39<4,"Đơn giản",IF(G39<=7,"Trung bình","Phức tạp")) -> Trung bình | F39: B | G39: =COUNTA(D40:D43) -> 4
A40: =IF(C40="","",SUBTOTAL(3,$C$8:C40)) | D40: Quản trị hệ thống có thể xem danh sách tham số hệ thống
A41: =IF(C41="","",SUBTOTAL(3,$C$8:C41)) | D41: Quản trị hệ thống có thể thêm mới tham số hệ thống
A42: =IF(C42="","",SUBTOTAL(3,$C$8:C42)) | D42: Quản trị hệ thống có thể sửa thông tin tham số hệ thống
...

Sheet UC.III.v2
A2: Bảng chuyển đổi yêu cầu chức năng sang trường hợp sử dụng (USE CASE) | I2: =PM_LGSP.VIII!I10 -> 7003000000
A3: Phụ lục III ban hành kèm theo Quyết định số 671/QĐ-BTTTT
A5: TT | B5: Tên Use-case | C5: Tên tác nhân | D5: Giao dịch (Transaction) | E5: Phân loại theo độ phức tạp | F5: Phân loại theo BMT | G5: Sử dụng
A6: I | B6: HỆ THỐNG QUẢN TRỊ
B7: Quản trị hệ thống
A8: =IF(C8="","",SUBTOTAL(3,$C$8:C8)) -> 1 | B8: Quản trị hệ thống | C8: Quản trị hệ thống | E8: =IF(G8<4,"Đơn giản",IF(G8<=7,"Trung bình","Phức tạp")) -> Phức tạp | F8: B | G8: =COUNTA(D9:D17) -> 9
A9: =IF(C9="","",SUBTOTAL(3,$C$8:C9)) | D9: Quản trị hệ thống có thể xem danh sách người dùng
A10: =IF(C10="","",SUBTOTAL(3,$C$8:C10)) | D10: Quản trị hệ thống có thể thêm mới người dùng
A11: =IF(C11="","",SUBTOTAL(3,$C$8:C11)) | D11: Quản trị hệ thống có thể sửa thông tin người dùng
A12: =IF(C12="","",SUBTOTAL(3,$C$8:C12)) | D12: Quản trị hệ thống có thể xóa người dùng
A13: =IF(C13="","",SUBTOTAL(3,$C$8:C13)) | D13: Quản trị hệ thống có thể lựa chọn xóa nhiều người dùng
A14: =IF(C14="","",SUBTOTAL(3,$C$8:C14)) | D14: Quản trị hệ thống có thể xem chi tiết người dùng
A15: =IF(C15="","",SUBTOTAL(3,$C$8:C15)) | D15: Quản trị hệ thống có thể tìm kiếm người dùng
A16: =IF(C16="","",SUBTOTAL(3,$C$8:C16)) | D16: Quản trị hệ thống có thể xem kết quả tìm kiếm
A17: =IF(C17="","",SUBTOTAL(3,$C$8:C17)) | D17: Quản trị hệ thống có thể xem phân trang người dùng nếu số lượng nhiều
A18: =IF(C18="","",SUBTOTAL(3,$C$8:C18)) -> 2 | B18: Quản trị vai trò, phân quyền người dùng | C18: Quản trị hệ thống | E18: =IF(G18<4,"Đơn giản",IF(G18<=7,"Trung bình","Phức tạp")) -> Phức tạp | F18: B | G18: =COUNTA(D19:D27) -> 9
A19: =IF(C19="","",SUBTOTAL(3,$C$8:C19)) | D19: Quản trị hệ thống có thể xem danh sách vai trò
A20: =IF(C20="","",SUBTOTAL(3,$C$8:C20)) | D20: Quản trị hệ thống có thể thêm mới vai trò
A21: =IF(C21="","",SUBTOTAL(3,$C$8:C21)) | D21: Quản trị hệ thống có thể sửa thông tin vai trò
A22: =IF(C22="","",SUBTOTAL(3,$C$8:C22)) | D22: Quản trị hệ thống có thể xóa vai trò
A23: =IF(C23="","",SUBTOTAL(3,$C$8:C23)) | D23: Quản trị hệ thống có thể xem chi tiết vai trò
A24: =IF(C24="","",SUBTOTAL(3,$C$8:C24)) | D24: Quản trị có thể tìm kiếm vai trò
A25: =IF(C25="","",SUBTOTAL(3,$C$8:C25)) | D25: Quản trị có thể xem kết quả tìm kiếm
A26: =IF(C26="","",SUBTOTAL(3,$C$8:C26)) | D26: Quản trị có thể gán vai trò cho người dùng
A27: =IF(C27="","",SUBTOTAL(3,$C$8:C27)) | D27: Quản trị có thể gán vai trò cho nhóm người dùng
A28: =IF(C28="","",SUBTOTAL(3,$C$8:C28)) -> 3 | B28: Quản lý nhóm người dùng | C28: Quản trị hệ thống | E28: =IF(G28<4,"Đơn giản",IF(G28<=7,"Trung bình","Phức tạp")) -> Phức tạp | F28: B | G28: =COUNTA(D29:D38) -> 10
A29: =IF(C29="","",SUBTOTAL(3,$C$8:C29)) | D29: Quản trị hệ thống có thể xem danh sách nhóm người dùng
A30: =IF(C30="","",SUBTOTAL(3,$C$8:C30)) | D30: Quản trị hệ thống có thể thêm mới nhóm người dùng
A31: =IF(C31="","",SUBTOTAL(3,$C$8:C31)) | D31: Quản trị hệ thống có thể sửa nhóm người dùng
A32: =IF(C32="","",SUBTOTAL(3,$C$8:C32)) | D32: Quản trị hệ thống có thể xóa nhóm người dùng
A33: =IF(C33="","",SUBTOTAL(3,$C$8:C33)) | D33: Quản trị hệ thống có thể lựa chọn xóa nhiều nhóm người dùng
A34: =IF(C34="","",SUBTOTAL(3,$C$8:C34)) | D34: Quản trị hệ thống có thể xem danh sách người dùng trong nhóm
A35: =IF(C35="","",SUBTOTAL(3,$C$8:C35)) | D35: Quản trị hệ thống có thể gán quyền cho nhóm
A36: =IF(C36="","",SUBTOTAL(3,$C$8:C36)) | D36: Quản trị hệ thống có thể tìm kiếm nhóm người dùng
A37: =IF(C37="","",SUBTOTAL(3,$C$8:C37)) | D37: Quản trị hệ thống có thể xem kết quả tìm kiếm
A38: =IF(C38="","",SUBTOTAL(3,$C$8:C38)) | D38: Quản trị hệ thống có thể xem phân trang nhóm người dùng nếu số lượng nhiều
A39: =IF(C39="","",SUBTOTAL(3,$C$8:C39)) -> 4 | B39: Quản trị tham số hệ thống | C39: Quản trị hệ thống | E39: =IF(G39<4,"Đơn giản",IF(G39<=7,"Trung bình","Phức tạp")) -> Trung bình | F39: B | G39: =COUNTA(D40:D43) -> 4
A40: =IF(C40="","",SUBTOTAL(3,$C$8:C40)) | D40: Quản trị hệ thống có thể xem danh sách tham số hệ thống
A41: =IF(C41="","",SUBTOTAL(3,$C$8:C41)) | D41: Quản trị hệ thống có thể thêm mới tham số hệ thống
A42: =IF(C42="","",SUBTOTAL(3,$C$8:C42)) | D42: Quản trị hệ thống có thể sửa thông tin tham số hệ thống
...

Sheet UC update
A2: Bảng chuyển đổi yêu cầu chức năng sang trường hợp sử dụng (USE CASE) | I2: =PM_LGSP.VIII!I10 -> 7003000000
A3: Phụ lục III ban hành kèm theo Quyết định số 671/QĐ-BTTTT
A5: TT | B5: Tên Use-case | C5: Tên tác nhân | D5: Giao dịch (Transaction) | E5: Phân loại theo độ phức tạp | F5: Phân loại theo BMT | G5: Sử dụng
A6: A | B6: Bộ phần mềm nền tảng LGSP
A7: I | B7: Trục tích hợp
A8: I.1 | B8: Quản lý kết nối, định tuyến, xử lý và chuyển đổi
A9: =IF(C9="","",SUBTOTAL(3,$C9:C$9)) -> 1 | B9: Quản lý các dịch vụ trung gian (Proxy services) | C9: Quản trị hệ thống | E9: =IF(G9<4,"Đơn giản",IF(G9<=7,"Trung bình","Phức tạp")) -> Trung bình | F9: B | G9: =COUNTA(D10:D16) -> 7 | H9: Kết nối
D10: Quản trị chọn menu Danh sách Dịch vụ Proxy. Hệ thống hiển thị danh sách các dịch vụ proxy
D11: Quản trị có thể nhập từ khóa để tìm kiếm dịch vụ theo tên. Hệ thống hiển thị dịch vụ theo từ khóa tìm kiếm
D12: Quản trị có thể tìm kiếm theo tiêu chí kiểu dịch vụ. Hệ thống hiển thị danh sách dịch vụ theo tiêu chí tìm kiếm
D13: Quản trị có thể kết hợp tìm kiếm dịch vụ theo từ khóa và tiêu chí kiểu dịch vụ. Hệ thống hiển thị dịch vụ thỏa mãn điều kiện tìm kiếm
D14: Quản trị có thể chọn xem thông tin WSDL của dịch vụ. Hệ thống hiển thị thông tin cần thiết của dịch vụ được chọn
D15: Quản trị có thể chọn tải về gói dịch vụ kiểu axis2. Hệ thống tải về gói dịch vụ được chọn
D16: Quản trị có thể chọn kiểm thử dịch vụ bằng công cụ. Hệ thống hiển thị màn hình để kiểm thử dịch vụ
A17: =IF(C17="","",SUBTOTAL(3,$C$9:C17)) -> 2 | B17: Tạo mới các dịch vụ trung gian (proxy services) | C17: Quản trị hệ thống | E17: =IF(G17<4,"Đơn giản",IF(G17<=7,"Trung bình","Phức tạp")) -> Trung bình | F17: B | G17: =COUNTA(D18:D24) -> 7 | H17: Kết nối
D18: Quản trị chọn menu Thêm mới Dịch vụ Proxy. Hệ thống hiển thị danh sách các dịch vụ để thêm mới
D19: Quản trị có thể chọn tạo mới dịch vụ dạng Pass Through Proxy. Hệ thống hiển thị màn hình thêm mới dịch vụ Pass Through Proxy
D20: Quản trị có thể chọn tạo mới dịch vụ dạng Secure Proxy. Hệ thống hiển thị màn hình thêm mới dịch vụ Secure Proxy
D21: Quản trị có thể chọn tạo mới dịch vụ dạng WSDL based proxy. Hệ thống hiển thị màn hình thêm mới dịch vụ WSDL based proxy
D22: Quản trị có thể chọn tạo mới dịch vụ dạng Logging proxy. Hệ thống hiển thị màn hình thêm mới dịch vụ Logging proxy
D23: Quản trị có thể chọn tạo mới dịch vụ dạng Transformer Proxy. Hệ thống hiển thị màn hình thêm mới dịch vụ Transformer Proxy
D24: Quản trị có thể chọn tạo mới dịch vụ dạng Custom proxy. Hệ thống hiển thị màn hình thêm mới dịch vụ Custom proxy
A25: =IF(C25="","",SUBTOTAL(3,$C$9:C25)) -> 3 | B25: Thiết lập dịch vụ Pass Through Proxy (dữ liệu vào của dịch vụ trung gian) | C25: Quản trị hệ thống | E25: =IF(G25<4,"Đơn giản",IF(G25<=7,"Trung bình","Phức tạp")) -> Trung bình | F25: B | G25: =COUNTA(D26:D32) -> 7 | H25: Định tuyến
D26: Quản trị chọn tạo mới dịch vụ dạng Pass Through Proxy. Hệ thống hiển thị màn hình thêm mới dịch vụ Pass Through Proxy
D27: Quản trị nhập các thông tin để thêm mới. Hệ thống hiển thị thông tin nhập
D28: Quản trị có thể lựa chọn điểm truy cập đích từ định nghĩa URL trực tiếp khi thêm mới dịch vụ Pass Through Proxy. Hệ thống hiển thị ra thêm các trường để nhập thông tin nếu có
D29: Quản trị có thể lựa chọn điểm truy cập đích từ kho đăng ký khi thêm mới dịch vụ Pass Through Proxy. Hệ thống hiển thị ra thêm các trường để nhập thông tin nếu có
D30: Quản trị có thể lựa chọn chuyển đổi yêu cầu gửi tới bằng XSLT từ kho đăng ký khi thêm mới dịch vụ Pass Through Proxy. Hệ thống đánh dấu thông tin lựa chọn
D31: Quản trị có thể lựa chọn chuyển đổi phản hồi bằng XSLT từ kho đăng ký khi thêm mới dịch vụ Pass Through Proxy. Hệ thống đánh dấu thông tin lựa chọn
D32: Quản trị có thể nhấn nút Thiết lập. Hệ thống lưu lại thông tin và thiết lập dịch vụ
A33: =IF(C33="","",SUBTOTAL(3,$C$9:C33)) -> 4 | B33: Thiết lập dịch vụ Transformer Proxy | C33: Quản trị hệ thống | E33: =IF(G33<4,"Đơn giản",IF(G33<=7,"Trung bình","Phức tạp")) -> Trung bình | F33: B | G33: =COUNTA(D34:D40) -> 7 | H33: Định tuyến
D34: Quản trị chọn tạo mới dịch vụ dạng Transformer Proxy. Hệ thống hiển thị màn hình thêm mới dịch vụ Transformer Proxy
D35: Quản trị nhập các thông tin để thêm mới. Hệ thống hiển thị thông tin nhập
D36: Quản trị có thể lựa chọn điểm truy cập đích từ định nghĩa URL trực tiếp khi thêm mới dịch vụ Transformer Proxy. Hệ thống hiển thị ra thêm các trường để nhập thông tin nếu có
D37: Quản trị có thể lựa chọn điểm truy cập đích từ kho đăng ký khi thêm mới dịch vụ Transformer Proxy. Hệ thống hiển thị ra thêm các trường để nhập thông tin nếu có
D38: Quản trị có thể lựa chọn chuyển đổi yêu cầu gửi tới bằng XSLT từ kho đăng ký khi thêm mới dịch vụ Transformer Proxy. Hệ thống đánh dấu thông tin lựa chọn
D39: Quản trị có thể lựa chọn chuyển đổi phản hồi bằng XSLT từ kho đăng ký khi thêm mới dịch vụ Transformer Proxy. Hệ thống đánh dấu thông tin lựa chọn
D40: Quản trị có thể nhấn nút Thiết lập. Hệ thống lưu lại thông tin và thiết lập dịch vụ
A41: =IF(C41="","",SUBTOTAL(3,$C$9:C41)) -> 5 | B41: Thiết lập dịch vụ Secure Proxy | C41: Quản trị hệ thống | E41: =IF(G41<4,"Đơn giản",IF(G41<=7,"Trung bình","Phức tạp")) -> Trung bình | F41: B | G41: =COUNTA(D42:D48) -> 7 | H41: Xử lý
D42: Quản trị chọn tạo mới dịch vụ dạng Secure Proxy. Hệ thống hiển thị màn hình thêm mới dịch vụ Secure Proxy
...

Sheet UC.III_18.11
B2: Bảng chuyển đổi yêu cầu chức năng sang trường hợp sử dụng (USE CASE) | J2: =PM_LGSP.VIII!I10 -> 7003000000
B3: Phụ lục III ban hành kèm theo Quyết định số 671/QĐ-BTTTT
B5: TT | C5: Tên Use-case | D5: Tên tác nhân | E5: Giao dịch (Transaction) | F5: Phân loại theo độ phức tạp | G5: Phân loại theo BMT | H5: Sử dụng
B6: I | C6: Quản lý hệ thống các phần mềm, CSDL kết nối với LGSP
B7: =IF(D7="","",SUBTOTAL(3,$D$6:D9)) -> 1 | C7: Quản lý phần mềm tích hợp chia sẻ | D7: Quản trị hệ thống | F7: =IF(H7<4,"Đơn giản",IF(H7<=7,"Trung bình","Phức tạp")) -> Trung bình | G7: B | H7: =COUNTA(E8:E14) -> 7
E8: Quản trị hệ thống xem danh sách phần mềm. Hệ thống LGSP hiển thị danh sách phần mềm.
E9: Quản trị hệ thống có thể xem chi tiết thông tin phần mềm. Hệ thống LGSP hiển thị thông tin chi tiết phần mềm.
E10: Quản trị hệ thống có thể tìm kiếm phần mềm theo tiêu chí. Hệ thống LGSP hiển thị danh sách kết quả tìm kiếm phần mềm theo tiêu chí.
E11: Quản trị hệ thống có thể sắp xếp danh sách phần mềm. Hệ thống LGSP sắp xếp danh sách phần mềm theo thứ tự tăng/giảm.
E12: Quản trị hệ thống có thể thêm phần mềm. Hệ thống LGSP kiểm tra và lưu thông tin thêm phần mềm.
E13: Quản trị hệ thống có thể sửa phần mềm. Hệ thống LGSP kiểm tra và lưu thông tin sửa phần mềm.
E14: Quản trị hệ thống có thể xóa phần mềm. Hệ thống LGSP kiểm tra và lưu thông tin xóa phần mềm.
B15: =IF(D15="","",SUBTOTAL(3,$D$6:D17)) -> 2 | C15: Danh mục cơ quan, đơn vị tích hợp | D15: Quản trị hệ thống | F15: =IF(H15<4,"Đơn giản",IF(H15<=7,"Trung bình","Phức tạp")) -> Trung bình | G15: B | H15: =COUNTA(E16:E22) -> 7
E16: Quản trị hệ thống xem danh sách cơ quan, đơn vị. Hệ thống LGSP hiển thị danh sách cơ quan, đơn vị tích hợp.
E17: Quản trị hệ thống có thể xem chi tiết thông tin cơ quan, đơn vị. Hệ thống LGSP hiển thị thông tin chi tiết thông tin cơ quan, đơn vị.
E18: Quản trị hệ thống có thể tìm kiếm cơ quan, đơn vị theo tiêu chí. Hệ thống LGSP hiển thị thông tin cơ quan, đơn vị theo tiêu chí tìm kiếm.
E19: Quản trị hệ thống có thể sắp xếp danh sách cơ quan, đơn vị. Hệ thống LGSP hiển thị danh sách cơ quan, đơn vị theo thứ tự sắp xếp
E20: Quản trị hệ thống có thể thêm cơ quan, đơn vị. Hệ thống LGSP lưu thông tin thêm cơ quan, đơn vị.
E21: Quản trị hệ thống có thể sửa cơ quan, đơn vị. Hệ thống LGSP lưu thông tin sửa cơ quan, đơn vị.
E22: Quản trị hệ thống có thể xóa cơ quan, đơn vị. Hệ thống LGSP lưu thông tin xoá cơ quan, đơn vị.
B23: II | C23: Quản lý hệ thống các API
B24: =IF(D24="","",SUBTOTAL(3,$D$6:D26)) -> 3 | C24: Danh mục loại dữ liệu | D24: Quản trị hệ thống | F24: =IF(H24<4,"Đơn giản",IF(H24<=7,"Trung bình","Phức tạp")) -> Trung bình | G24: B | H24: =COUNTA(E25:E28) -> 4
E25: Quản trị hệ thống có thể xem danh sách loại dữ liệu. Hệ thống LGSP hiển thị danh sách loại dữ liệu.
E26: Quản trị hệ thống có thể thêm mới loại dữ liệu. Hệ thống LGSP lưu thông tin thêm mới loại dữ liệu.
E27: Quản trị hệ thống có thể sửa thông tin loại dữ liệu. Hệ thống LGSP lưu thông tin sửa thông tin loại dữ liệu
E28: Quản trị hệ thống có thể xóa loại dữ liệu. Hệ thống LGSP lưu thông tin xoá loại dữ liệu
E29: Quản trị hệ thống có thể tìm kiếm loại dữ liệu. Hệ thống LGSP hiển thị thông tin tìm kiếm loại dữ liệu
B30: =IF(D30="","",SUBTOTAL(3,$D$6:D31)) -> 4 | C30: Danh mục lược đồ dữ liệu | D30: Quản trị hệ thống | F30: =IF(H30<4,"Đơn giản",IF(H30<=7,"Trung bình","Phức tạp")) -> Trung bình | G30: B | H30: =COUNTA(E31:E34) -> 4
E31: Quản trị hệ thống có thể thêm mới lược đồ dữ liệu. Hệ thống LGSP lưu thông tin thêm mới lược đồ dữ liệu.
E32: Quản trị hệ thống có thể sửa thông tin lược đồ dữ liệu. Hệ thống LGSP lưu thông tin sửa lược đồ dữ liệu
E33: Quản trị hệ thống có thể xóa lược đồ dữ liệu. Hệ thống LGSP lưu thông tin xoá lược đồ dữ liệu
E34: Quản trị hệ thống có thể xem nội dung lược đồ dữ liệu. Hệ thống LGSP hiển thị nội dung lược đồ dữ liệu.
